Workbook

Sheet Bang TH nop
A1: CÔNG TY TNHH SD TẠI THANH HOÁ
A2: Bộ phận: Bảo vệ
A5: TT | B5: Họ và tên | C5: Mã số | D5: Lương CB | E5: Mức lương | F5: Công | G5: Phép | H5: Lễ tết | I5: Học, họp | J5: Công ca 3 | K5: Thêm giờ | L5: Công không ăn | M5: Chăm hoa | N5: Khuyến công | O5: Xăng xe | P5: PC ATV | Q5: Chức vụ | R5: Chủ nhật | S5: Thâm niên
N9: =12000*(IFERROR(F9,0)+IFERROR(R9,0)+IFERROR(H9,0)) -> 0 | O9: =10000*(IFERROR(F9,0)+IFERROR(R9,0)+IFERROR(H9,0)) -> 0
N11: =12000*(IFERROR(F11,0)+IFERROR(R11,0)+IFERROR(H11,0)) -> 0 | O11: =10000*(IFERROR(F11,0)+IFERROR(R11,0)+IFERROR(H11,0)) -> 0
N13: =12000*(IFERROR(F13,0)+IFERROR(R13,0)+IFERROR(H13,0)) -> 0 | O13: =10000*(IFERROR(F13,0)+IFERROR(R13,0)+IFERROR(H13,0)) -> 0
N15: =12000*(IFERROR(F15,0)+IFERROR(R15,0)+IFERROR(H15,0)) -> 0 | O15: =10000*(IFERROR(F15,0)+IFERROR(R15,0)+IFERROR(H15,0)) -> 0
N17: =12000*(IFERROR(F17,0)+IFERROR(R17,0)+IFERROR(H17,0)) -> 0 | O17: =10000*(IFERROR(F17,0)+IFERROR(R17,0)+IFERROR(H17,0)) -> 0
N19: =12000*(IFERROR(F19,0)+IFERROR(R19,0)+IFERROR(H19,0)) -> 0 | O19: =10000*(IFERROR(F19,0)+IFERROR(R19,0)+IFERROR(H19,0)) -> 0
N21: =12000*(IFERROR(F21,0)+IFERROR(R21,0)+IFERROR(H21,0)) -> 0 | O21: =10000*(IFERROR(F21,0)+IFERROR(R21,0)+IFERROR(H21,0)) -> 0
N23: =12000*(IFERROR(F23,0)+IFERROR(R23,0)+IFERROR(H23,0)) -> 0 | O23: =10000*(IFERROR(F23,0)+IFERROR(R23,0)+IFERROR(H23,0)) -> 0
N25: =12000*(IFERROR(F25,0)+IFERROR(R25,0)+IFERROR(H25,0)) -> 0 | O25: =10000*(IFERROR(F25,0)+IFERROR(R25,0)+IFERROR(H25,0)) -> 0
N27: =12000*(IFERROR(F27,0)+IFERROR(R27,0)+IFERROR(H27,0)) -> 0 | O27: =10000*(IFERROR(F27,0)+IFERROR(R27,0)+IFERROR(H27,0)) -> 0
N29: =12000*(IFERROR(F29,0)+IFERROR(R29,0)+IFERROR(H29,0)) -> 0 | O29: =10000*(IFERROR(F29,0)+IFERROR(R29,0)+IFERROR(H29,0)) -> 0
N31: =12000*(IFERROR(F31,0)+IFERROR(R31,0)+IFERROR(H31,0)) -> 0 | O31: =10000*(IFERROR(F31,0)+IFERROR(R31,0)+IFERROR(H31,0)) -> 0
... N87: =12000*(IFERROR(F87,0)+IFERROR(R87,0)+IFERROR(H87,0)) -> 0 | O87: =10000*(IFERROR(F87,0)+IFERROR(R87,0)+IFERROR(H87,0)) -> 0
B90: Người lập
A95: Lê Thị Linh

Sheet LƯƠNG Tx
A1: CN CÔNG TY TNHH S&D TẠI THANH HOÁ
A2: Tổ: Bảo vệ | O2: BẢNG CHI TIẾT THANH TOÁN LƯƠNG
O3: Tháng 04 năm 2026
A5: Stt | B5: Họ và tên | C5: Mã số | D5: Ngày tiếp nhận / Mức lương CB | F5: Lương SP | G5: Các khoản tiền lương | N5: Các khoản hỗ trợ | U5: Tổng cộng | V5: Khấu trừ | X5: Thực lĩnh | Y5: Ký tên | Z5: Công T03 | AA5: Lương T03 | AB5: BQT03 | AC5: BQT04 | AD5: So sánh | AE5: Tổng lương thực tế
G6: Công SP | H6: Thêm giờ | I6: Phép | J6: Lễ tết | K6: Chủ nhật | L6: Ca ba | M6: Ca ba lễ tết | N6: Xăng xe | O6: Chuyên cần | P6: Đi lại | Q6: Chăm hoa | R6: Phụ cấp chức vụ+ATV | S6: Ăn ca | T6: Thưởng theo KQKD | V6: BHXH, BHYT, BHTN | W6: CĐ
A8: 1 | B8: 2 | C8: 3 | D8: 4 | G8: 5 | H8: 6 | I8: 7 | J8: 8 | K8: 9 | L8: 10 | N8: 11 | O8: 12 | P8: 13 | Q8: 14 | R8: 15 | S8: 16 | T8: 17 | U8: 18 | V8: 19 | W8: 20 | X8: 21 | Y8: 22 | Z8: 23 | AA8: 24 | AB8: 25=24/23 | AC8: 26=28/22 | AD8: 27=26/25 | AE8: 28=18-8
A9: 1 | B9: ='Bang TH nop'!B9 -> 0 | C9: ='Bang TH nop'!C9 -> 0 | G9: ='Bang TH nop'!F9 -> 0 | H9: ='Bang TH nop'!K9 -> 0 | I9: =+'Bang TH nop'!G9 -> 0 | J9: =+'Bang TH nop'!H9 -> 0 | K9: =+'Bang TH nop'!R9 -> 0 | L9: =+'Bang TH nop'!J9 -> 0 | S9: ='Bang TH nop'!L9 -> 0
D10: =+'Bang TH nop'!D9 -> 0 | F10: =+'Bang TH nop'!E9 -> 0 | G10: =IFERROR(F10/26*G9,0) -> 0 | H10: =(IFERROR(F10,0)/26/8*150%)*IFERROR(H9,0) -> 0 | I10: =IFERROR(ROUND(D10/26*I9,0),0) -> 0 | J10: =IFERROR(ROUND(F10/26*J9,0)*4,0) -> 0 | K10: =IFERROR(F10/26*K9*2,0) -> 0 | L10: =IFERROR(F10*L9/26*30%,0) -> 0 | M10: =IFERROR(F10/26*M9*60%,0) -> 0 | N10: ='Bang TH nop'!O9 -> 0 | O10: ='Bang TH nop'!N9 -> 0 | P10: =+'Bang TH nop'!S9 -> 0 | Q10: ='Bang TH nop'!M9 -> 0 | R10: =IFERROR('Bang TH nop'!Q9,0)+IFERROR('Bang TH nop'!P9,0) -> 0 | S10: =IFERROR(S9*15000,0) -> 0 | U10: {=SUM(IFERROR(G10:S10,0))} -> 0 | W10: =IFERROR(ROUND(D10*0.5%,-3),0) -> 0 | X10: =IFERROR(ROUND(U10-V10-W10,-2),0) -> 0 | Y10: =IFERROR('Bang TH nop'!F9,0)+IFERROR('Bang TH nop'!H9,0)+IFERROR('Bang TH nop'!R9,0) -> 0 | AB10: =IFERROR(AA10/Z10,0) -> 0 | AC10: =IFERROR(AE10/Y10,0) -> 0 | AD10: =IFERROR(AC10/AB10,0) -> 0 | AE10: =IFERROR(U10-J10,0) -> 0
A11: 2 | B11: ='Bang TH nop'!B11 -> 0 | C11: ='Bang TH nop'!C11 -> 0 | G11: ='Bang TH nop'!F11 -> 0 | H11: ='Bang TH nop'!K11 -> 0 | I11: =+'Bang TH nop'!G11 -> 0 | J11: =+'Bang TH nop'!H11 -> 0 | K11: =+'Bang TH nop'!R11 -> 0 | L11: =+'Bang TH nop'!J11 -> 0 | S11: ='Bang TH nop'!L11 -> 0
D12: =+'Bang TH nop'!D11 -> 0 | F12: =+'Bang TH nop'!E11 -> 0 | G12: =IFERROR(F12/26*G11,0) -> 0 | H12: =(IFERROR(F12,0)/26/8*150%)*IFERROR(H11,0) -> 0 | I12: =IFERROR(ROUND(D12/26*I11,0),0) -> 0 | J12: =IFERROR(ROUND(F12/26*J11,0)*4,0) -> 0 | K12: =IFERROR(F12/26*K11*2,0) -> 0 | L12: =IFERROR(F12*L11/26*30%,0) -> 0 | M12: =IFERROR(F12/26*M11*60%,0) -> 0 | N12: ='Bang TH nop'!O11 -> 0 | O12: ='Bang TH nop'!N11 -> 0 | P12: =+'Bang TH nop'!S11 -> 0 | Q12: ='Bang TH nop'!M11 -> 0 | R12: =IFERROR('Bang TH nop'!Q11,0)+IFERROR('Bang TH nop'!P11,0) -> 0 | S12: =IFERROR(S11*15000,0) -> 0 | U12: {=SUM(IFERROR(G12:S12,0))} -> 0 | W12: =IFERROR(ROUND(D12*0.5%,-3),0) -> 0 | X12: =IFERROR(ROUND(U12-V12-W12,-2),0) -> 0 | Y12: =IFERROR('Bang TH nop'!F11,0)+IFERROR('Bang TH nop'!H11,0)+IFERROR('Bang TH nop'!R11,0) -> 0 | AB12: =IFERROR(AA12/Z12,0) -> 0 | AC12: =IFERROR(AE12/Y12,0) -> 0 | AD12: =IFERROR(AC12/AB12,0) -> 0 | AE12: =IFERROR(U12-J12,0) -> 0
A13: 3 | B13: ='Bang TH nop'!B13 -> 0 | C13: ='Bang TH nop'!C13 -> 0 | G13: ='Bang TH nop'!F13 -> 0 | H13: ='Bang TH nop'!K13 -> 0 | I13: =+'Bang TH nop'!G13 -> 0 | J13: =+'Bang TH nop'!H13 -> 0 | K13: =+'Bang TH nop'!R13 -> 0 | L13: =+'Bang TH nop'!J13 -> 0 | S13: ='Bang TH nop'!L13 -> 0
D14: =+'Bang TH nop'!D13 -> 0 | F14: =+'Bang TH nop'!E13 -> 0 | G14: =IFERROR(F14/26*G13,0) -> 0 | H14: =(IFERROR(F14,0)/26/8*150%)*IFERROR(H13,0) -> 0 | I14: =IFERROR(ROUND(D14/26*I13,0),0) -> 0 | J14: =IFERROR(ROUND(F14/26*J13,0)*4,0) -> 0 | K14: =IFERROR(F14/26*K13*2,0) -> 0 | L14: =IFERROR(F14*L13/26*30%,0) -> 0 | M14: =IFERROR(F14/26*M13*60%,0) -> 0 | N14: ='Bang TH nop'!O13 -> 0 | O14: ='Bang TH nop'!N13 -> 0 | P14: =+'Bang TH nop'!S13 -> 0 | Q14: ='Bang TH nop'!M13 -> 0 | R14: =IFERROR('Bang TH nop'!Q13,0)+IFERROR('Bang TH nop'!P13,0) -> 0 | S14: =IFERROR(S13*15000,0) -> 0 | U14: {=SUM(IFERROR(G14:S14,0))} -> 0 | W14: =IFERROR(ROUND(D14*0.5%,-3),0) -> 0 | X14: =IFERROR(ROUND(U14-V14-W14,-2),0) -> 0 | Y14: =IFERROR('Bang TH nop'!F13,0)+IFERROR('Bang TH nop'!H13,0)+IFERROR('Bang TH nop'!R13,0) -> 0 | AB14: =IFERROR(AA14/Z14,0) -> 0 | AC14: =IFERROR(AE14/Y14,0) -> 0 | AD14: =IFERROR(AC14/AB14,0) -> 0 | AE14: =IFERROR(U14-J14,0) -> 0
A15: 4 | B15: ='Bang TH nop'!B15 -> 0 | C15: ='Bang TH nop'!C15 -> 0 | G15: ='Bang TH nop'!F15 -> 0 | H15: ='Bang TH nop'!K15 -> 0 | I15: =+'Bang TH nop'!G15 -> 0 | J15: =+'Bang TH nop'!H15 -> 0 | K15: =+'Bang TH nop'!R15 -> 0 | L15: =+'Bang TH nop'!J15 -> 0 | S15: ='Bang TH nop'!L15 -> 0
D16: =+'Bang TH nop'!D15 -> 0 | F16: =+'Bang TH nop'!E15 -> 0 | G16: =IFERROR(F16/26*G15,0) -> 0 | H16: =(IFERROR(F16,0)/26/8*150%)*IFERROR(H15,0) -> 0 | I16: =IFERROR(ROUND(D16/26*I15,0),0) -> 0 | J16: =IFERROR(ROUND(F16/26*J15,0)*4,0) -> 0 | K16: =IFERROR(F16/26*K15*2,0) -> 0 | L16: =IFERROR(F16*L15/26*30%,0) -> 0 | M16: =IFERROR(F16/26*M15*60%,0) -> 0 | N16: ='Bang TH nop'!O15 -> 0 | O16: ='Bang TH nop'!N15 -> 0 | P16: =+'Bang TH nop'!S15 -> 0 | Q16: ='Bang TH nop'!M15 -> 0 | R16: =IFERROR('Bang TH nop'!Q15,0)+IFERROR('Bang TH nop'!P15,0) -> 0 | S16: =IFERROR(S15*15000,0) -> 0 | U16: {=SUM(IFERROR(G16:S16,0))} -> 0 | W16: =IFERROR(ROUND(D16*0.5%,-3),0) -> 0 | X16: =IFERROR(ROUND(U16-V16-W16,-2),0) -> 0 | Y16: =IFERROR('Bang TH nop'!F15,0)+IFERROR('Bang TH nop'!H15,0)+IFERROR('Bang TH nop'!R15,0) -> 0 | AB16: =IFERROR(AA16/Z16,0) -> 0 | AC16: =IFERROR(AE16/Y16,0) -> 0 | AD16: =IFERROR(AC16/AB16,0) -> 0 | AE16: =IFERROR(U16-J16,0) -> 0
A17: 5 | B17: ='Bang TH nop'!B17 -> 0 | C17: ='Bang TH nop'!C17 -> 0 | G17: ='Bang TH nop'!F17 -> 0 | H17: ='Bang TH nop'!K17 -> 0 | I17: =+'Bang TH nop'!G17 -> 0 | J17: =+'Bang TH nop'!H17 -> 0 | K17: =+'Bang TH nop'!R17 -> 0 | L17: =+'Bang TH nop'!J17 -> 0 | S17: ='Bang TH nop'!L17 -> 0
D18: =+'Bang TH nop'!D17 -> 0 | F18: =+'Bang TH nop'!E17 -> 0 | G18: =IFERROR(F18/26*G17,0) -> 0 | H18: =(IFERROR(F18,0)/26/8*150%)*IFERROR(H17,0) -> 0 | I18: =IFERROR(ROUND(D18/26*I17,0),0) -> 0 | J18: =IFERROR(ROUND(F18/26*J17,0)*4,0) -> 0 | K18: =IFERROR(F18/26*K17*2,0) -> 0 | L18: =IFERROR(F18*L17/26*30%,0) -> 0 | M18: =IFERROR(F18/26*M17*60%,0) -> 0 | N18: ='Bang TH nop'!O17 -> 0 | O18: ='Bang TH nop'!N17 -> 0 | P18: =+'Bang TH nop'!S17 -> 0 | Q18: ='Bang TH nop'!M17 -> 0 | R18: =IFERROR('Bang TH nop'!Q17,0)+IFERROR('Bang TH nop'!P17,0) -> 0 | S18: =IFERROR(S17*15000,0) -> 0 | U18: {=SUM(IFERROR(G18:S18,0))} -> 0 | W18: =IFERROR(ROUND(D18*0.5%,-3),0) -> 0 | X18: =IFERROR(ROUND(U18-V18-W18,-2),0) -> 0 | Y18: =IFERROR('Bang TH nop'!F17,0)+IFERROR('Bang TH nop'!H17,0)+IFERROR('Bang TH nop'!R17,0) -> 0 | AB18: =IFERROR(AA18/Z18,0) -> 0 | AC18: =IFERROR(AE18/Y18,0) -> 0 | AD18: =IFERROR(AC18/AB18,0) -> 0 | AE18: =IFERROR(U18-J18,0) -> 0
A19: 6 | B19: ='Bang TH nop'!B19 -> 0 | C19: ='Bang TH nop'!C19 -> 0 | G19: ='Bang TH nop'!F19 -> 0 | H19: ='Bang TH nop'!K19 -> 0 | I19: =+'Bang TH nop'!G19 -> 0 | J19: =+'Bang TH nop'!H19 -> 0 | K19: =+'Bang TH nop'!R19 -> 0 | L19: =+'Bang TH nop'!J19 -> 0 | S19: ='Bang TH nop'!L19 -> 0
D20: =+'Bang TH nop'!D19 -> 0 | F20: =+'Bang TH nop'!E19 -> 0 | G20: =IFERROR(F20/26*G19,0) -> 0 | H20: =(IFERROR(F20,0)/26/8*150%)*IFERROR(H19,0) -> 0 | I20: =IFERROR(ROUND(D20/26*I19,0),0) -> 0 | J20: =IFERROR(ROUND(F20/26*J19,0)*4,0) -> 0 | K20: =IFERROR(F20/26*K19*2,0) -> 0 | L20: =IFERROR(F20*L19/26*30%,0) -> 0 | M20: =IFERROR(F20/26*M19*60%,0) -> 0 | N20: ='Bang TH nop'!O19 -> 0 | O20: ='Bang TH nop'!N19 -> 0 | P20: =+'Bang TH nop'!S19 -> 0 | Q20: ='Bang TH nop'!M19 -> 0 | R20: =IFERROR('Bang TH nop'!Q19,0)+IFERROR('Bang TH nop'!P19,0) -> 0 | S20: =IFERROR(S19*15000,0) -> 0 | U20: {=SUM(IFERROR(G20:S20,0))} -> 0 | W20: =IFERROR(ROUND(D20*0.5%,-3),0) -> 0 | X20: =IFERROR(ROUND(U20-V20-W20,-2),0) -> 0 | Y20: =IFERROR('Bang TH nop'!F19,0)+IFERROR('Bang TH nop'!H19,0)+IFERROR('Bang TH nop'!R19,0) -> 0 | AB20: =IFERROR(AA20/Z20,0) -> 0 | AC20: =IFERROR(AE20/Y20,0) -> 0 | AD20: =IFERROR(AC20/AB20,0) -> 0 | AE20: =IFERROR(U20-J20,0) -> 0
A21: 7 | B21: ='Bang TH nop'!B21 -> 0 | C21: ='Bang TH nop'!C21 -> 0 | G21: ='Bang TH nop'!F21 -> 0 | H21: ='Bang TH nop'!K21 -> 0 | I21: =+'Bang TH nop'!G21 -> 0 | J21: =+'Bang TH nop'!H21 -> 0 | K21: =+'Bang TH nop'!R21 -> 0 | L21: =+'Bang TH nop'!J21 -> 0 | S21: ='Bang TH nop'!L21 -> 0
D22: =+'Bang TH nop'!D21 -> 0 | F22: =+'Bang TH nop'!E21 -> 0 | G22: =IFERROR(F22/26*G21,0) -> 0 | H22: =(IFERROR(F22,0)/26/8*150%)*IFERROR(H21,0) -> 0 | I22: =IFERROR(ROUND(D22/26*I21,0),0) -> 0 | J22: =IFERROR(ROUND(F22/26*J21,0)*4,0) -> 0 | K22: =IFERROR(F22/26*K21*2,0) -> 0 | L22: =IFERROR(F22*L21/26*30%,0) -> 0 | M22: =IFERROR(F22/26*M21*60%,0) -> 0 | N22: ='Bang TH nop'!O21 -> 0 | O22: ='Bang TH nop'!N21 -> 0 | P22: =+'Bang TH nop'!S21 -> 0 | Q22: ='Bang TH nop'!M21 -> 0 | R22: =IFERROR('Bang TH nop'!Q21,0)+IFERROR('Bang TH nop'!P21,0) -> 0 | S22: =IFERROR(S21*15000,0) -> 0 | U22: {=SUM(IFERROR(G22:S22,0))} -> 0 | W22: =IFERROR(ROUND(D22*0.5%,-3),0) -> 0 | X22: =IFERROR(ROUND(U22-V22-W22,-2),0) -> 0 | Y22: =IFERROR('Bang TH nop'!F21,0)+IFERROR('Bang TH nop'!H21,0)+IFERROR('Bang TH nop'!R21,0) -> 0 | AB22: =IFERROR(AA22/Z22,0) -> 0 | AC22: =IFERROR(AE22/Y22,0) -> 0 | AD22: =IFERROR(AC22/AB22,0) -> 0 | AE22: =IFERROR(U22-J22,0) -> 0
K23: =+'Bang TH nop'!R23 -> 0 | L23: =+'Bang TH nop'!J23 -> 0
K24: =+F24/26*K23*2 -> 0 | L24: =F24*L23/(26)*30% -> 0 | Z24: =+IFERROR(VLOOKUP(C23,'[1]Bản gốc T10'!$C$1:$J$1000,8,0),0) -> 0 | AA24: =+IFERROR(VLOOKUP(C23,'[1]Bản gốc T10'!$C$1:$F$1000,4,0),0) -> 0
K25: =+'Bang TH nop'!R25 -> 0 | L25: =+'Bang TH nop'!J25 -> 0
K26: =+F26/26*K25*2 -> 0 | L26: =F26*L25/(26)*30% -> 0 | Z26: =+IFERROR(VLOOKUP(C25,'[1]Bản gốc T10'!$C$1:$J$1000,8,0),0) -> 0 | AA26: =+IFERROR(VLOOKUP(C25,'[1]Bản gốc T10'!$C$1:$F$1000,4,0),0) -> 0
K27: =+'Bang TH nop'!R27 -> 0 | L27: =+'Bang TH nop'!J27 -> 0
K28: =+F28/26*K27*2 -> 0 | L28: =F28*L27/(26)*30% -> 0 | Z28: =+IFERROR(VLOOKUP(C27,'[1]Bản gốc T10'!$C$1:$J$1000,8,0),0) -> 0 | AA28: =+IFERROR(VLOOKUP(C27,'[1]Bản gốc T10'!$C$1:$F$1000,4,0),0) -> 0
K29: =+'Bang TH nop'!R29 -> 0 | L29: =+'Bang TH nop'!J29 -> 0
K30: =+F30/26*K29*2 -> 0 | L30: =F30*L29/(26)*30% -> 0 | Z30: =+IFERROR(VLOOKUP(C29,'[1]Bản gốc T10'!$C$1:$J$1000,8,0),0) -> 0 | AA30: =+IFERROR(VLOOKUP(C29,'[1]Bản gốc T10'!$C$1:$F$1000,4,0),0) -> 0
K31: =+'Bang TH nop'!R31 -> 0 | L31: =+'Bang TH nop'!J31 -> 0
K32: =+F32/26*K31*2 -> 0 | L32: =F32*L31/(26)*30% -> 0 | Z32: =+IFERROR(VLOOKUP(C31,'[1]Bản gốc T10'!$C$1:$J$1000,8,0),0) -> 0 | AA32: =+IFERROR(VLOOKUP(C31,'[1]Bản gốc T10'!$C$1:$F$1000,4,0),0) -> 0
K33: =+'Bang TH nop'!R33 -> 0 | L33: =+'Bang TH nop'!J33 -> 0
K34: =+F34/26*K33*2 -> 0 | L34: =F34*L33/(26)*30% -> 0 | Z34: =+IFERROR(VLOOKUP(C33,'[1]Bản gốc T10'!$C$1:$J$1000,8,0),0) -> 0 | AA34: =+IFERROR(VLOOKUP(C33,'[1]Bản gốc T10'!$C$1:$F$1000,4,0),0) -> 0
K35: =+'Bang TH nop'!R35 -> 0 | L35: =+'Bang TH nop'!J35 -> 0
K36: =+F36/26*K35*2 -> 0 | L36: =F36*L35/(26)*30% -> 0 | Z36: =+IFERROR(VLOOKUP(C35,'[1]Bản gốc T10'!$C$1:$J$1000,8,0),0) -> 0 | AA36: =+IFERROR(VLOOKUP(C35,'[1]Bản gốc T10'!$C$1:$F$1000,4,0),0) -> 0
K37: =+'Bang TH nop'!R37 -> 0 | L37: =+'Bang TH nop'!J37 -> 0
K38: =+F38/26*K37*2 -> 0 | L38: =F38*L37/(26)*30% -> 0 | Z38: =+IFERROR(VLOOKUP(C37,'[1]Bản gốc T10'!$C$1:$J$1000,8,0),0) -> 0 | AA38: =+IFERROR(VLOOKUP(C37,'[1]Bản gốc T10'!$C$1:$F$1000,4,0),0) -> 0
K39: =+'Bang TH nop'!R39 -> 0 | L39: =+'Bang TH nop'!J39 -> 0
K40: =+F40/26*K39*2 -> 0 | L40: =F40*L39/(26)*30% -> 0 | Z40: =+IFERROR(VLOOKUP(C39,'[1]Bản gốc T10'!$C$1:$J$1000,8,0),0) -> 0 | AA40: =+IFERROR(VLOOKUP(C39,'[1]Bản gốc T10'!$C$1:$F$1000,4,0),0) -> 0
K41: =+'Bang TH nop'!R41 -> 0 | L41: =+'Bang TH nop'!J41 -> 0
K42: =+F42/26*K41*2 -> 0 | L42: =F42*L41/(26)*30% -> 0 | Z42: =+IFERROR(VLOOKUP(C41,'[1]Bản gốc T10'!$C$1:$J$1000,8,0),0) -> 0 | AA42: =+IFERROR(VLOOKUP(C41,'[1]Bản gốc T10'!$C$1:$F$1000,4,0),0) -> 0
...
