Workbook
Name TaxTV: 10%
Name TaxXL: 5%

Sheet Bang TH nop
A1: CÔNG TY TNHH SD
A2: BẢNG HẾ SỐ HƯỞNG LƯƠNG THÁNG 10/2025
A3: Tổ Gián tiếp
S4: A | T4: B | U4: C
A5: TT | B5: Họ và tên | C5: Mã số | D5: Hệ số hưởng lương | E5: Giây / HS | F5: Giây hưởng lương | G5: Giây/1 công | H5: Ngày vào | I5: Mức lương | J5: Công | K5: Phép | L5: lễ tết | M5: Học, họp | N5: Thai 7 tháng | O5: Thêm giờ | P5: Tiền con nhỏ | Q5: Khuyến công | R5: Xăng xe | S5: Phân loại | T5: PC ATV | U5: Vắt sữa | V5: CN | W5: Thâm niên | X5: HT | Y5: Trừ phân loại lđ
F9: =IFERROR((E9*D9)/26*J9 + 400*V9,0) -> 0 | G9: =IFERROR(F9/J9,0) -> 0 | R9: =IFERROR(10000*J9,0) -> 0 | Y9: =IFERROR(-IF(S9=$S$4,0,IF(S9=$T$4,15*680*J9,IF(S9=$U$4,30*680*J9,IF(S9=0,50*680*J9,0)))),0) -> 0 | Z9: =+(130*24-T9)*E9*J9/24*680 -> 0
F11: =IFERROR((E11*D11)/26*J11 + 400*V11,0) -> 0 | G11: =IFERROR(F11/J11,0) -> 0 | R11: =IFERROR(10000*J11,0) -> 0 | Y11: =IFERROR(-IF(S11=$S$4,0,IF(S11=$T$4,15*680*J11,IF(S11=$U$4,30*680*J11,IF(S11=0,50*680*J11,0)))),0) -> 0 | Z11: =+(130*24-T11)*E11*J11/24*680 -> 0
F13: =IFERROR((E13*D13)/26*J13 + 400*V13,0) -> 0 | G13: =IFERROR(F13/J13,0) -> 0 | R13: =IFERROR(10000*J13,0) -> 0 | Y13: =IFERROR(-IF(S13=$S$4,0,IF(S13=$T$4,15*680*J13,IF(S13=$U$4,30*680*J13,IF(S13=0,50*680*J13,0)))),0) -> 0 | Z13: =+(130*24-T13)*E13*J13/24*680 -> 0
F15: =IFERROR((E15*D15)/26*J15 + 400*V15,0) -> 0 | G15: =IFERROR(F15/J15,0) -> 0 | R15: =IFERROR(10000*J15,0) -> 0 | Y15: =IFERROR(-IF(S15=$S$4,0,IF(S15=$T$4,15*680*J15,IF(S15=$U$4,30*680*J15,IF(S15=0,50*680*J15,0)))),0) -> 0 | Z15: =+(130*24-T15)*E15*J15/24*680 -> 0
F17: =IFERROR((E17*D17)/26*J17 + 400*V17,0) -> 0 | G17: =IFERROR(F17/J17,0) -> 0 | R17: =IFERROR(10000*J17,0) -> 0 | Y17: =IFERROR(-IF(S17=$S$4,0,IF(S17=$T$4,15*680*J17,IF(S17=$U$4,30*680*J17,IF(S17=0,50*680*J17,0)))),0) -> 0 | Z17: =+(130*24-T17)*E17*J17/24*680 -> 0
F19: =IFERROR((E19*D19)/26*J19 + 400*V19,0) -> 0 | G19: =IFERROR(F19/J19,0) -> 0 | R19: =IFERROR(10000*J19,0) -> 0 | Y19: =IFERROR(-IF(S19=$S$4,0,IF(S19=$T$4,15*680*J19,IF(S19=$U$4,30*680*J19,IF(S19=0,50*680*J19,0)))),0) -> 0
F21: =IFERROR((E21*D21)/26*J21 + 400*V21,0) -> 0 | G21: =IFERROR(F21/J21,0) -> 0 | R21: =IFERROR(10000*J21,0) -> 0 | Y21: =IFERROR(-IF(S21=$S$4,0,IF(S21=$T$4,15*680*J21,IF(S21=$U$4,30*680*J21,IF(S21=0,50*680*J21,0)))),0) -> 0
F23: =IFERROR((E23*D23)/26*J23 + 400*V23,0) -> 0 | G23: =IFERROR(F23/J23,0) -> 0 | R23: =IFERROR(10000*J23,0) -> 0 | Y23: =IFERROR(-IF(S23=$S$4,0,IF(S23=$T$4,15*680*J23,IF(S23=$U$4,30*680*J23,IF(S23=0,50*680*J23,0)))),0) -> 0
F25: =IFERROR((E25*D25)/26*J25 + 400*V25,0) -> 0 | G25: =IFERROR(F25/J25,0) -> 0 | R25: =IFERROR(10000*J25,0) -> 0 | Y25: =IFERROR(-IF(S25=$S$4,0,IF(S25=$T$4,15*680*J25,IF(S25=$U$4,30*680*J25,IF(S25=0,50*680*J25,0)))),0) -> 0
F27: =IFERROR((E27*D27)/26*J27 + 400*V27,0) -> 0 | G27: =IFERROR(F27/J27,0) -> 0 | R27: =IFERROR(10000*J27,0) -> 0 | Y27: =IFERROR(-IF(S27=$S$4,0,IF(S27=$T$4,15*680*J27,IF(S27=$U$4,30*680*J27,IF(S27=0,50*680*J27,0)))),0) -> 0
F29: =IFERROR((E29*D29)/26*J29 + 400*V29,0) -> 0 | G29: =IFERROR(F29/J29,0) -> 0 | R29: =IFERROR(10000*J29,0) -> 0 | Y29: =IFERROR(-IF(S29=$S$4,0,IF(S29=$T$4,15*680*J29,IF(S29=$U$4,30*680*J29,IF(S29=0,50*680*J29,0)))),0) -> 0
F31: =IFERROR((E31*D31)/26*J31 + 400*V31,0) -> 0 | G31: =IFERROR(F31/J31,0) -> 0 | R31: =IFERROR(10000*J31,0) -> 0 | Y31: =IFERROR(-IF(S31=$S$4,0,IF(S31=$T$4,15*680*J31,IF(S31=$U$4,30*680*J31,IF(S31=0,50*680*J31,0)))),0) -> 0
F33: =IFERROR((E33*D33)/26*J33 + 400*V33,0) -> 0 | G33: =IFERROR(F33/J33,0) -> 0 | R33: =IFERROR(10000*J33,0) -> 0 | Y33: =IFERROR(-IF(S33=$S$4,0,IF(S33=$T$4,15*680*J33,IF(S33=$U$4,30*680*J33,IF(S33=0,50*680*J33,0)))),0) -> 0
F35: =IFERROR((E35*D35)/26*J35 + 400*V35,0) -> 0 | G35: =IFERROR(F35/J35,0) -> 0 | R35: =IFERROR(10000*J35,0) -> 0 | Y35: =IFERROR(-IF(S35=$S$4,0,IF(S35=$T$4,15*680*J35,IF(S35=$U$4,30*680*J35,IF(S35=0,50*680*J35,0)))),0) -> 0
F37: =IFERROR((E37*D37)/26*J37 + 400*V37,0) -> 0 | G37: =IFERROR(F37/J37,0) -> 0 | R37: =IFERROR(10000*J37,0) -> 0 | Y37: =IFERROR(-IF(S37=$S$4,0,IF(S37=$T$4,15*680*J37,IF(S37=$U$4,30*680*J37,IF(S37=0,50*680*J37,0)))),0) -> 0
F39: =IFERROR((E39*D39)/26*J39 + 400*V39,0) -> 0 | G39: =IFERROR(F39/J39,0) -> 0 | R39: =IFERROR(10000*J39,0) -> 0 | Y39: =IFERROR(-IF(S39=$S$4,0,IF(S39=$T$4,15*680*J39,IF(S39=$U$4,30*680*J39,IF(S39=0,50*680*J39,0)))),0) -> 0
F41: =IFERROR((E41*D41)/26*J41 + 400*V41,0) -> 0 | G41: =IFERROR(F41/J41,0) -> 0 | R41: =IFERROR(10000*J41,0) -> 0 | Y41: =IFERROR(-IF(S41=$S$4,0,IF(S41=$T$4,15*680*J41,IF(S41=$U$4,30*680*J41,IF(S41=0,50*680*J41,0)))),0) -> 0
... F55: =IFERROR((E55*D55)/26*J55 + 400*V55,0) -> 0 | G55: =IFERROR(F55/J55,0) -> 0 | R55: =IFERROR(10000*J55,0) -> 0 | Y55: =IFERROR(-IF(S55=$S$4,0,IF(S55=$T$4,15*680*J55,IF(S55=$U$4,30*680*J55,IF(S55=0,50*680*J55,0)))),0) -> 0

Sheet LƯƠNG Tx
A1: CN CÔNG TY TNHH S&D TẠI THANH HOÁ
A3: BP: Cơ điện | N3: BẢNG CHI TIẾT THANH TOÁN LƯƠNG
F4: PC | I4: 1 | N4: Tháng 04 năm 2026
A6: Stt | B6: Họ và tên | C6: Mã Số | D6: Ngày tiếp nhận/ Mức lương CB | I6: Các khoản tiền lương | P6: Các khoản hỗ trợ | V6: Trừ phận loại lđ | W6: Tổng cộng | X6: Khấu trừ | Z6: Thực lĩnh | AA6: Ký nhận | AB6: Công T03 | AC6: Lương T03 | AD6: BQT03 | AE6: BQT04 | AF6: So sánh | AG6: Tổng lương thực tế
I7: Sản phẩm CBCV | J7: Thêm giờ | K7: Phép | L7: Lễ tết | M7: Học họp | N7: Phụ cấp nuôi con +ATV | P7: Khuyến công | Q7: Xăng xe | R7: bï l­¬ng SP | S7: bï l­¬ng Thªm giê | T7: Đi lại | U7: Thưởng theo KQKD | X7: BHXH, BHYT, BHTN | Y7: CĐ
F8: Tổng giây | G8: Bù lương
A9: 1 | B9: 2 | C9: 3 | D9: 4 | F9: 5 | I9: 6 | J9: 7 | K9: 8 | L9: 9 | M9: 10 | N9: 12 | O9: 13 | P9: 14 | Q9: 15 | T9: 18 | U9: 19 | W9: 20 | X9: 21 | Y9: 22 | Z9: 23 | AA9: 24 | AB9: 25 | AC9: 26 | AD9: 27=26/25 | AE9: 28=30/24 | AF9: 29=28/27 | AG9: 30=20-8-9
A10: 1 | B10: ='Bang TH nop'!B9 -> 0 | C10: ='Bang TH nop'!C9 -> 0 | D10: ='Bang TH nop'!H9 -> 0 | I10: ='Bang TH nop'!J9 -> 0 | J10: =+'Bang TH nop'!O9 -> 0 | K10: =+'Bang TH nop'!K9 -> 0 | L10: =+'Bang TH nop'!L9 -> 0 | M10: =+'Bang TH nop'!M9 -> 0 | O10: =+'Bang TH nop'!W9 -> 0
D11: ='Bang TH nop'!I9 -> 0 | F11: ='Bang TH nop'!F9 -> 0 | I11: =IFERROR(F11*680*(((I10-M10)*8+M10*7))/(((I10-M10)*8+M10*7+J10))*$I$4,0) -> 0 | J11: =IFERROR(F11*680*J10*150%/(((I10-M10)*8+M10*7+J10))*$I$4,0) -> 0 | K11: =IFERROR(ROUND(D11/26*K10,0),0) -> 0 | L11: =IFERROR(ROUND(D11/26*L10,0),0) -> 0 | M11: =IFERROR(ROUND(D11/26*M10,0),0) -> 0 | N11: =IFERROR('Bang TH nop'!T9,0)+IFERROR('Bang TH nop'!P9,0) -> 0 | O11: =+'Bang TH nop'!X9 -> 0 | P11: =+'Bang TH nop'!Q9 -> 0 | Q11: =+'Bang TH nop'!R9 -> 0 | R11: =IFERROR(MAX(G11-I11,0),0) -> 0 | S11: =IFERROR(MAX(H11-J11,0),0) -> 0 | T11: =+'Bang TH nop'!W9 -> 0 | V11: =+'Bang TH nop'!Y9 -> 0 | W11: {=SUM(IFERROR(I11:Q11,0))+IFERROR(T11,0)+IFERROR(U11,0)+IFERROR(V11,0)} -> 0 | X11: =IFERROR(IF((26-(IFERROR(I10,0)+IFERROR(M10,0)+IFERROR(K10,0)+IFERROR(L10,0)))>12,0,D11*10.5%),0) -> 0 | Y11: =IFERROR(ROUND(IF(D11=4939000,D11*0.5%,0),-2),0) -> 0 | Z11: =IFERROR(ROUND(W11-X11-Y11,-2),0) -> 0 | AA11: =IFERROR('Bang TH nop'!J9,0)+IFERROR('Bang TH nop'!V7,0) -> 0 | AD11: =IFERROR(AC11/AB11,0) -> 0 | AE11: =IFERROR(AG11/AA11,0) -> 0 | AF11: =IFERROR(AE11/AD11,0) -> 0 | AG11: =IFERROR(W11-L11,0) -> 0
A12: 2 | B12: ='Bang TH nop'!B11 -> 0 | C12: ='Bang TH nop'!C11 -> 0 | D12: ='Bang TH nop'!H11 -> 0 | I12: ='Bang TH nop'!J11 -> 0 | J12: =+'Bang TH nop'!O11 -> 0 | K12: =+'Bang TH nop'!K11 -> 0 | L12: =+'Bang TH nop'!L11 -> 0 | M12: =+'Bang TH nop'!M11 -> 0 | O12: =+'Bang TH nop'!W11 -> 0
D13: ='Bang TH nop'!I11 -> 0 | F13: ='Bang TH nop'!F11 -> 0 | I13: =IFERROR(F13*680*(((I12-M12)*8+M12*7))/(((I12-M12)*8+M12*7+J12))*$I$4,0) -> 0 | J13: =IFERROR(F13*680*J12*150%/(((I12-M12)*8+M12*7+J12))*$I$4,0) -> 0 | K13: =IFERROR(ROUND(D13/26*K12,0),0) -> 0 | L13: =IFERROR(ROUND(D13/26*L12,0),0) -> 0 | M13: =IFERROR(ROUND(D13/26*M12,0),0) -> 0 | N13: =IFERROR('Bang TH nop'!T11,0)+IFERROR('Bang TH nop'!P11,0) -> 0 | O13: =+'Bang TH nop'!X11 -> 0 | P13: =+'Bang TH nop'!Q11 -> 0 | Q13: =+'Bang TH nop'!R11 -> 0 | R13: =IFERROR(MAX(G13-I13,0),0) -> 0 | S13: =IFERROR(MAX(H13-J13,0),0) -> 0 | T13: =+'Bang TH nop'!W11 -> 0 | V13: =+'Bang TH nop'!Y11 -> 0 | W13: {=SUM(IFERROR(I13:Q13,0))+IFERROR(T13,0)+IFERROR(U13,0)+IFERROR(V13,0)} -> 0 | X13: =IFERROR(IF((26-(IFERROR(I12,0)+IFERROR(M12,0)+IFERROR(K12,0)+IFERROR(L12,0)))>12,0,D13*10.5%),0) -> 0 | Y13: =IFERROR(ROUND(IF(D13=4939000,D13*0.5%,0),-2),0) -> 0 | Z13: =IFERROR(ROUND(W13-X13-Y13,-2),0) -> 0 | AA13: =IFERROR('Bang TH nop'!J11,0)+IFERROR('Bang TH nop'!V9,0) -> 0 | AD13: =IFERROR(AC13/AB13,0) -> 0 | AE13: =IFERROR(AG13/AA13,0) -> 0 | AF13: =IFERROR(AE13/AD13,0) -> 0 | AG13: =IFERROR(W13-L13,0) -> 0
A14: 3 | B14: ='Bang TH nop'!B13 -> 0 | C14: ='Bang TH nop'!C13 -> 0 | D14: ='Bang TH nop'!H13 -> 0 | I14: ='Bang TH nop'!J13 -> 0 | J14: =+'Bang TH nop'!O13 -> 0 | K14: =+'Bang TH nop'!K13 -> 0 | L14: =+'Bang TH nop'!L13 -> 0 | M14: =+'Bang TH nop'!M13 -> 0 | O14: =+'Bang TH nop'!W13 -> 0
D15: ='Bang TH nop'!I13 -> 0 | F15: ='Bang TH nop'!F13 -> 0 | I15: =IFERROR(F15*680*(((I14-M14)*8+M14*7))/(((I14-M14)*8+M14*7+J14))*$I$4,0) -> 0 | J15: =IFERROR(F15*680*J14*150%/(((I14-M14)*8+M14*7+J14))*$I$4,0) -> 0 | K15: =IFERROR(ROUND(D15/26*K14,0),0) -> 0 | L15: =IFERROR(ROUND(D15/26*L14,0),0) -> 0 | M15: =IFERROR(ROUND(D15/26*M14,0),0) -> 0 | N15: =IFERROR('Bang TH nop'!T13,0)+IFERROR('Bang TH nop'!P13,0) -> 0 | O15: =+'Bang TH nop'!X13 -> 0 | P15: =+'Bang TH nop'!Q13 -> 0 | Q15: =+'Bang TH nop'!R13 -> 0 | R15: =IFERROR(MAX(G15-I15,0),0) -> 0 | S15: =IFERROR(MAX(H15-J15,0),0) -> 0 | T15: =+'Bang TH nop'!W13 -> 0 | V15: =+'Bang TH nop'!Y13 -> 0 | W15: {=SUM(IFERROR(I15:Q15,0))+IFERROR(T15,0)+IFERROR(U15,0)+IFERROR(V15,0)} -> 0 | X15: =IFERROR(IF((26-(IFERROR(I14,0)+IFERROR(M14,0)+IFERROR(K14,0)+IFERROR(L14,0)))>12,0,D15*10.5%),0) -> 0 | Y15: =IFERROR(ROUND(IF(D15=4939000,D15*0.5%,0),-2),0) -> 0 | Z15: =IFERROR(ROUND(W15-X15-Y15,-2),0) -> 0 | AA15: =IFERROR('Bang TH nop'!J13,0)+IFERROR('Bang TH nop'!V11,0) -> 0 | AD15: =IFERROR(AC15/AB15,0) -> 0 | AE15: =IFERROR(AG15/AA15,0) -> 0 | AF15: =IFERROR(AE15/AD15,0) -> 0 | AG15: =IFERROR(W15-L15,0) -> 0
A16: 4 | B16: ='Bang TH nop'!B15 -> 0 | C16: ='Bang TH nop'!C15 -> 0 | D16: ='Bang TH nop'!H15 -> 0 | I16: ='Bang TH nop'!J15 -> 0 | J16: =+'Bang TH nop'!O15 -> 0 | K16: =+'Bang TH nop'!K15 -> 0 | L16: =+'Bang TH nop'!L15 -> 0 | M16: =+'Bang TH nop'!M15 -> 0 | O16: =+'Bang TH nop'!W15 -> 0
D17: ='Bang TH nop'!I15 -> 0 | F17: ='Bang TH nop'!F15 -> 0 | I17: =IFERROR(F17*680*(((I16-M16)*8+M16*7))/(((I16-M16)*8+M16*7+J16))*$I$4,0) -> 0 | J17: =IFERROR(F17*680*J16*150%/(((I16-M16)*8+M16*7+J16))*$I$4,0) -> 0 | K17: =IFERROR(ROUND(D17/26*K16,0),0) -> 0 | L17: =IFERROR(ROUND(D17/26*L16,0),0) -> 0 | M17: =IFERROR(ROUND(D17/26*M16,0),0) -> 0 | N17: =IFERROR('Bang TH nop'!T15,0)+IFERROR('Bang TH nop'!P15,0) -> 0 | O17: =+'Bang TH nop'!X15 -> 0 | P17: =+'Bang TH nop'!Q15 -> 0 | Q17: =+'Bang TH nop'!R15 -> 0 | R17: =IFERROR(MAX(G17-I17,0),0) -> 0 | S17: =IFERROR(MAX(H17-J17,0),0) -> 0 | T17: =+'Bang TH nop'!W15 -> 0 | V17: =+'Bang TH nop'!Y15 -> 0 | W17: {=SUM(IFERROR(I17:Q17,0))+IFERROR(T17,0)+IFERROR(U17,0)+IFERROR(V17,0)} -> 0 | X17: =IFERROR(IF((26-(IFERROR(I16,0)+IFERROR(M16,0)+IFERROR(K16,0)+IFERROR(L16,0)))>12,0,D17*10.5%),0) -> 0 | Y17: =IFERROR(ROUND(IF(D17=4939000,D17*0.5%,0),-2),0) -> 0 | Z17: =IFERROR(ROUND(W17-X17-Y17,-2),0) -> 0 | AA17: =IFERROR('Bang TH nop'!J15,0)+IFERROR('Bang TH nop'!V13,0) -> 0 | AD17: =IFERROR(AC17/AB17,0) -> 0 | AE17: =IFERROR(AG17/AA17,0) -> 0 | AF17: =IFERROR(AE17/AD17,0) -> 0 | AG17: =IFERROR(W17-L17,0) -> 0
A18: 5 | B18: ='Bang TH nop'!B17 -> 0 | C18: ='Bang TH nop'!C17 -> 0 | D18: ='Bang TH nop'!H17 -> 0 | I18: ='Bang TH nop'!J17 -> 0 | J18: =+'Bang TH nop'!O17 -> 0 | K18: =+'Bang TH nop'!K17 -> 0 | L18: =+'Bang TH nop'!L17 -> 0 | M18: =+'Bang TH nop'!M17 -> 0 | O18: =+'Bang TH nop'!W17 -> 0
D19: ='Bang TH nop'!I17 -> 0 | F19: ='Bang TH nop'!F17 -> 0 | I19: =IFERROR(F19*680*(((I18-M18)*8+M18*7))/(((I18-M18)*8+M18*7+J18))*$I$4,0) -> 0 | J19: =IFERROR(F19*680*J18*150%/(((I18-M18)*8+M18*7+J18))*$I$4,0) -> 0 | K19: =IFERROR(ROUND(D19/26*K18,0),0) -> 0 | L19: =IFERROR(ROUND(D19/26*L18,0),0) -> 0 | M19: =IFERROR(ROUND(D19/26*M18,0),0) -> 0 | N19: =IFERROR('Bang TH nop'!T17,0)+IFERROR('Bang TH nop'!P17,0) -> 0 | O19: =+'Bang TH nop'!X17 -> 0 | P19: =+'Bang TH nop'!Q17 -> 0 | Q19: =+'Bang TH nop'!R17 -> 0 | R19: =IFERROR(MAX(G19-I19,0),0) -> 0 | S19: =IFERROR(MAX(H19-J19,0),0) -> 0 | T19: =+'Bang TH nop'!W17 -> 0 | V19: =+'Bang TH nop'!Y17 -> 0 | W19: {=SUM(IFERROR(I19:Q19,0))+IFERROR(T19,0)+IFERROR(U19,0)+IFERROR(V19,0)} -> 0 | X19: =IFERROR(IF((26-(IFERROR(I18,0)+IFERROR(M18,0)+IFERROR(K18,0)+IFERROR(L18,0)))>12,0,D19*10.5%),0) -> 0 | Y19: =IFERROR(ROUND(IF(D19=4939000,D19*0.5%,0),-2),0) -> 0 | Z19: =IFERROR(ROUND(W19-X19-Y19,-2),0) -> 0 | AA19: =IFERROR('Bang TH nop'!J17,0)+IFERROR('Bang TH nop'!V15,0) -> 0 | AD19: =IFERROR(AC19/AB19,0) -> 0 | AE19: =IFERROR(AG19/AA19,0) -> 0 | AF19: =IFERROR(AE19/AD19,0) -> 0 | AG19: =IFERROR(W19-L19,0) -> 0
A20: 6 | B20: ='Bang TH nop'!B19 -> 0 | C20: ='Bang TH nop'!C19 -> 0 | D20: ='Bang TH nop'!H19 -> 0 | I20: ='Bang TH nop'!J19 -> 0 | J20: =+'Bang TH nop'!O19 -> 0 | K20: =+'Bang TH nop'!K19 -> 0 | L20: =+'Bang TH nop'!L19 -> 0 | M20: =+'Bang TH nop'!M19 -> 0 | O20: =+'Bang TH nop'!W19 -> 0
D21: ='Bang TH nop'!I19 -> 0 | F21: ='Bang TH nop'!F19 -> 0 | I21: =IFERROR(F21*680*(((I20-M20)*8+M20*7))/(((I20-M20)*8+M20*7+J20))*$I$4,0) -> 0 | J21: =IFERROR(F21*680*J20*150%/(((I20-M20)*8+M20*7+J20))*$I$4,0) -> 0 | K21: =IFERROR(ROUND(D21/26*K20,0),0) -> 0 | L21: =IFERROR(ROUND(D21/26*L20,0),0) -> 0 | M21: =IFERROR(ROUND(D21/26*M20,0),0) -> 0 | N21: =IFERROR('Bang TH nop'!T19,0)+IFERROR('Bang TH nop'!P19,0) -> 0 | O21: =+'Bang TH nop'!X19 -> 0 | P21: =+'Bang TH nop'!Q19 -> 0 | Q21: =+'Bang TH nop'!R19 -> 0 | R21: =IFERROR(MAX(G21-I21,0),0) -> 0 | S21: =IFERROR(MAX(H21-J21,0),0) -> 0 | T21: =+'Bang TH nop'!W19 -> 0 | V21: =+'Bang TH nop'!Y19 -> 0 | W21: {=SUM(IFERROR(I21:Q21,0))+IFERROR(T21,0)+IFERROR(U21,0)+IFERROR(V21,0)} -> 0 | X21: =IFERROR(IF((26-(IFERROR(I20,0)+IFERROR(M20,0)+IFERROR(K20,0)+IFERROR(L20,0)))>12,0,D21*10.5%),0) -> 0 | Y21: =IFERROR(ROUND(IF(D21=4939000,D21*0.5%,0),-2),0) -> 0 | Z21: =IFERROR(ROUND(W21-X21-Y21,-2),0) -> 0 | AA21: =IFERROR('Bang TH nop'!J19,0)+IFERROR('Bang TH nop'!V17,0) -> 0 | AD21: =IFERROR(AC21/AB21,0) -> 0 | AE21: =IFERROR(AG21/AA21,0) -> 0 | AF21: =IFERROR(AE21/AD21,0) -> 0 | AG21: =IFERROR(W21-L21,0) -> 0
A22: 7 | B22: ='Bang TH nop'!B21 -> 0 | C22: ='Bang TH nop'!C21 -> 0 | D22: ='Bang TH nop'!H21 -> 0 | I22: ='Bang TH nop'!J21 -> 0 | J22: =+'Bang TH nop'!O21 -> 0 | K22: =+'Bang TH nop'!K21 -> 0 | L22: =+'Bang TH nop'!L21 -> 0 | M22: =+'Bang TH nop'!M21 -> 0 | O22: =+'Bang TH nop'!W21 -> 0
D23: ='Bang TH nop'!I21 -> 0 | F23: ='Bang TH nop'!F21 -> 0 | I23: =IFERROR(F23*680*(((I22-M22)*8+M22*7))/(((I22-M22)*8+M22*7+J22))*$I$4,0) -> 0 | J23: =IFERROR(F23*680*J22*150%/(((I22-M22)*8+M22*7+J22))*$I$4,0) -> 0 | K23: =IFERROR(ROUND(D23/26*K22,0),0) -> 0 | L23: =IFERROR(ROUND(D23/26*L22,0),0) -> 0 | M23: =IFERROR(ROUND(D23/26*M22,0),0) -> 0 | N23: =IFERROR('Bang TH nop'!T21,0)+IFERROR('Bang TH nop'!P21,0) -> 0 | O23: =+'Bang TH nop'!X21 -> 0 | P23: =+'Bang TH nop'!Q21 -> 0 | Q23: =+'Bang TH nop'!R21 -> 0 | R23: =IFERROR(MAX(G23-I23,0),0) -> 0 | S23: =IFERROR(MAX(H23-J23,0),0) -> 0 | T23: =+'Bang TH nop'!W21 -> 0 | V23: =+'Bang TH nop'!Y21 -> 0 | W23: {=SUM(IFERROR(I23:Q23,0))+IFERROR(T23,0)+IFERROR(U23,0)+IFERROR(V23,0)} -> 0 | X23: =IFERROR(IF((26-(IFERROR(I22,0)+IFERROR(M22,0)+IFERROR(K22,0)+IFERROR(L22,0)))>12,0,D23*10.5%),0) -> 0 | Y23: =IFERROR(ROUND(IF(D23=4939000,D23*0.5%,0),-2),0) -> 0 | Z23: =IFERROR(ROUND(W23-X23-Y23,-2),0) -> 0 | AA23: =IFERROR('Bang TH nop'!J21,0)+IFERROR('Bang TH nop'!V19,0) -> 0 | AD23: =IFERROR(AC23/AB23,0) -> 0 | AE23: =IFERROR(AG23/AA23,0) -> 0 | AF23: =IFERROR(AE23/AD23,0) -> 0 | AG23: =IFERROR(W23-L23,0) -> 0
A24: 8 | B24: ='Bang TH nop'!B23 -> 0 | C24: ='Bang TH nop'!C23 -> 0 | D24: ='Bang TH nop'!H23 -> 0 | I24: ='Bang TH nop'!J23 -> 0 | J24: =+'Bang TH nop'!O23 -> 0 | K24: =+'Bang TH nop'!K23 -> 0 | L24: =+'Bang TH nop'!L23 -> 0 | M24: =+'Bang TH nop'!M23 -> 0 | O24: =+'Bang TH nop'!W23 -> 0
D25: ='Bang TH nop'!I23 -> 0 | F25: ='Bang TH nop'!F23 -> 0 | I25: =IFERROR(F25*680*(((I24-M24)*8+M24*7))/(((I24-M24)*8+M24*7+J24))*$I$4,0) -> 0 | J25: =IFERROR(F25*680*J24*150%/(((I24-M24)*8+M24*7+J24))*$I$4,0) -> 0 | K25: =IFERROR(ROUND(D25/26*K24,0),0) -> 0 | L25: =IFERROR(ROUND(D25/26*L24,0),0) -> 0 | M25: =IFERROR(ROUND(D25/26*M24,0),0) -> 0 | N25: =IFERROR('Bang TH nop'!T23,0)+IFERROR('Bang TH nop'!P23,0) -> 0 | O25: =+'Bang TH nop'!X23 -> 0 | P25: =+'Bang TH nop'!Q23 -> 0 | Q25: =+'Bang TH nop'!R23 -> 0 | R25: =IFERROR(MAX(G25-I25,0),0) -> 0 | S25: =IFERROR(MAX(H25-J25,0),0) -> 0 | T25: =+'Bang TH nop'!W23 -> 0 | V25: =+'Bang TH nop'!Y23 -> 0 | W25: {=SUM(IFERROR(I25:Q25,0))+IFERROR(T25,0)+IFERROR(U25,0)+IFERROR(V25,0)} -> 0 | X25: =IFERROR(IF((26-(IFERROR(I24,0)+IFERROR(M24,0)+IFERROR(K24,0)+IFERROR(L24,0)))>12,0,D25*10.5%),0) -> 0 | Y25: =IFERROR(ROUND(IF(D25=4939000,D25*0.5%,0),-2),0) -> 0 | Z25: =IFERROR(ROUND(W25-X25-Y25,-2),0) -> 0 | AA25: =IFERROR('Bang TH nop'!J23,0)+IFERROR('Bang TH nop'!V21,0) -> 0 | AD25: =IFERROR(AC25/AB25,0) -> 0 | AE25: =IFERROR(AG25/AA25,0) -> 0 | AF25: =IFERROR(AE25/AD25,0) -> 0 | AG25: =IFERROR(W25-L25,0) -> 0
A26: 9 | B26: ='Bang TH nop'!B25 -> 0 | C26: ='Bang TH nop'!C25 -> 0 | D26: ='Bang TH nop'!H25 -> 0 | I26: ='Bang TH nop'!J25 -> 0 | J26: =+'Bang TH nop'!O25 -> 0 | K26: =+'Bang TH nop'!K25 -> 0 | L26: =+'Bang TH nop'!L25 -> 0 | M26: =+'Bang TH nop'!M25 -> 0 | O26: =+'Bang TH nop'!W25 -> 0
D27: ='Bang TH nop'!I25 -> 0 | F27: ='Bang TH nop'!F25 -> 0 | I27: =IFERROR(F27*680*(((I26-M26)*8+M26*7))/(((I26-M26)*8+M26*7+J26))*$I$4,0) -> 0 | J27: =IFERROR(F27*680*J26*150%/(((I26-M26)*8+M26*7+J26))*$I$4,0) -> 0 | K27: =IFERROR(ROUND(D27/26*K26,0),0) -> 0 | L27: =IFERROR(ROUND(D27/26*L26,0),0) -> 0 | M27: =IFERROR(ROUND(D27/26*M26,0),0) -> 0 | N27: =IFERROR('Bang TH nop'!T25,0)+IFERROR('Bang TH nop'!P25,0) -> 0 | O27: =+'Bang TH nop'!X25 -> 0 | P27: =+'Bang TH nop'!Q25 -> 0 | Q27: =+'Bang TH nop'!R25 -> 0 | R27: =IFERROR(MAX(G27-I27,0),0) -> 0 | S27: =IFERROR(MAX(H27-J27,0),0) -> 0 | T27: =+'Bang TH nop'!W25 -> 0 | V27: =+'Bang TH nop'!Y25 -> 0 | W27: {=SUM(IFERROR(I27:Q27,0))+IFERROR(T27,0)+IFERROR(U27,0)+IFERROR(V27,0)} -> 0 | X27: =IFERROR(IF((26-(IFERROR(I26,0)+IFERROR(M26,0)+IFERROR(K26,0)+IFERROR(L26,0)))>12,0,D27*10.5%),0) -> 0 | Y27: =IFERROR(ROUND(IF(D27=4939000,D27*0.5%,0),-2),0) -> 0 | Z27: =IFERROR(ROUND(W27-X27-Y27,-2),0) -> 0 | AA27: =IFERROR('Bang TH nop'!J25,0)+IFERROR('Bang TH nop'!V23,0) -> 0 | AD27: =IFERROR(AC27/AB27,0) -> 0 | AE27: =IFERROR(AG27/AA27,0) -> 0 | AF27: =IFERROR(AE27/AD27,0) -> 0 | AG27: =IFERROR(W27-L27,0) -> 0
W29: =SUM(I29:Q29)+T29+U29+V29 -> 0 | Y29: =+ROUND(IF(D29=4939000,D29*0.5%,0),-2) -> 0 | AA29: ='[1]Bang TH nop'!AO27 -> 0 | AB29: =+IFERROR(VLOOKUP(C28,'[2]Bản gốc T01'!$C$1:$M$1000,11,0),0) -> 0 | AC29: =+IFERROR(VLOOKUP(C28,'[2]Bản gốc T01'!$C$1:$I$1000,7,0),0) -> 0
W31: =SUM(I31:Q31)+T31+U31+V31 -> 0 | Y31: =+ROUND(IF(D31=4939000,D31*0.5%,0),-2) -> 0 | AA31: ='[1]Bang TH nop'!AO29 -> 0 | AB31: =+IFERROR(VLOOKUP(C30,'[2]Bản gốc T01'!$C$1:$M$1000,11,0),0) -> 0 | AC31: =+IFERROR(VLOOKUP(C30,'[2]Bản gốc T01'!$C$1:$I$1000,7,0),0) -> 0
W33: =SUM(I33:Q33)+T33+U33+V33 -> 0 | Y33: =+ROUND(IF(D33=4939000,D33*0.5%,0),-2) -> 0 | AA33: ='[1]Bang TH nop'!AO31 -> 0 | AB33: =+IFERROR(VLOOKUP(C32,'[2]Bản gốc T01'!$C$1:$M$1000,11,0),0) -> 0 | AC33: =+IFERROR(VLOOKUP(C32,'[2]Bản gốc T01'!$C$1:$I$1000,7,0),0) -> 0
W35: =SUM(I35:Q35)+T35+U35+V35 -> 0 | Y35: =+ROUND(IF(D35=4939000,D35*0.5%,0),-2) -> 0 | AA35: ='[1]Bang TH nop'!AO33 -> 0 | AB35: =+IFERROR(VLOOKUP(C34,'[2]Bản gốc T01'!$C$1:$M$1000,11,0),0) -> 0 | AC35: =+IFERROR(VLOOKUP(C34,'[2]Bản gốc T01'!$C$1:$I$1000,7,0),0) -> 0
W37: =SUM(I37:Q37)+T37+U37+V37 -> 0 | Y37: =+ROUND(IF(D37=4939000,D37*0.5%,0),-2) -> 0 | AA37: ='[1]Bang TH nop'!AO35 -> 0 | AB37: =+IFERROR(VLOOKUP(C36,'[2]Bản gốc T01'!$C$1:$M$1000,11,0),0) -> 0 | AC37: =+IFERROR(VLOOKUP(C36,'[2]Bản gốc T01'!$C$1:$I$1000,7,0),0) -> 0
W39: =SUM(I39:Q39)+T39+U39+V39 -> 0 | Y39: =+ROUND(IF(D39=4939000,D39*0.5%,0),-2) -> 0 | AA39: ='[1]Bang TH nop'!AO37 -> 0 | AB39: =+IFERROR(VLOOKUP(C38,'[2]Bản gốc T01'!$C$1:$M$1000,11,0),0) -> 0 | AC39: =+IFERROR(VLOOKUP(C38,'[2]Bản gốc T01'!$C$1:$I$1000,7,0),0) -> 0
W41: =SUM(I41:Q41)+T41+U41+V41 -> 0 | Y41: =+ROUND(IF(D41=4939000,D41*0.5%,0),-2) -> 0 | AA41: ='[1]Bang TH nop'!AO39 -> 0 | AB41: =+IFERROR(VLOOKUP(C40,'[2]Bản gốc T01'!$C$1:$M$1000,11,0),0) -> 0 | AC41: =+IFERROR(VLOOKUP(C40,'[2]Bản gốc T01'!$C$1:$I$1000,7,0),0) -> 0
W43: =SUM(I43:Q43)+T43+U43+V43 -> 0 | Y43: =+ROUND(IF(D43=4939000,D43*0.5%,0),-2) -> 0 | AA43: ='[1]Bang TH nop'!AO41 -> 0 | AB43: =+IFERROR(VLOOKUP(C42,'[2]Bản gốc T01'!$C$1:$M$1000,11,0),0) -> 0 | AC43: =+IFERROR(VLOOKUP(C42,'[2]Bản gốc T01'!$C$1:$I$1000,7,0),0) -> 0
W45: =SUM(I45:Q45)+T45+U45+V45 -> 0 | Y45: =+ROUND(IF(D45=4939000,D45*0.5%,0),-2) -> 0 | AA45: ='[1]Bang TH nop'!AO43 -> 0 | AB45: =+IFERROR(VLOOKUP(C44,'[2]Bản gốc T01'!$C$1:$M$1000,11,0),0) -> 0 | AC45: =+IFERROR(VLOOKUP(C44,'[2]Bản gốc T01'!$C$1:$I$1000,7,0),0) -> 0
W47: =SUM(I47:Q47)+T47+U47+V47 -> 0 | Y47: =+ROUND(IF(D47=4939000,D47*0.5%,0),-2) -> 0 | AA47: ='[1]Bang TH nop'!AO45 -> 0 | AB47: =+IFERROR(VLOOKUP(C46,'[2]Bản gốc T01'!$C$1:$M$1000,11,0),0) -> 0 | AC47: =+IFERROR(VLOOKUP(C46,'[2]Bản gốc T01'!$C$1:$I$1000,7,0),0) -> 0
W49: =SUM(I49:Q49)+T49+U49+V49 -> 0 | Y49: =+ROUND(IF(D49=4939000,D49*0.5%,0),-2) -> 0 | AA49: ='[1]Bang TH nop'!AO47 -> 0 | AB49: =+IFERROR(VLOOKUP(C48,'[2]Bản gốc T01'!$C$1:$M$1000,11,0),0) -> 0 | AC49: =+IFERROR(VLOOKUP(C48,'[2]Bản gốc T01'!$C$1:$I$1000,7,0),0) -> 0
W51: =SUM(I51:Q51)+T51+U51+V51 -> 0 | Y51: =+ROUND(IF(D51=4939000,D51*0.5%,0),-2) -> 0 | AA51: ='[1]Bang TH nop'!AO49 -> 0 | AB51: =+IFERROR(VLOOKUP(C50,'[2]Bản gốc T01'!$C$1:$M$1000,11,0),0) -> 0 | AC51: =+IFERROR(VLOOKUP(C50,'[2]Bản gốc T01'!$C$1:$I$1000,7,0),0) -> 0
... W133: =SUM(I133:Q133)+T133+U133+V133 -> 0 | Y133: =+ROUND(IF(D133=4939000,D133*0.5%,0),-2) -> 0 | AA133: ='[1]Bang TH nop'!AO131 -> 0 | AB133: =+IFERROR(VLOOKUP(C132,'[2]Bản gốc T01'!$C$1:$M$1000,11,0),0) -> 0 | AC133: =+IFERROR(VLOOKUP(C132,'[2]Bản gốc T01'!$C$1:$I$1000,7,0),0) -> 0
B135: Cộng | F135: =SUM(F10+F12+F14+F16+F18+F20+F22+F24+F26+F28+F30+F32+F34+F36+F38+F40+F42+F44+F48+F50+F52+F54+F56+F58+F60+F62+F64+F66+F68+F70+F72+F74+F76+F78+F80+F82+F84+F86+F88+F90+F92+F94+F96+F98+F100+F132+F46+F102+F104+F106+F108+F110+F112+F114+F116+F126+F128+F130+F118+F120+F122+F124) -> 0 | G135: =SUM(G10+G12+G14+G16+G18+G20+G22+G24+G26+G28+G30+G32+G34+G36+G38+G40+G42+G44+G48+G50+G52+G54+G56+G58+G60+G62+G64+G66+G68+G70+G72+G74+G76+G78+G80+G82+G84+G86+G88+G90+G92+G94+G96+G98+G100+G132+G46+G102+G104+G106+G108+G110+G112+G114+G116+G126+G128+G130+G118+G120+G122+G124) -> 0 | H135: =SUM(H10+H12+H14+H16+H18+H20+H22+H24+H26+H28+H30+H32+H34+H36+H38+H40+H42+H44+H48+H50+H52+H54+H56+H58+H60+H62+H64+H66+H68+H70+H72+H74+H76+H78+H80+H82+H84+H86+H88+H90+H92+H94+H96+H98+H100+H132+H46+H102+H104+H106+H108+H110+H112+H114+H116+H126+H128+H130+H118+H120+H122+H124) -> 0 | I135: {=SUMPRODUCT((MOD(ROW(I10:I132),2)=0)*IFERROR(I10:I132,0))} -> 0 | J135: {=SUMPRODUCT((MOD(ROW(J10:J132),2)=0)*IFERROR(J10:J132,0))} -> 0 | K135: {=SUMPRODUCT((MOD(ROW(K10:K132),2)=0)*IFERROR(K10:K132,0))} -> 0 | L135: {=SUMPRODUCT((MOD(ROW(L10:L132),2)=0)*IFERROR(L10:L132,0))} -> 0 | M135: {=SUMPRODUCT((MOD(ROW(M10:M132),2)=0)*IFERROR(M10:M132,0))} -> 0 | N135: {=SUMPRODUCT((MOD(ROW(N10:N132),2)=0)*IFERROR(N10:N132,0))} -> 0 | O135: {=SUMPRODUCT((MOD(ROW(O10:O132),2)=0)*IFERROR(O10:O132,0))} -> 0 | P135: {=SUMPRODUCT((MOD(ROW(P10:P132),2)=0)*IFERROR(P10:P132,0))} -> 0 | ... AA135: {=SUMPRODUCT((MOD(ROW(AA10:AA132),2)=0)*IFERROR(AA10:AA132,0))} -> 0
F136: =SUM(F11+F13+F15+F17+F19+F21+F23+F25+F27+F29+F31+F33+F35+F37+F39+F41+F43+F45+F49+F51+F53+F55+F57+F59+F61+F63+F65+F67+F69+F71+F73+F75+F77+F79+F81+F83+F85+F87+F89+F91+F93+F95+F97+F99+F101+F133+F47+F103+F105+F107+F109+F111+F113+F115+F117+F127+F129+F131+F119+F121+F123+F125) -> 0 | G136: =SUM(G11+G13+G15+G17+G19+G21+G23+G25+G27+G29+G31+G33+G35+G37+G39+G41+G43+G45+G49+G51+G53+G55+G57+G59+G61+G63+G65+G67+G69+G71+G73+G75+G77+G79+G81+G83+G85+G87+G89+G91+G93+G95+G97+G99+G101+G133+G47+G103+G105+G107+G109+G111+G113+G115+G117+G127+G129+G131+G119+G121+G123+G125) -> 0 | H136: =SUM(H11+H13+H15+H17+H19+H21+H23+H25+H27+H29+H31+H33+H35+H37+H39+H41+H43+H45+H49+H51+H53+H55+H57+H59+H61+H63+H65+H67+H69+H71+H73+H75+H77+H79+H81+H83+H85+H87+H89+H91+H93+H95+H97+H99+H101+H133+H47+H103+H105+H107+H109+H111+H113+H115+H117+H127+H129+H131+H119+H121+H123+H125) -> 0 | I136: {=SUMPRODUCT((MOD(ROW(I11:I133),2)=1)*IFERROR(I11:I133,0))} -> 0 | J136: {=SUMPRODUCT((MOD(ROW(J11:J133),2)=1)*IFERROR(J11:J133,0))} -> 0 | K136: {=SUMPRODUCT((MOD(ROW(K11:K133),2)=1)*IFERROR(K11:K133,0))} -> 0 | L136: {=SUMPRODUCT((MOD(ROW(L11:L133),2)=1)*IFERROR(L11:L133,0))} -> 0 | M136: {=SUMPRODUCT((MOD(ROW(M11:M133),2)=1)*IFERROR(M11:M133,0))} -> 0 | N136: {=SUMPRODUCT((MOD(ROW(N11:N133),2)=1)*IFERROR(N11:N133,0))} -> 0 | O136: {=SUMPRODUCT((MOD(ROW(O11:O133),2)=1)*IFERROR(O11:O133,0))} -> 0 | P136: {=SUMPRODUCT((MOD(ROW(P11:P133),2)=1)*IFERROR(P11:P133,0))} -> 0 | ... AA136: {=SUMPRODUCT((MOD(ROW(AA11:AA133),2)=1)*IFERROR(AA11:AA133,0))} -> 0 | AB136: =IFERROR(W136/(AA136+L135)*(AA140+2),0) -> 0 | AC136: =IFERROR(AG136/AA136*AA140,0) -> 0 | AG136: {=SUMPRODUCT((MOD(ROW(AG11:AG133),2)=1)*IFERROR(AG11:AG133,0))} -> 0
...

Sheet Phieu lương
A1: CÔNG TY TNHH 888 | L1: 26 | M1: CÔNG TY TNHH 888 | X1: 25
A2: STT : 01 | L2: Gián tiếp | M2: STT : 02
A3: PHIẾU CHI TIẾT LƯƠNG | M3: PHIẾU CHI TIẾT LƯƠNG
A4: (01) Họ Và Tên | E4: : | F4: ='[1]Bang TH nop'!B9 -> Nguyễn Văn Bình | M4: (01) Họ Và Tên | Q4: : | R4: Nguyễn Văn Huy
A5: (02) Mã số cá nhân | E5: : | F5: ='[1]Bang TH nop'!C9 -> 50015 | M5: (02) Mã số cá nhân | Q5: : | R5: 50018
A6: (03) Tổ / Bộ phận | E6: : | F6: =$L$2 -> Gián tiếp | M6: (03) Tổ / Bộ phận | Q6: : | R6: =$L$2 -> Gián tiếp
A7: (04) Chức danh: Công nhân vận hành máy may công nghiệp | M7: (04) Chức danh: Công nhân vận hành máy may công nghiệp
A8: (05) Lương cơ bản | E8: : | F8: 3876000 | J8: vnd | M8: (05) Lương cơ bản | Q8: : | R8: 3876000 | V8: vnd
A9: (06) Giây chế tạo | I9: ='[1]LUONG T7'!F11 -> 8232.4 | M9: (06) Giây chế tạo | U9: ='[1]LUONG T7'!F13 -> 8553.4
A10: (07) Lương 1 giờ: | I10: =I11/C11/8 -> 20516.348 | M10: (07) Lương 1 giờ: | U10: =U11/O11/8 -> 24478.723
A11: (08) Công SP | B11: : | C11: ='[1]LUONG T7'!I10 -> 26 | D11: ngày | E11: Lương SP | H11: : | I11: ='[1]LUONG T7'!I11 -> 4267400.3 | K11: vnd | L11: =F8/L1*C11 -> 3876000 | M11: (08) Công SP | N11: : | O11: ='[1]LUONG T7'!I12 -> 26 | P11: ngày | Q11: Lương SP | T11: : | U11: ='[1]LUONG T7'!I13 -> 5091574.4 | W11: vnd | X11: =R8/X1*O11 -> 4031040
A12: (09) Phép | B12: : | C12: ='[1]LUONG T7'!J10 -> 0 | D12: ngày | E12: Lương Phép | H12: : | I12: =$F$8/$L$1*C12 -> 0 | K12: vnd | M12: (09) Phép | N12: : | O12: ='[1]LUONG T7'!J12 -> 0 | P12: ngày | Q12: Lương Phép | T12: : | U12: =$F$8/$L$1*O12 -> 0 | W12: vnd
A13: (10) Lễ, tết | B13: : | C13: ='[1]LUONG T7'!K10 -> 0 | D13: ngày | E13: Lương lễ tết | H13: : | I13: =$F$8/$L$1*C13 -> 0 | K13: vnd | M13: (10) Lễ, tết | N13: : | O13: ='[1]LUONG T7'!K12 -> 0 | P13: ngày | Q13: Lương lễ tết | T13: : | U13: =$F$8/$L$1*O13 -> 0 | W13: vnd
A14: (11) Học, họp | B14: : | C14: ='[1]LUONG T7'!L10 -> 0 | D14: ngày | E14: Lương học họp | H14: : | I14: =$F$8/$L$1*C14 -> 0 | K14: vnd | M14: (11) Học, họp | N14: : | O14: ='[1]LUONG T7'!L12 -> 0 | P14: ngày | Q14: Lương học họp | T14: : | U14: =$F$8/$L$1*O14 -> 0 | W14: vnd
A15: (12) Thêm giờ | B15: : | C15: ='[1]LUONG T7'!Q10 -> 78.5 | D15: Giờ | E15: Lương thêm giờ | H15: : | I15: ='[1]LUONG T7'!Q11 -> 2415799.9 | K15: vnd | L15: =F8*C15/L1/8*1.5 -> 2194226 | M15: (12) Thêm giờ | N15: : | O15: ='[1]LUONG T7'!Q12 -> 70 | P15: Giờ | Q15: Lương thêm giờ | T15: : | U15: ='[1]LUONG T7'!Q13 -> 2570265.9 | W15: vnd | X15: =R8*O15/X1/8*1.5 -> 2034900
A16: (13) Thêm ngày CN | D16: ngày | E16: Lương thêm ngày | H16: : | K16: vnd | M16: (13) Thêm ngày CN | P16: ngày | Q16: Lương thêm ngày | T16: : | W16: vnd
A17: (14) Chờ Việc | B17: : | D17: ngày | E17: Lương chờ việc | H17: : | K17: vnd | M17: (14) Chờ Việc | N17: : | P17: ngày | Q17: Lương chờ việc | T17: : | W17: vnd
A18: (15) Con nhỏ, thai 7 tháng | C18: ='[1]LUONG T7'!M10 -> 0 | D18: Giờ | E18: Lương giờ con nhỏ | H18: : | I18: =$F$8*C18/8/$L$1 -> 0 | K18: vnd | M18: (15) Con nhỏ, thai 7 tháng | O18: ='[1]LUONG T7'!M12 -> 0 | P18: Giờ | Q18: Lương giờ con nhỏ | T18: : | U18: 10000 | W18: vnd
A19: (16) Ca ba | B19: : | D19: Giờ | E19: Cơm ca | H19: : | I19: 240000 | K19: vnd | M19: (16) Ca ba | N19: : | P19: Giờ | Q19: Cơm ca | T19: : | U19: 240000 | W19: vnd
A20: (17) Nóng, độc hại | B20: : | D20: % | E20: Tiền nóng, độc hại | H20: : | K20: vnd | L20: =+IF(L11-I11<0,0,L11-I11)+IF(L15-I15<0,0,L15-I15) -> 0 | M20: (17) Nóng, độc hại | N20: : | P20: % | Q20: Tiền nóng, độc hại | T20: : | W20: vnd | X20: =+IF(X11-U11<0,0,X11-U11)+IF(X15-U15<0,0,X15-U15) -> 0
A21: (18) Khuyến công | D21: ngày | E21: Tiền khuyến công | H21: : | I21: 324000 | K21: vnd | M21: (18) Khuyến công | P21: ngày | Q21: Tiền khuyến công | T21: : | U21: 324000 | W21: vnd
A22: (19) Lương khác | H22: : | I22: ='[1]LUONG T7'!P11 -> 0 | K22: vnd | M22: (19) Lương khác | T22: : | U22: ='[1]LUONG T7'!P13 -> 0 | W22: vnd
A23: (20) Bù lương | B23: : | E23: -------> | H23: : | I23: =L20 -> 0 | K23: vnd | M23: (20) Bù lương | N23: : | Q23: -------> | T23: : | U23: =X20 -> 0 | W23: vnd
A24: (21) Tổng cộng lương | G24: : | H24: =+I21+I11+I12+I13+I14+I15+I18+I22+I23+I19 -> 7247200.2 | K24: vnd | M24: (21) Tổng cộng lương | S24: : | T24: =+U21+U11+U12+U13+U14+U15+U18+U22+U23+U19 -> 8235840.4 | W24: vnd
A26: (22) Khấu trừ | M26: (22) Khấu trừ
A27: BHXH (8%) | G27: : | H27: =IF(($L$1-(C11+C12+C13+C14))>12,0,F8*8%) -> 310080 | K27: vnd | M27: BHXH (8%) | S27: : | T27: =IF(($L$1-(O11+O12+O13+O14))>12,0,R8*8%) -> 310080 | W27: vnd
A28: BHYT (1.5%) | G28: : | H28: =IF(($L$1-(C11+C12+C13+C14))>12,0,F8*1.5%) -> 58140 | K28: vnd | M28: BHYT (1.5%) | S28: : | T28: =IF(($L$1-(O11+O12+O13+O14))>12,0,R8*1.5%) -> 58140 | W28: vnd
A29: BHTN (1%) | G29: : | H29: =IF(($L$1-(C11+C12+C13+C14))>12,0,F8*1%) -> 38760 | K29: vnd | M29: BHTN (1%) | S29: : | T29: =IF(($L$1-(O11+O12+O13+O14))>12,0,R8*1%) -> 38760 | W29: vnd
A30: (23) Thuế | G30: : | H30: 0 | K30: vnd | M30: (23) Thuế | S30: : | T30: 0 | W30: vnd
A31: (24) Tổng khấu trừ | G31: : | H31: =SUM(H27:J30) -> 406980 | K31: vnd | M31: (24) Tổng khấu trừ | S31: : | T31: =SUM(T27:V30) -> 406980 | W31: vnd
A32: (25) Thực lĩnh | G32: : | H32: =ROUND(H24-H31,-2) -> 6840200 | K32: vnd | M32: (25) Thực lĩnh | S32: : | T32: =ROUND(T24-T31,-2) -> 7828900 | W32: vnd
I34: Phụ trách đơn vị | U34: Phụ trách đơn vị
I36: Đã duyệt | U36: Đã duyệt
A39: CÔNG TY TNHH 888 | L39: 25 | M39: CÔNG TY TNHH 888 | X39: 25
A40: STT : 03 | M40: STT : 04
A41: PHIẾU CHI TIẾT LƯƠNG | M41: PHIẾU CHI TIẾT LƯƠNG
A42: (01) Họ Và Tên | E42: : | F42: Phạm Văn Định | M42: (01) Họ Và Tên | Q42: : | R42: Đặng Văn Tá
A43: (02) Mã số cá nhân | E43: : | F43: 50038 | M43: (02) Mã số cá nhân | Q43: : | R43: 50041
A44: (03) Tổ / Bộ phận | E44: : | F44: =$L$2 -> Gián tiếp | M44: (03) Tổ / Bộ phận | Q44: : | R44: =$L$2 -> Gián tiếp
A45: (04) Chức danh: Công nhân vận hành máy may công nghiệp | M45: (04) Chức danh: Công nhân vận hành máy may công nghiệp
...
