Workbook
Name TaxTV: 10%
Name TaxXL: 5%

Sheet Bang TH nop
A1: CÔNG TY TNHH S&D
A2: BẢNG HẾ SỐ HƯỞNG LƯƠNG THÁNG 11/2024
A3: Tổ Gián tiếp
A5: TT | B5: Họ và tên | C5: Mã số | D5: Mức lương CB | E5: Ngày vào | F5: Mức lương | G5: Công | H5: Phép | I5: Lễ tết | J5: Học, họp | K5: Đi lại (Thâm niên) | L5: Thêm giờ | M5: Tiền con nhỏ | N5: Khuyến công | O5: Xăng xe | P5: Phân loại | Q5: PC ATV | R5: Vắt sữa | S5: PCCV | T5: CN
N9: =12000*(G9+U9) -> 0 | O9: =10000*G9 -> 0 | T9: =+IFERROR(VLOOKUP(C9,'[1]507'!$C$5:$AN$10000,38,0),0) -> 0
N11: =12000*(G11+U11) -> 0 | O11: =10000*G11 -> 0 | T11: =+IFERROR(VLOOKUP(C11,'[1]507'!$C$5:$AN$10000,38,0),0) -> 0
N13: =12000*(G13+U13) -> 0 | O13: =10000*G13 -> 0 | T13: =+IFERROR(VLOOKUP(C13,'[1]507'!$C$5:$AN$10000,38,0),0) -> 0
N15: =12000*(G15+U15) -> 0 | O15: =10000*G15 -> 0
E17: =IFERROR(VLOOKUP(C17,'[2]DSCBCNV '!$E$5:$AE$400,27,0),0) -> 0 | F17: =IFERROR(VLOOKUP(C17,'[2]DSCBCNV '!$E$5:$AO$400,37,0),0) -> 0 | G17: =IFERROR(VLOOKUP(C17,[3]T1!$AH$7:$AI$371,2,0),0) -> 0 | H17: =IFERROR(VLOOKUP(C17,[3]T1!$AH$7:$AK$371,4,0),0) -> 0 | I17: =IFERROR(VLOOKUP(C17,[3]T1!$AH$7:$AJ$371,3,0),0) -> 0 | J17: =IFERROR(VLOOKUP(C17,[3]T1!$AH$7:$AO$371,8,0),0) -> 0 | K17: =IFERROR(VLOOKUP(C17,[3]T1!$AH$7:$AM$371,6,0),0) -> 0 | L17: =IFERROR(VLOOKUP(C17,[4]T1!$C$7:$AH$370,32,0),0) -> 0 | N17: =12000*(G17+U17) -> 0 | O17: =10000*G17 -> 0
E19: =IFERROR(VLOOKUP(C19,'[2]DSCBCNV '!$E$5:$AE$400,27,0),0) -> 0 | F19: =IFERROR(VLOOKUP(C19,'[2]DSCBCNV '!$E$5:$AO$400,37,0),0) -> 0 | G19: =IFERROR(VLOOKUP(C19,[3]T1!$AH$7:$AI$371,2,0),0) -> 0 | H19: =IFERROR(VLOOKUP(C19,[3]T1!$AH$7:$AK$371,4,0),0) -> 0 | I19: =IFERROR(VLOOKUP(C19,[3]T1!$AH$7:$AJ$371,3,0),0) -> 0 | J19: =IFERROR(VLOOKUP(C19,[3]T1!$AH$7:$AO$371,8,0),0) -> 0 | K19: =IFERROR(VLOOKUP(C19,[3]T1!$AH$7:$AM$371,6,0),0) -> 0 | L19: =IFERROR(VLOOKUP(C19,[4]T1!$C$7:$AH$370,32,0),0) -> 0 | M19: =IFERROR(VLOOKUP(C19,[5]Sheet1!$A$4:$B$103,2,0),0) -> 0 | N19: =12000*(G19+U19) -> 0 | O19: =10000*G19 -> 0
E21: =IFERROR(VLOOKUP(C21,'[2]DSCBCNV '!$E$5:$AE$400,27,0),0) -> 0 | F21: =IFERROR(VLOOKUP(C21,'[2]DSCBCNV '!$E$5:$AO$400,37,0),0) -> 0 | G21: =IFERROR(VLOOKUP(C21,[3]T1!$AH$7:$AI$371,2,0),0) -> 0 | H21: =IFERROR(VLOOKUP(C21,[3]T1!$AH$7:$AK$371,4,0),0) -> 0 | I21: =IFERROR(VLOOKUP(C21,[3]T1!$AH$7:$AJ$371,3,0),0) -> 0 | J21: =IFERROR(VLOOKUP(C21,[3]T1!$AH$7:$AO$371,8,0),0) -> 0 | K21: =IFERROR(VLOOKUP(C21,[3]T1!$AH$7:$AM$371,6,0),0) -> 0 | L21: =IFERROR(VLOOKUP(C21,[4]T1!$C$7:$AH$370,32,0),0) -> 0 | M21: =IFERROR(VLOOKUP(C21,[5]Sheet1!$A$4:$B$103,2,0),0) -> 0 | N21: =12000*(G21+U21) -> 0 | O21: =10000*G21 -> 0
E23: =IFERROR(VLOOKUP(C23,'[2]DSCBCNV '!$E$5:$AE$400,27,0),0) -> 0 | F23: =IFERROR(VLOOKUP(C23,'[2]DSCBCNV '!$E$5:$AO$400,37,0),0) -> 0 | G23: =IFERROR(VLOOKUP(C23,[3]T1!$AH$7:$AI$371,2,0),0) -> 0 | H23: =IFERROR(VLOOKUP(C23,[3]T1!$AH$7:$AK$371,4,0),0) -> 0 | I23: =IFERROR(VLOOKUP(C23,[3]T1!$AH$7:$AJ$371,3,0),0) -> 0 | J23: =IFERROR(VLOOKUP(C23,[3]T1!$AH$7:$AO$371,8,0),0) -> 0 | K23: =IFERROR(VLOOKUP(C23,[3]T1!$AH$7:$AM$371,6,0),0) -> 0 | L23: =IFERROR(VLOOKUP(C23,[4]T1!$C$7:$AH$370,32,0),0) -> 0 | N23: =12000*(G23+U23) -> 0 | O23: =10000*G23 -> 0
M24: =IFERROR(VLOOKUP(C24,[5]Sheet1!$A$4:$B$103,2,0),0) -> 0
E25: =IFERROR(VLOOKUP(C25,'[2]DSCBCNV '!$E$5:$AE$400,27,0),0) -> 0 | F25: =IFERROR(VLOOKUP(C25,'[2]DSCBCNV '!$E$5:$AO$400,37,0),0) -> 0 | G25: =IFERROR(VLOOKUP(C25,[3]T1!$AH$7:$AI$371,2,0),0) -> 0 | H25: =IFERROR(VLOOKUP(C25,[3]T1!$AH$7:$AK$371,4,0),0) -> 0 | I25: =IFERROR(VLOOKUP(C25,[3]T1!$AH$7:$AJ$371,3,0),0) -> 0 | J25: =IFERROR(VLOOKUP(C25,[3]T1!$AH$7:$AO$371,8,0),0) -> 0 | K25: =IFERROR(VLOOKUP(C25,[3]T1!$AH$7:$AM$371,6,0),0) -> 0 | L25: =IFERROR(VLOOKUP(C25,[4]T1!$C$7:$AH$370,32,0),0) -> 0 | N25: =12000*(G25+U25) -> 0 | O25: =10000*G25 -> 0
M26: =IFERROR(VLOOKUP(C26,[5]Sheet1!$A$4:$B$103,2,0),0) -> 0
E27: =IFERROR(VLOOKUP(C27,'[2]DSCBCNV '!$E$5:$AE$400,27,0),0) -> 0 | F27: =IFERROR(VLOOKUP(C27,'[2]DSCBCNV '!$E$5:$AO$400,37,0),0) -> 0 | G27: =IFERROR(VLOOKUP(C27,[3]T1!$AH$7:$AI$371,2,0),0) -> 0 | H27: =IFERROR(VLOOKUP(C27,[3]T1!$AH$7:$AK$371,4,0),0) -> 0 | I27: =IFERROR(VLOOKUP(C27,[3]T1!$AH$7:$AJ$371,3,0),0) -> 0 | J27: =IFERROR(VLOOKUP(C27,[3]T1!$AH$7:$AO$371,8,0),0) -> 0 | K27: =IFERROR(VLOOKUP(C27,[3]T1!$AH$7:$AM$371,6,0),0) -> 0 | L27: =IFERROR(VLOOKUP(C27,[4]T1!$C$7:$AH$370,32,0),0) -> 0 | N27: =12000*(G27+U27) -> 0 | O27: =10000*G27 -> 0
E29: =IFERROR(VLOOKUP(C29,'[2]DSCBCNV '!$E$5:$AE$400,27,0),0) -> 0 | F29: =IFERROR(VLOOKUP(C29,'[2]DSCBCNV '!$E$5:$AO$400,37,0),0) -> 0 | G29: =IFERROR(VLOOKUP(C29,[3]T1!$AH$7:$AI$371,2,0),0) -> 0 | H29: =IFERROR(VLOOKUP(C29,[3]T1!$AH$7:$AK$371,4,0),0) -> 0 | I29: =IFERROR(VLOOKUP(C29,[3]T1!$AH$7:$AJ$371,3,0),0) -> 0 | J29: =IFERROR(VLOOKUP(C29,[3]T1!$AH$7:$AO$371,8,0),0) -> 0 | K29: =IFERROR(VLOOKUP(C29,[3]T1!$AH$7:$AM$371,6,0),0) -> 0 | L29: =IFERROR(VLOOKUP(C29,[4]T1!$C$7:$AH$370,32,0),0) -> 0 | M29: =IFERROR(VLOOKUP(C29,[5]Sheet1!$A$4:$B$103,2,0),0) -> 0 | N29: =12000*(G29+U29) -> 0 | O29: =10000*G29 -> 0
E31: =IFERROR(VLOOKUP(C31,'[2]DSCBCNV '!$E$5:$AE$400,27,0),0) -> 0 | F31: =IFERROR(VLOOKUP(C31,'[2]DSCBCNV '!$E$5:$AO$400,37,0),0) -> 0 | G31: =IFERROR(VLOOKUP(C31,[3]T1!$AH$7:$AI$371,2,0),0) -> 0 | H31: =IFERROR(VLOOKUP(C31,[3]T1!$AH$7:$AK$371,4,0),0) -> 0 | I31: =IFERROR(VLOOKUP(C31,[3]T1!$AH$7:$AJ$371,3,0),0) -> 0 | J31: =IFERROR(VLOOKUP(C31,[3]T1!$AH$7:$AO$371,8,0),0) -> 0 | K31: =IFERROR(VLOOKUP(C31,[3]T1!$AH$7:$AM$371,6,0),0) -> 0 | L31: =IFERROR(VLOOKUP(C31,[4]T1!$C$7:$AH$370,32,0),0) -> 0 | M31: =IFERROR(VLOOKUP(C31,[5]Sheet1!$A$4:$B$103,2,0),0) -> 0 | N31: =12000*(G31+U31) -> 0 | O31: =10000*G31 -> 0
B46: =B42*G15 -> 0
A93: 10 | M93: =IFERROR(VLOOKUP(C93,[6]t1!A$4:C$523,2,0),0) -> 0
A95: 11 | M95: =IFERROR(VLOOKUP(C95,[6]t1!A$4:C$523,2,0),0) -> 0
A96: 12
M97: =IFERROR(VLOOKUP(C97,[6]t1!A$4:C$523,2,0),0) -> 0
M99: =IFERROR(VLOOKUP(C99,[6]t1!A$4:C$523,2,0),0) -> 0
M101: =IFERROR(VLOOKUP(C101,[6]t1!A$4:C$523,2,0),0) -> 0
M103: =IFERROR(VLOOKUP(C103,[6]t1!A$4:C$523,2,0),0) -> 0
M105: =IFERROR(VLOOKUP(C105,[6]t1!A$4:C$523,2,0),0) -> 0
M107: =IFERROR(VLOOKUP(C107,[6]t1!A$4:C$523,2,0),0) -> 0
M109: =IFERROR(VLOOKUP(C109,[6]t1!A$4:C$523,2,0),0) -> 0
M111: =IFERROR(VLOOKUP(C111,[6]t1!A$4:C$523,2,0),0) -> 0
M113: =IFERROR(VLOOKUP(C113,[6]t1!A$4:C$523,2,0),0) -> 0
M115: =IFERROR(VLOOKUP(C115,[6]t1!A$4:C$523,2,0),0) -> 0
M117: =IFERROR(VLOOKUP(C117,[6]t1!A$4:C$523,2,0),0) -> 0
M119: =IFERROR(VLOOKUP(C119,[6]t1!A$4:C$523,2,0),0) -> 0
M121: =IFERROR(VLOOKUP(C121,[6]t1!A$4:C$523,2,0),0) -> 0
A123: 8 | B123: Lê Thị Hà | C123: 80426 | M123: =IFERROR(VLOOKUP(C123,[6]t1!A$4:C$523,2,0),0) -> 0
A125: 9 | B125: Bùi Huy Ánh | C125: 80462 | M125: =IFERROR(VLOOKUP(C125,[6]t1!A$4:C$523,2,0),0) -> 0
M127: =IFERROR(VLOOKUP(C127,[6]t1!A$4:C$523,2,0),0) -> 0
M129: =IFERROR(VLOOKUP(C129,[6]t1!A$4:C$523,2,0),0) -> 0
M131: =IFERROR(VLOOKUP(C131,[6]t1!A$4:C$523,2,0),0) -> 0
...

Sheet LƯƠNG Tx
A1: CN CÔNG TY TNHH S&D TẠI THANH HOÁ
A3: BP: Bốc xếp | N3: BẢNG CHI TIẾT THANH TOÁN LƯƠNG
N4: Tháng 04 năm 2026
A6: Stt | B6: Họ và tên | C6: Mã Số | D6: Ngày tiếp nhận/ Mức lương CB | F6: Lương SP | H6: Các khoản tiền lương | O6: Các khoản hỗ trợ | W6: Ăn ca | X6: Tổng cộng | Y6: Khấu trừ | AA6: Thực lĩnh | AB6: Ký nhận | AC6: Công T03 | AD6: Lương T03 | AE6: BQT03 | AF6: BQT04 | AG6: So sánh | AH6: Tổng lương thực tế
H7: Công SP | I7: Thêm Giờ | J7: Phép | K7: Lễ, tết | L7: Chủ nhật | M7: Phụ cấp nuôi con nhỏ + ATV | N7: Bốc công ngoài giờ | O7: Chuyên cần | P7: Xăng xe | Q7: Đi lại | R7: Hỗ trợ gửi hàng | S7: Thưởng theo KQKD | T7: bï l­¬ng SP | U7: bï l­¬ng Thªm giê | Y7: BHXH, BHYT, BHTN | Z7: CĐ
W8: Công tiền
A9: 1 | B9: 2 | C9: 3 | D9: 4 | H9: 5 | I9: 6 | J9: 7 | K9: 8 | L9: 9 | M9: 10 | N9: 11 | O9: 12 | P9: 13 | Q9: 14 | R9: 15 | S9: 16 | V9: 18 | W9: 19 | X9: 17 | Y9: 18 | Z9: 19 | AA9: 20 | AB9: 21 | AC9: 22 | AD9: 23 | AE9: 24=23/22 | AF9: 25=27/21 | AG9: 26=25/24 | AH9: 27=17-8
A10: 1 | B10: ='Bang TH nop'!B9 -> 0 | C10: =+'Bang TH nop'!C9 -> 0 | D10: ='Bang TH nop'!E9 -> 0 | H10: ='Bang TH nop'!G9 -> 0 | I10: ='Bang TH nop'!L9 -> 0 | J10: ='Bang TH nop'!H9 -> 0 | K10: ='Bang TH nop'!I9 -> 0 | L10: =+'Bang TH nop'!T9 -> 0
D11: =+'Bang TH nop'!D9 -> 0 | F11: =+'Bang TH nop'!F9 -> 0 | H11: =(F11/26)*H10 -> 0 | I11: =(F11/26/8*150%)*I10 -> 0 | J11: =D11/26*J10 -> 0 | K11: =D11/26*K10 -> 0 | L11: =+F11/26*L10*2 -> 0 | M11: =+'Bang TH nop'!Q9 -> 0 | O11: ='Bang TH nop'!N9 -> 0 | P11: ='Bang TH nop'!O9 -> 0 | Q11: =+'Bang TH nop'!K9 -> 0 | R11: =500000/26*H10 -> 0 | X11: =SUM(H11:S11) -> 0 | Y11: =+IF((26-(H10+J10+K10))>12,0,D11*10.5%) -> 0 | AB11: =+'Bang TH nop'!G9+'Bang TH nop'!T9 -> 0 | AC11: =+IFERROR(VLOOKUP(C10,'[7]Bản gốc T03'!$C$1:$J$2000,8,0),0) -> 0 | AD11: =+IFERROR(VLOOKUP(C10,'[7]Bản gốc T03'!$C$1:$F$1000,4,0),0) -> 0 | AE11: =+AD11/AC11 -> #DIV/0! | AF11: =AH11/AB11 -> #DIV/0! | AG11: =+AF11/AE11 -> #DIV/0! | AH11: =+X11-K11 -> 0
A12: 2 | B12: ='Bang TH nop'!B11 -> 0 | C12: ='Bang TH nop'!C11 -> 0 | D12: ='Bang TH nop'!E11 -> 0 | H12: ='Bang TH nop'!G11 -> 0 | I12: ='Bang TH nop'!L11 -> 0 | J12: ='Bang TH nop'!H11 -> 0 | K12: ='Bang TH nop'!I11 -> 0 | L12: =+'Bang TH nop'!T11 -> 0
D13: =+'Bang TH nop'!D11 -> 0 | F13: =+'Bang TH nop'!F11 -> 0 | H13: =(F13/26)*H12 -> 0 | I13: =(F13/26/8*150%)*I12 -> 0 | J13: =D13/26*J12 -> 0 | K13: =D13/26*K12 -> 0 | L13: =+F13/26*L12*2 -> 0 | M13: =+'Bang TH nop'!Q11 -> 0 | O13: ='Bang TH nop'!N11 -> 0 | P13: ='Bang TH nop'!O11 -> 0 | Q13: =+'Bang TH nop'!K11 -> 0 | X13: =SUM(H13:S13) -> 0 | Y13: =+IF((26-(H12+J12+K12))>12,0,D13*10.5%) -> 0 | AB13: =+'Bang TH nop'!G11+'Bang TH nop'!T11 -> 0 | AC13: =+IFERROR(VLOOKUP(C12,'[7]Bản gốc T03'!$C$1:$J$2000,8,0),0) -> 0 | AD13: =+IFERROR(VLOOKUP(C12,'[7]Bản gốc T03'!$C$1:$F$1000,4,0),0) -> 0 | AE13: =+AD13/AC13 -> #DIV/0! | AF13: =X13/AB13 -> #DIV/0! | AG13: =+AF13/AE13 -> #DIV/0! | AH13: =+X13-K13 -> 0
A14: 3 | B14: ='Bang TH nop'!B13 -> 0 | C14: ='Bang TH nop'!C13 -> 0 | D14: ='Bang TH nop'!E13 -> 0 | H14: ='Bang TH nop'!G13 -> 0 | I14: ='Bang TH nop'!L13 -> 0 | J14: ='Bang TH nop'!H13 -> 0 | K14: ='Bang TH nop'!I13 -> 0 | L14: =+'Bang TH nop'!T13 -> 0
D15: =+'Bang TH nop'!D13 -> 0 | F15: =+'Bang TH nop'!F13 -> 0 | H15: =(F15/26)*H14 -> 0 | I15: =(F15/26/8*150%)*I14 -> 0 | J15: =D15/26*J14 -> 0 | K15: =D15/26*K14 -> 0 | L15: =+F15/26*L14*2 -> 0 | M15: =+'Bang TH nop'!Q13 -> 0 | O15: ='Bang TH nop'!N13 -> 0 | P15: ='Bang TH nop'!O13 -> 0 | Q15: =+'Bang TH nop'!K13 -> 0 | X15: =SUM(H15:S15) -> 0 | Y15: =+IF((26-(H14+J14+K14))>12,0,D15*10.5%) -> 0 | AB15: =+'Bang TH nop'!G13+'Bang TH nop'!T13 -> 0 | AC15: =+IFERROR(VLOOKUP(C14,'[7]Bản gốc T03'!$C$1:$J$2000,8,0),0) -> 0 | AD15: =+IFERROR(VLOOKUP(C14,'[7]Bản gốc T03'!$C$1:$F$1000,4,0),0) -> 0 | AE15: =+AD15/AC15 -> #DIV/0! | AF15: =X15/AB15 -> #DIV/0! | AG15: =+AF15/AE15 -> #DIV/0! | AH15: =+X15-K15 -> 0
A16: 4 | B16: ='Bang TH nop'!B15 -> 0 | C16: ='Bang TH nop'!C15 -> 0 | D16: ='Bang TH nop'!E15 -> 0 | H16: ='Bang TH nop'!G15 -> 0 | I16: ='Bang TH nop'!L15 -> 0 | J16: ='Bang TH nop'!H15 -> 0 | K16: ='Bang TH nop'!I15 -> 0 | L16: =+'Bang TH nop'!T15 -> 0
D17: =+'Bang TH nop'!D15 -> 0 | F17: =+'Bang TH nop'!F15 -> 0 | H17: =(F17/26)*H16 -> 0 | I17: =(F17/26/8*150%)*I16 -> 0 | J17: =D17/26*J16 -> 0 | K17: =D17/26*K16 -> 0 | L17: =+F17/26*L16*2 -> 0 | M17: =+'Bang TH nop'!Q15 -> 0 | O17: ='Bang TH nop'!N15 -> 0 | P17: ='Bang TH nop'!O15 -> 0 | Q17: =+'Bang TH nop'!K15 -> 0 | X17: =SUM(H17:S17) -> 0 | Y17: =+IF((26-(H16+J16+K16))>12,0,D17*10.5%) -> 0 | AB17: =+'Bang TH nop'!G15+'Bang TH nop'!T15 -> 0 | AC17: =+IFERROR(VLOOKUP(C16,'[7]Bản gốc T03'!$C$1:$J$2000,8,0),0) -> 0 | AD17: =+IFERROR(VLOOKUP(C16,'[7]Bản gốc T03'!$C$1:$F$1000,4,0),0) -> 0 | AE17: =+AD17/AC17 -> #DIV/0! | AF17: =X17/AB17 -> #DIV/0! | AG17: =+AF17/AE17 -> #DIV/0! | AH17: =+X17-K17 -> 0
J18: ='Bang TH nop'!H17 -> 0
J19: =D19/26*J18 -> 0 | AC19: =+IFERROR(VLOOKUP(C18,'[8]Bản gốc T02'!$C$1:$J$1000,8,0),0) -> 0 | AD19: =+IFERROR(VLOOKUP(C18,'[8]Bản gốc T02'!$C$1:$F$1000,4,0),0) -> 0 | AH19: =+X19-K19 -> 0
J20: ='Bang TH nop'!H19 -> 0
J21: =D21/26*J20 -> 0 | AC21: =+IFERROR(VLOOKUP(C20,'[8]Bản gốc T02'!$C$1:$J$1000,8,0),0) -> 0 | AD21: =+IFERROR(VLOOKUP(C20,'[8]Bản gốc T02'!$C$1:$F$1000,4,0),0) -> 0 | AH21: =+X21-K21 -> 0
J22: ='Bang TH nop'!H21 -> 0
J23: =D23/26*J22 -> 0 | AC23: =+IFERROR(VLOOKUP(C22,'[8]Bản gốc T02'!$C$1:$J$1000,8,0),0) -> 0 | AD23: =+IFERROR(VLOOKUP(C22,'[8]Bản gốc T02'!$C$1:$F$1000,4,0),0) -> 0 | AH23: =+X23-K23 -> 0
J24: ='Bang TH nop'!H23 -> 0
J25: =D25/26*J24 -> 0 | AC25: =+IFERROR(VLOOKUP(C24,'[8]Bản gốc T02'!$C$1:$J$1000,8,0),0) -> 0 | AD25: =+IFERROR(VLOOKUP(C24,'[8]Bản gốc T02'!$C$1:$F$1000,4,0),0) -> 0 | AH25: =+X25-K25 -> 0
J26: ='Bang TH nop'!H25 -> 0
J27: =D27/26*J26 -> 0 | AC27: =+IFERROR(VLOOKUP(C26,'[8]Bản gốc T02'!$C$1:$J$1000,8,0),0) -> 0 | AD27: =+IFERROR(VLOOKUP(C26,'[8]Bản gốc T02'!$C$1:$F$1000,4,0),0) -> 0 | AH27: =+X27-K27 -> 0
J28: ='Bang TH nop'!H27 -> 0
J29: =D29/26*J28 -> 0 | AC29: =+IFERROR(VLOOKUP(C28,'[8]Bản gốc T02'!$C$1:$J$1000,8,0),0) -> 0 | AD29: =+IFERROR(VLOOKUP(C28,'[8]Bản gốc T02'!$C$1:$F$1000,4,0),0) -> 0 | AH29: =+X29-K29 -> 0
J30: ='Bang TH nop'!H29 -> 0
J31: =D31/26*J30 -> 0 | AC31: =+IFERROR(VLOOKUP(C30,'[8]Bản gốc T02'!$C$1:$J$1000,8,0),0) -> 0 | AD31: =+IFERROR(VLOOKUP(C30,'[8]Bản gốc T02'!$C$1:$F$1000,4,0),0) -> 0 | AH31: =+X31-K31 -> 0
J32: ='Bang TH nop'!H31 -> 0
J33: =D33/26*J32 -> 0 | AC33: =+IFERROR(VLOOKUP(C32,'[8]Bản gốc T02'!$C$1:$J$1000,8,0),0) -> 0 | AD33: =+IFERROR(VLOOKUP(C32,'[8]Bản gốc T02'!$C$1:$F$1000,4,0),0) -> 0 | AH33: =+X33-K33 -> 0
J34: ='Bang TH nop'!H33 -> 0
J35: =D35/26*J34 -> 0 | AC35: =+IFERROR(VLOOKUP(C34,'[8]Bản gốc T02'!$C$1:$J$1000,8,0),0) -> 0 | AD35: =+IFERROR(VLOOKUP(C34,'[8]Bản gốc T02'!$C$1:$F$1000,4,0),0) -> 0 | AH35: =+X35-K35 -> 0
J36: ='Bang TH nop'!H35 -> 0
J37: =D37/26*J36 -> 0 | AC37: =+IFERROR(VLOOKUP(C36,'[8]Bản gốc T02'!$C$1:$J$1000,8,0),0) -> 0 | AD37: =+IFERROR(VLOOKUP(C36,'[8]Bản gốc T02'!$C$1:$F$1000,4,0),0) -> 0 | AH37: =+X37-K37 -> 0
J38: ='Bang TH nop'!H37 -> 0
J39: =D39/26*J38 -> 0 | AC39: =+IFERROR(VLOOKUP(C38,'[8]Bản gốc T02'!$C$1:$J$1000,8,0),0) -> 0 | AD39: =+IFERROR(VLOOKUP(C38,'[8]Bản gốc T02'!$C$1:$F$1000,4,0),0) -> 0 | AH39: =+X39-K39 -> 0
J40: ='Bang TH nop'!H39 -> 0
J41: =D41/26*J40 -> 0 | AC41: =+IFERROR(VLOOKUP(C40,'[8]Bản gốc T02'!$C$1:$J$1000,8,0),0) -> 0 | AD41: =+IFERROR(VLOOKUP(C40,'[8]Bản gốc T02'!$C$1:$F$1000,4,0),0) -> 0 | AH41: =+X41-K41 -> 0
J42: ='Bang TH nop'!H41 -> 0
...

Sheet Phieu lương
A1: CÔNG TY TNHH 888 | L1: 26 | M1: CÔNG TY TNHH 888 | X1: 25
A2: STT : 01 | L2: Gián tiếp | M2: STT : 02
A3: PHIẾU CHI TIẾT LƯƠNG | M3: PHIẾU CHI TIẾT LƯƠNG
A4: (01) Họ Và Tên | E4: : | F4: ='[9]Bang TH nop'!B9 -> #REF! | M4: (01) Họ Và Tên | Q4: : | R4: Nguyễn Văn Huy
A5: (02) Mã số cá nhân | E5: : | F5: ='[9]Bang TH nop'!C9 -> #REF! | M5: (02) Mã số cá nhân | Q5: : | R5: 50018
A6: (03) Tổ / Bộ phận | E6: : | F6: =$L$2 -> Gián tiếp | M6: (03) Tổ / Bộ phận | Q6: : | R6: =$L$2 -> Gián tiếp
A7: (04) Chức danh: Công nhân vận hành máy may công nghiệp | M7: (04) Chức danh: Công nhân vận hành máy may công nghiệp
A8: (05) Lương cơ bản | E8: : | F8: 3876000 | J8: vnd | M8: (05) Lương cơ bản | Q8: : | R8: 3876000 | V8: vnd
A9: (06) Giây chế tạo | I9: ='[9]LUONG T7'!#REF! -> #REF! | M9: (06) Giây chế tạo | U9: ='[9]LUONG T7'!#REF! -> #REF!
A10: (07) Lương 1 giờ: | I10: =I11/C11/8 -> #REF! | M10: (07) Lương 1 giờ: | U10: =U11/O11/8 -> #REF!
A11: (08) Công SP | B11: : | C11: ='[9]LUONG T7'!#REF! -> #REF! | D11: ngày | E11: Lương SP | H11: : | I11: ='[9]LUONG T7'!#REF! -> #REF! | K11: vnd | L11: =F8/L1*C11 -> #REF! | M11: (08) Công SP | N11: : | O11: ='[9]LUONG T7'!#REF! -> #REF! | P11: ngày | Q11: Lương SP | T11: : | U11: ='[9]LUONG T7'!#REF! -> #REF! | W11: vnd | X11: =R8/X1*O11 -> #REF!
A12: (09) Phép | B12: : | C12: ='[9]LUONG T7'!#REF! -> #REF! | D12: ngày | E12: Lương Phép | H12: : | I12: =$F$8/$L$1*C12 -> #REF! | K12: vnd | M12: (09) Phép | N12: : | O12: ='[9]LUONG T7'!#REF! -> #REF! | P12: ngày | Q12: Lương Phép | T12: : | U12: =$F$8/$L$1*O12 -> #REF! | W12: vnd
A13: (10) Lễ, tết | B13: : | C13: ='[9]LUONG T7'!#REF! -> #REF! | D13: ngày | E13: Lương lễ tết | H13: : | I13: =$F$8/$L$1*C13 -> #REF! | K13: vnd | M13: (10) Lễ, tết | N13: : | O13: ='[9]LUONG T7'!#REF! -> #REF! | P13: ngày | Q13: Lương lễ tết | T13: : | U13: =$F$8/$L$1*O13 -> #REF! | W13: vnd
A14: (11) Học, họp | B14: : | C14: ='[9]LUONG T7'!#REF! -> #REF! | D14: ngày | E14: Lương học họp | H14: : | I14: =$F$8/$L$1*C14 -> #REF! | K14: vnd | M14: (11) Học, họp | N14: : | O14: ='[9]LUONG T7'!#REF! -> #REF! | P14: ngày | Q14: Lương học họp | T14: : | U14: =$F$8/$L$1*O14 -> #REF! | W14: vnd
A15: (12) Thêm giờ | B15: : | C15: ='[9]LUONG T7'!#REF! -> #REF! | D15: Giờ | E15: Lương thêm giờ | H15: : | I15: ='[9]LUONG T7'!#REF! -> #REF! | K15: vnd | L15: =F8*C15/L1/8*1.5 -> #REF! | M15: (12) Thêm giờ | N15: : | O15: ='[9]LUONG T7'!#REF! -> #REF! | P15: Giờ | Q15: Lương thêm giờ | T15: : | U15: ='[9]LUONG T7'!#REF! -> #REF! | W15: vnd | X15: =R8*O15/X1/8*1.5 -> #REF!
A16: (13) Thêm ngày CN | D16: ngày | E16: Lương thêm ngày | H16: : | K16: vnd | M16: (13) Thêm ngày CN | P16: ngày | Q16: Lương thêm ngày | T16: : | W16: vnd
A17: (14) Chờ Việc | B17: : | D17: ngày | E17: Lương chờ việc | H17: : | K17: vnd | M17: (14) Chờ Việc | N17: : | P17: ngày | Q17: Lương chờ việc | T17: : | W17: vnd
A18: (15) Con nhỏ, thai 7 tháng | C18: ='[9]LUONG T7'!#REF! -> #REF! | D18: Giờ | E18: Lương giờ con nhỏ | H18: : | I18: =$F$8*C18/8/$L$1 -> #REF! | K18: vnd | M18: (15) Con nhỏ, thai 7 tháng | O18: ='[9]LUONG T7'!#REF! -> #REF! | P18: Giờ | Q18: Lương giờ con nhỏ | T18: : | U18: 10000 | W18: vnd
A19: (16) Ca ba | B19: : | D19: Giờ | E19: Cơm ca | H19: : | I19: 240000 | K19: vnd | M19: (16) Ca ba | N19: : | P19: Giờ | Q19: Cơm ca | T19: : | U19: 240000 | W19: vnd
A20: (17) Nóng, độc hại | B20: : | D20: % | E20: Tiền nóng, độc hại | H20: : | K20: vnd | L20: =+IF(L11-I11<0,0,L11-I11)+IF(L15-I15<0,0,L15-I15) -> #REF! | M20: (17) Nóng, độc hại | N20: : | P20: % | Q20: Tiền nóng, độc hại | T20: : | W20: vnd | X20: =+IF(X11-U11<0,0,X11-U11)+IF(X15-U15<0,0,X15-U15) -> #REF!
A21: (18) Khuyến công | D21: ngày | E21: Tiền khuyến công | H21: : | I21: 324000 | K21: vnd | M21: (18) Khuyến công | P21: ngày | Q21: Tiền khuyến công | T21: : | U21: 324000 | W21: vnd
A22: (19) Lương khác | H22: : | I22: ='[9]LUONG T7'!#REF! -> #REF! | K22: vnd | M22: (19) Lương khác | T22: : | U22: ='[9]LUONG T7'!#REF! -> #REF! | W22: vnd
A23: (20) Bù lương | B23: : | E23: -------> | H23: : | I23: =L20 -> #REF! | K23: vnd | M23: (20) Bù lương | N23: : | Q23: -------> | T23: : | U23: =X20 -> #REF! | W23: vnd
A24: (21) Tổng cộng lương | G24: : | H24: =+I21+I11+I12+I13+I14+I15+I18+I22+I23+I19 -> #REF! | K24: vnd | M24: (21) Tổng cộng lương | S24: : | T24: =+U21+U11+U12+U13+U14+U15+U18+U22+U23+U19 -> #REF! | W24: vnd
A26: (22) Khấu trừ | M26: (22) Khấu trừ
A27: BHXH (8%) | G27: : | H27: =IF(($L$1-(C11+C12+C13+C14))>12,0,F8*8%) -> #REF! | K27: vnd | M27: BHXH (8%) | S27: : | T27: =IF(($L$1-(O11+O12+O13+O14))>12,0,R8*8%) -> #REF! | W27: vnd
A28: BHYT (1.5%) | G28: : | H28: =IF(($L$1-(C11+C12+C13+C14))>12,0,F8*1.5%) -> #REF! | K28: vnd | M28: BHYT (1.5%) | S28: : | T28: =IF(($L$1-(O11+O12+O13+O14))>12,0,R8*1.5%) -> #REF! | W28: vnd
A29: BHTN (1%) | G29: : | H29: =IF(($L$1-(C11+C12+C13+C14))>12,0,F8*1%) -> #REF! | K29: vnd | M29: BHTN (1%) | S29: : | T29: =IF(($L$1-(O11+O12+O13+O14))>12,0,R8*1%) -> #REF! | W29: vnd
A30: (23) Thuế | G30: : | H30: 0 | K30: vnd | M30: (23) Thuế | S30: : | T30: 0 | W30: vnd
A31: (24) Tổng khấu trừ | G31: : | H31: =SUM(H27:J30) -> #REF! | K31: vnd | M31: (24) Tổng khấu trừ | S31: : | T31: =SUM(T27:V30) -> #REF! | W31: vnd
A32: (25) Thực lĩnh | G32: : | H32: =ROUND(H24-H31,-2) -> #REF! | K32: vnd | M32: (25) Thực lĩnh | S32: : | T32: =ROUND(T24-T31,-2) -> #REF! | W32: vnd
I34: Phụ trách đơn vị | U34: Phụ trách đơn vị
I36: Đã duyệt | U36: Đã duyệt
A39: CÔNG TY TNHH 888 | L39: 25 | M39: CÔNG TY TNHH 888 | X39: 25
A40: STT : 03 | M40: STT : 04
A41: PHIẾU CHI TIẾT LƯƠNG | M41: PHIẾU CHI TIẾT LƯƠNG
A42: (01) Họ Và Tên | E42: : | F42: Phạm Văn Định | M42: (01) Họ Và Tên | Q42: : | R42: Đặng Văn Tá
A43: (02) Mã số cá nhân | E43: : | F43: 50038 | M43: (02) Mã số cá nhân | Q43: : | R43: 50041
A44: (03) Tổ / Bộ phận | E44: : | F44: =$L$2 -> Gián tiếp | M44: (03) Tổ / Bộ phận | Q44: : | R44: =$L$2 -> Gián tiếp
A45: (04) Chức danh: Công nhân vận hành máy may công nghiệp | M45: (04) Chức danh: Công nhân vận hành máy may công nghiệp
...
