Workbook
Name TaxTV: 10%
Name TaxXL: 5%

Sheet Bang TH nop
A1: CÔNG TY TNHH SD
A2: BẢNG HẾ SỐ HƯỞNG LƯƠNG THÁNG 10/2025
A3: Tổ Gián tiếp
S4: A | T4: B | U4: C
A5: TT | B5: Họ và tên | C5: Mã số | D5: Hệ số hưởng lương | E5: Giây / HS | F5: Giây hưởng lương | G5: Giây/1 công | H5: Ngày vào | I5: Mức lương | J5: Công | K5: Phép | L5: lễ tết | M5: Học, họp | N5: Thai 7 tháng | O5: Thêm giờ | P5: Tiền con nhỏ | Q5: Khuyến công | R5: Xăng xe | S5: Phân loại | T5: PC ATV | U5: Vắt sữa | V5: CN | W5: Thâm niên | X5: HT | Y5: Trừ phân loại lđ | Z5: Gửi hàng
F9: =(+E9*D9)/24*J9+400*V9 -> 0 | G9: =F9/J9 -> #DIV/0! | R9: =10000*J9 -> 0 | Y9: =-IF(S9=$S$4,0,IF(S9=$T$4,15*680*J9,IF(S9=$U$4,30*680*J9,IF(S9=0,50*680*J9)))) -> 0
F11: =(+E11*D11)/24*J11+400*V11 -> 0 | G11: =F11/J11 -> #DIV/0! | R11: =10000*J11 -> 0 | Y11: =-IF(S11=$S$4,0,IF(S11=$T$4,15*680*J11,IF(S11=$U$4,30*680*J11,IF(S11=0,50*680*J11)))) -> 0
F13: =(+E13*D13)/24*J13+400*V13 -> 0 | G13: =F13/J13 -> #DIV/0! | R13: =10000*J13 -> 0 | Y13: =-IF(S13=$S$4,0,IF(S13=$T$4,15*680*J13,IF(S13=$U$4,30*680*J13,IF(S13=0,50*680*J13)))) -> 0
F15: =(+E15*D15)/24*J15+400*V15 -> 0 | G15: =F15/J15 -> #DIV/0! | R15: =10000*J15 -> 0
F17: =(+E17*D17)/24*J17+400*V17 -> 0 | G17: =F17/J17 -> #DIV/0! | R17: =10000*J17 -> 0
F19: =(+E19*D19)/24*J19+400*V19 -> 0 | G19: =F19/J19 -> #DIV/0! | R19: =10000*J19 -> 0
F21: =(+E21*D21)/24*J21+400*V21 -> 0 | G21: =F21/J21 -> #DIV/0! | R21: =10000*J21 -> 0
F23: =(+E23*D23)/24*J23+400*V23 -> 0 | G23: =F23/J23 -> #DIV/0! | R23: =10000*J23 -> 0
F25: =(+E25*D25)/24*J25+400*V25 -> 0 | G25: =F25/J25 -> #DIV/0! | R25: =10000*J25 -> 0
F27: =(+E27*D27)/24*J27+400*V27 -> 0 | G27: =F27/J27 -> #DIV/0! | R27: =10000*J27 -> 0
F29: =(+E29*D29)/24*J29+400*V29 -> 0 | G29: =F29/J29 -> #DIV/0! | R29: =10000*J29 -> 0
F31: =(+E31*D31)/24*J31+400*V31 -> 0 | G31: =F31/J31 -> #DIV/0! | R31: =10000*J31 -> 0
F33: =(+E33*D33)/24*J33+400*V33 -> 0 | G33: =F33/J33 -> #DIV/0! | R33: =10000*J33 -> 0
F35: =(+E35*D35)/24*J35+400*V35 -> 0 | G35: =F35/J35 -> #DIV/0! | R35: =10000*J35 -> 0
F37: =(+E37*D37)/24*J37+400*V37 -> 0 | G37: =F37/J37 -> #DIV/0! | R37: =10000*J37 -> 0
... F53: =(+E53*D53)/24*J53+400*V53 -> 0 | G53: =F53/J53 -> #DIV/0! | R53: =10000*J53 -> 0
P83: =IFERROR(VLOOKUP(C83,[1]t1!A$4:C$523,2,0),0) -> 0
P85: =IFERROR(VLOOKUP(C85,[1]t1!A$4:C$523,2,0),0) -> 0
P87: =IFERROR(VLOOKUP(C87,[1]t1!A$4:C$523,2,0),0) -> 0
A89: 10 | F89: =E89*40%+D89*E89 -> 0 | G89: =F89/24.5 -> 0 | P89: =IFERROR(VLOOKUP(C89,[1]t1!A$4:C$523,2,0),0) -> 0
A91: 11 | P91: =IFERROR(VLOOKUP(C91,[1]t1!A$4:C$523,2,0),0) -> 0
A92: 12
P93: =IFERROR(VLOOKUP(C93,[1]t1!A$4:C$523,2,0),0) -> 0
P95: =IFERROR(VLOOKUP(C95,[1]t1!A$4:C$523,2,0),0) -> 0
P97: =IFERROR(VLOOKUP(C97,[1]t1!A$4:C$523,2,0),0) -> 0
P99: =IFERROR(VLOOKUP(C99,[1]t1!A$4:C$523,2,0),0) -> 0
P101: =IFERROR(VLOOKUP(C101,[1]t1!A$4:C$523,2,0),0) -> 0
P103: =IFERROR(VLOOKUP(C103,[1]t1!A$4:C$523,2,0),0) -> 0
P105: =IFERROR(VLOOKUP(C105,[1]t1!A$4:C$523,2,0),0) -> 0
P107: =IFERROR(VLOOKUP(C107,[1]t1!A$4:C$523,2,0),0) -> 0
P109: =IFERROR(VLOOKUP(C109,[1]t1!A$4:C$523,2,0),0) -> 0
P111: =IFERROR(VLOOKUP(C111,[1]t1!A$4:C$523,2,0),0) -> 0
P113: =IFERROR(VLOOKUP(C113,[1]t1!A$4:C$523,2,0),0) -> 0
P115: =IFERROR(VLOOKUP(C115,[1]t1!A$4:C$523,2,0),0) -> 0
P117: =IFERROR(VLOOKUP(C117,[1]t1!A$4:C$523,2,0),0) -> 0
...

Sheet LƯƠNG Tx
A1: CN CÔNG TY TNHH S&D TẠI THANH HOÁ
A3: BP: Văn phòng | O3: BẢNG CHI TIẾT THANH TOÁN LƯƠNG
F4: PC | I4: 1 | O4: Tháng 04 năm 2026
A6: Stt | B6: Họ và tên | C6: Mã Số | D6: Ngày tiếp nhận/ Mức lương CB | I6: Các khoản tiền lương | O6: Các khoản hỗ trợ | X6: Thưởng theo KQKD | Y6: Trừ PLLĐ | Z6: Tổng cộng | AA6: Khấu trừ | AC6: Thực lĩnh | AD6: Ký nhận | AE6: Công T03 | AF6: Lương T03 | AG6: BQT03 | AH6: BQT04 | AI6: So sánh | AJ6: Tổng lương thực tế
F7: Tổng giây | I7: Sản phẩm CBCV | J7: Thêm giờ | K7: Phép | L7: Lễ tết | M7: Mang thai | N7: Con nhỏ + Vắt sữa | O7: Chuyên cần | P7: Đi lại | Q7: Chăm hoa | R7: Xăng xe | S7: Hỗ trợ Hà Trung | T7: Nuôi con nhỏ+ATV | U7: Ăn ca | V7: bï l­¬ng SP | W7: bï l­¬ng Thªm giê | AA7: BHXH, BHYT, BHTN | AB7: CĐ
G8: Bù lương
A9: 1 | B9: 2 | C9: 3 | D9: 4 | I9: 5 | J9: 6 | K9: 7 | L9: 8 | M9: 9 | N9: 10 | O9: 11 | P9: 12 | Q9: 13 | R9: 14 | S9: 15 | T9: 16 | U9: 17 | X9: 18 | Y9: 19 | Z9: 20 | AA9: 21 | AB9: 22 | AC9: 23 | AD9: 24 | AE9: 25 | AF9: 26 | AG9: 27=26/25 | AH9: 28=30/24 | AI9: 29=28/27 | AJ9: 30=20-8-9
A10: 1 | B10: ='Bang TH nop'!B9 -> 0 | C10: ='Bang TH nop'!C9 -> 0 | D10: ='Bang TH nop'!H9 -> 0 | I10: ='Bang TH nop'!J9 -> 0 | J10: =+'Bang TH nop'!O9 -> 0 | K10: =+'Bang TH nop'!K9 -> 0 | L10: =+'Bang TH nop'!L9 -> 0 | M10: =+'Bang TH nop'!N9 -> 0 | N10: =+'Bang TH nop'!U9 -> 0 | Y10: =+'Bang TH nop'!S9 -> 0
D11: ='Bang TH nop'!I9 -> 0 | F11: ='Bang TH nop'!F9 -> 0 | G11: =D11*I10/26 -> 0 | H11: =D11*J10*150%/(26*8) -> 0 | I11: =F11*680*(((I10-M10)*8+M10*7))/(((I10-M10)*8+M10*7+J10))*$I$4 -> #DIV/0! | J11: =+F11*680*J10*150%/(((I10-M10)*8+M10*7+J10))*$I$4 -> #DIV/0! | K11: =ROUND(D11/26*K10,) -> 0 | L11: =ROUND(D11/26*L10,) -> 0 | M11: =+D11*M10/(26*8) -> 0 | N11: =ROUND(D11/(26*8)*N10,) -> 0 | O11: ='Bang TH nop'!Q9 -> 0 | P11: =+'Bang TH nop'!W9 -> 0 | R11: ='Bang TH nop'!R9 -> 0 | V11: =+IF(G11-I11<0,0,G11-I11) -> #DIV/0! | W11: =+IF(H11-J11<0,0,H11-J11) -> #DIV/0! | Y11: =+'Bang TH nop'!Y9 -> 0 | Z11: =SUM(I11:U11)+X11+Y11 -> #DIV/0! | AA11: =+IF((26-(I10+K10+L10))>12,0,D11*10.5%) -> 0 | AB11: =+ROUND(IF(D11=4939000,D11*0.5%,0),-2) -> 0 | AC11: =ROUND(Z11-AA11-AB11,-2) -> #DIV/0! | AD11: =+'Bang TH nop'!J9+'Bang TH nop'!V9 -> 0 | AG11: =+AF11/AE11 -> #DIV/0! | AH11: =AJ11/AD11 -> #DIV/0! | AI11: =+AH11/AG11 -> #DIV/0! | AJ11: =+Z11-L11 -> #DIV/0!
A12: 2 | B12: ='Bang TH nop'!B11 -> 0 | C12: ='Bang TH nop'!C11 -> 0 | D12: ='Bang TH nop'!H11 -> 0 | I12: ='Bang TH nop'!J11 -> 0 | J12: =+'Bang TH nop'!O11 -> 0 | K12: =+'Bang TH nop'!K11 -> 0 | L12: =+'Bang TH nop'!L11 -> 0 | M12: =+'Bang TH nop'!N11 -> 0 | N12: =+'Bang TH nop'!U11 -> 0 | Y12: =+'Bang TH nop'!S11 -> 0
D13: ='Bang TH nop'!I11 -> 0 | F13: ='Bang TH nop'!F11 -> 0 | G13: =D13*I12/26 -> 0 | H13: =D13*J12*150%/(26*8) -> 0 | I13: =F13*680*(((I12-M12)*8+M12*7))/(((I12-M12)*8+M12*7+J12))*$I$4 -> #DIV/0! | J13: =+F13*680*J12*150%/(((I12-M12)*8+M12*7+J12))*$I$4 -> #DIV/0! | K13: =ROUND(D13/26*K12,) -> 0 | L13: =ROUND(D13/26*L12,) -> 0 | M13: =+D13*M12/(26*8) -> 0 | N13: =ROUND(D13/(26*8)*N12,) -> 0 | O13: ='Bang TH nop'!Q11 -> 0 | P13: =+'Bang TH nop'!W11 -> 0 | R13: ='Bang TH nop'!R11 -> 0 | V13: =+IF(G13-I13<0,0,G13-I13) -> #DIV/0! | W13: =+IF(H13-J13<0,0,H13-J13) -> #DIV/0! | Y13: =+'Bang TH nop'!Y11 -> 0 | Z13: =SUM(I13:U13)+X13+Y13 -> #DIV/0! | AA13: =+IF((26-(I12+K12+L12))>12,0,D13*10.5%) -> 0 | AB13: =+ROUND(IF(D13=4939000,D13*0.5%,0),-2) -> 0 | AC13: =ROUND(Z13-AA13-AB13,-2) -> #DIV/0! | AD13: =+'Bang TH nop'!J11+'Bang TH nop'!V11 -> 0 | AG13: =+AF13/AE13 -> #DIV/0! | AH13: =AJ13/AD13 -> #DIV/0! | AI13: =+AH13/AG13 -> #DIV/0! | AJ13: =+Z13-L13 -> #DIV/0!
A14: 3 | B14: ='Bang TH nop'!B13 -> 0 | C14: ='Bang TH nop'!C13 -> 0 | D14: ='Bang TH nop'!H13 -> 0 | I14: ='Bang TH nop'!J13 -> 0 | J14: =+'Bang TH nop'!O13 -> 0 | K14: =+'Bang TH nop'!K13 -> 0 | L14: =+'Bang TH nop'!L13 -> 0 | M14: =+'Bang TH nop'!N13 -> 0 | N14: =+'Bang TH nop'!U13 -> 0 | Y14: =+'Bang TH nop'!S13 -> 0
D15: ='Bang TH nop'!I13 -> 0 | F15: ='Bang TH nop'!F13 -> 0 | G15: =D15*I14/26 -> 0 | H15: =D15*J14*150%/(26*8) -> 0 | I15: =F15*680*(((I14-M14)*8+M14*7))/(((I14-M14)*8+M14*7+J14))*$I$4 -> #DIV/0! | J15: =+F15*680*J14*150%/(((I14-M14)*8+M14*7+J14))*$I$4 -> #DIV/0! | K15: =ROUND(D15/26*K14,) -> 0 | L15: =ROUND(D15/26*L14,) -> 0 | M15: =+D15*M14/(26*8) -> 0 | N15: =ROUND(D15/(26*8)*N14,) -> 0 | O15: ='Bang TH nop'!Q13 -> 0 | P15: =+'Bang TH nop'!W13 -> 0 | R15: ='Bang TH nop'!R13 -> 0 | V15: =+IF(G15-I15<0,0,G15-I15) -> #DIV/0! | W15: =+IF(H15-J15<0,0,H15-J15) -> #DIV/0! | Y15: =+'Bang TH nop'!Y13 -> 0 | Z15: =SUM(I15:U15)+X15+Y15 -> #DIV/0! | AA15: =+IF((26-(I14+K14+L14))>12,0,D15*10.5%) -> 0 | AB15: =+ROUND(IF(D15=4939000,D15*0.5%,0),-2) -> 0 | AC15: =ROUND(Z15-AA15-AB15,-2) -> #DIV/0! | AD15: =+'Bang TH nop'!J13+'Bang TH nop'!V13 -> 0 | AG15: =+AF15/AE15 -> #DIV/0! | AH15: =AJ15/AD15 -> #DIV/0! | AI15: =+AH15/AG15 -> #DIV/0! | AJ15: =+Z15-L15 -> #DIV/0!
A16: 4 | B16: ='Bang TH nop'!B15 -> 0 | C16: ='Bang TH nop'!C15 -> 0 | D16: ='Bang TH nop'!H15 -> 0 | I16: ='Bang TH nop'!J15 -> 0 | J16: =+'Bang TH nop'!O15 -> 0 | K16: =+'Bang TH nop'!K15 -> 0 | L16: =+'Bang TH nop'!L15 -> 0 | M16: =+'Bang TH nop'!N15 -> 0 | N16: =+'Bang TH nop'!U15 -> 0 | Y16: =+'Bang TH nop'!S15 -> 0
D17: ='Bang TH nop'!I15 -> 0 | F17: ='Bang TH nop'!F15 -> 0 | G17: =D17*I16/26 -> 0 | H17: =D17*J16*150%/(26*8) -> 0 | I17: =F17*680*(((I16-M16)*8+M16*7))/(((I16-M16)*8+M16*7+J16))*$I$4 -> #DIV/0! | J17: =+F17*680*J16*150%/(((I16-M16)*8+M16*7+J16))*$I$4 -> #DIV/0! | K17: =ROUND(D17/26*K16,) -> 0 | L17: =ROUND(D17/26*L16,) -> 0 | M17: =+D17*M16/(26*8) -> 0 | N17: =ROUND(D17/(26*8)*N16,) -> 0 | O17: ='Bang TH nop'!Q15 -> 0 | P17: =+'Bang TH nop'!W15 -> 0 | R17: ='Bang TH nop'!R15 -> 0 | V17: =+IF(G17-I17<0,0,G17-I17) -> #DIV/0! | W17: =+IF(H17-J17<0,0,H17-J17) -> #DIV/0! | Y17: =+'Bang TH nop'!Y15 -> 0 | Z17: =SUM(I17:U17)+X17+Y17 -> #DIV/0! | AA17: =+IF((26-(I16+K16+L16))>12,0,D17*10.5%) -> 0 | AB17: =+ROUND(IF(D17=4939000,D17*0.5%,0),-2) -> 0 | AC17: =ROUND(Z17-AA17-AB17,-2) -> #DIV/0! | AD17: =+'Bang TH nop'!J15+'Bang TH nop'!V15 -> 0 | AG17: =+AF17/AE17 -> #DIV/0! | AH17: =AJ17/AD17 -> #DIV/0! | AI17: =+AH17/AG17 -> #DIV/0! | AJ17: =+Z17-L17 -> #DIV/0!
A18: 5 | B18: ='Bang TH nop'!B17 -> 0 | C18: ='Bang TH nop'!C17 -> 0 | D18: ='Bang TH nop'!H17 -> 0 | I18: ='Bang TH nop'!J17 -> 0 | J18: =+'Bang TH nop'!O17 -> 0 | K18: =+'Bang TH nop'!K17 -> 0 | L18: =+'Bang TH nop'!L17 -> 0 | M18: =+'Bang TH nop'!N17 -> 0 | N18: =+'Bang TH nop'!U17 -> 0 | Y18: =+'Bang TH nop'!S17 -> 0
D19: ='Bang TH nop'!I17 -> 0 | F19: ='Bang TH nop'!F17 -> 0 | G19: =D19*I18/26 -> 0 | H19: =D19*J18*150%/(26*8) -> 0 | I19: =F19*680*(((I18-M18)*8+M18*7))/(((I18-M18)*8+M18*7+J18))*$I$4 -> #DIV/0! | J19: =+F19*680*J18*150%/(((I18-M18)*8+M18*7+J18))*$I$4 -> #DIV/0! | K19: =ROUND(D19/26*K18,) -> 0 | L19: =ROUND(D19/26*L18,) -> 0 | M19: =+D19*M18/(26*8) -> 0 | N19: =ROUND(D19/(26*8)*N18,) -> 0 | O19: ='Bang TH nop'!Q17 -> 0 | P19: =+'Bang TH nop'!W17 -> 0 | R19: ='Bang TH nop'!R17 -> 0 | V19: =+IF(G19-I19<0,0,G19-I19) -> #DIV/0! | W19: =+IF(H19-J19<0,0,H19-J19) -> #DIV/0! | Y19: =+'Bang TH nop'!Y17 -> 0 | Z19: =SUM(I19:U19)+X19+Y19 -> #DIV/0! | AA19: =+IF((26-(I18+K18+L18))>12,0,D19*10.5%) -> 0 | AB19: =+ROUND(IF(D19=4939000,D19*0.5%,0),-2) -> 0 | AC19: =ROUND(Z19-AA19-AB19,-2) -> #DIV/0! | AD19: =+'Bang TH nop'!J17+'Bang TH nop'!V17 -> 0 | AG19: =+AF19/AE19 -> #DIV/0! | AH19: =AJ19/AD19 -> #DIV/0! | AI19: =+AH19/AG19 -> #DIV/0! | AJ19: =+Z19-L19 -> #DIV/0!
A20: 6 | B20: ='Bang TH nop'!B19 -> 0 | C20: ='Bang TH nop'!C19 -> 0 | D20: ='Bang TH nop'!H19 -> 0 | I20: ='Bang TH nop'!J19 -> 0 | J20: =+'Bang TH nop'!O19 -> 0 | K20: =+'Bang TH nop'!K19 -> 0 | L20: =+'Bang TH nop'!L19 -> 0 | M20: =+'Bang TH nop'!N19 -> 0 | N20: =+'Bang TH nop'!U19 -> 0 | Y20: =+'Bang TH nop'!S19 -> 0
D21: ='Bang TH nop'!I19 -> 0 | F21: ='Bang TH nop'!F19 -> 0 | G21: =D21*I20/26 -> 0 | H21: =D21*J20*150%/(26*8) -> 0 | I21: =F21*680*(((I20-M20)*8+M20*7))/(((I20-M20)*8+M20*7+J20))*$I$4 -> #DIV/0! | J21: =+F21*680*J20*150%/(((I20-M20)*8+M20*7+J20))*$I$4 -> #DIV/0! | K21: =ROUND(D21/26*K20,) -> 0 | L21: =ROUND(D21/26*L20,) -> 0 | M21: =+D21*M20/(26*8) -> 0 | N21: =ROUND(D21/(26*8)*N20,) -> 0 | O21: ='Bang TH nop'!Q19 -> 0 | P21: =+'Bang TH nop'!W19 -> 0 | R21: ='Bang TH nop'!R19 -> 0 | V21: =+IF(G21-I21<0,0,G21-I21) -> #DIV/0! | W21: =+IF(H21-J21<0,0,H21-J21) -> #DIV/0! | Y21: =+'Bang TH nop'!Y19 -> 0 | Z21: =SUM(I21:U21)+X21+Y21 -> #DIV/0! | AA21: =+IF((26-(I20+K20+L20))>12,0,D21*10.5%) -> 0 | AB21: =+ROUND(IF(D21=4939000,D21*0.5%,0),-2) -> 0 | AC21: =ROUND(Z21-AA21-AB21,-2) -> #DIV/0! | AD21: =+'Bang TH nop'!J19+'Bang TH nop'!V19 -> 0 | AG21: =+AF21/AE21 -> #DIV/0! | AH21: =AJ21/AD21 -> #DIV/0! | AI21: =+AH21/AG21 -> #DIV/0! | AJ21: =+Z21-L21 -> #DIV/0!
B127: Cộng | F127: =SUM(F10+F12+F14+F16+F18+F20+F22+F24+F26+F28+F30+F32+F34+F36+F40+F42+F44+F46+F48+F50+F52+F54+F56+F58+F60+F62+F64+F66+F68+F70+F72+F74+F76+F78+F80+F82+F84+F86+F88+F90+F92+F124+F38+F94+F96+F98+F100+F102+F104+F106+F108+F118+F120+F122+F110+F112+F114+F116) -> 0 | G127: =SUM(G10+G12+G14+G16+G18+G20+G22+G24+G26+G28+G30+G32+G34+G36+G40+G42+G44+G46+G48+G50+G52+G54+G56+G58+G60+G62+G64+G66+G68+G70+G72+G74+G76+G78+G80+G82+G84+G86+G88+G90+G92+G124+G38+G94+G96+G98+G100+G102+G104+G106+G108+G118+G120+G122+G110+G112+G114+G116) -> 0 | H127: =SUM(H10+H12+H14+H16+H18+H20+H22+H24+H26+H28+H30+H32+H34+H36+H40+H42+H44+H46+H48+H50+H52+H54+H56+H58+H60+H62+H64+H66+H68+H70+H72+H74+H76+H78+H80+H82+H84+H86+H88+H90+H92+H124+H38+H94+H96+H98+H100+H102+H104+H106+H108+H118+H120+H122+H110+H112+H114+H116) -> 0 | I127: =SUM(I10+I12+I14+I16+I18+I20+I22+I24+I26+I28+I30+I32+I34+I36+I40+I42+I44+I46+I48+I50+I52+I54+I56+I58+I60+I62+I64+I66+I68+I70+I72+I74+I76+I78+I80+I82+I84+I86+I88+I90+I92+I124+I38+I94+I96+I98+I100+I102+I104+I106+I108+I118+I120+I122+I110+I112+I114+I116) -> 0 | J127: =SUM(J10+J12+J14+J16+J18+J20+J22+J24+J26+J28+J30+J32+J34+J36+J40+J42+J44+J46+J48+J50+J52+J54+J56+J58+J60+J62+J64+J66+J68+J70+J72+J74+J76+J78+J80+J82+J84+J86+J88+J90+J92+J124+J38+J94+J96+J98+J100+J102+J104+J106+J108+J118+J120+J122+J110+J112+J114+J116) -> 0 | K127: =SUM(K10+K12+K14+K16+K18+K20+K22+K24+K26+K28+K30+K32+K34+K36+K40+K42+K44+K46+K48+K50+K52+K54+K56+K58+K60+K62+K64+K66+K68+K70+K72+K74+K76+K78+K80+K82+K84+K86+K88+K90+K92+K124+K38+K94+K96+K98+K100+K102+K104+K106+K108+K118+K120+K122+K110+K112+K114+K116) -> 0 | L127: =SUM(L10+L12+L14+L16+L18+L20+L22+L24+L26+L28+L30+L32+L34+L36+L40+L42+L44+L46+L48+L50+L52+L54+L56+L58+L60+L62+L64+L66+L68+L70+L72+L74+L76+L78+L80+L82+L84+L86+L88+L90+L92+L124+L38+L94+L96+L98+L100+L102+L104+L106+L108+L118+L120+L122+L110+L112+L114+L116) -> 0 | M127: =SUM(M10+M12+M14+M16+M18+M20+M22+M24+M26+M28+M30+M32+M34+M36+M40+M42+M44+M46+M48+M50+M52+M54+M56+M58+M60+M62+M64+M66+M68+M70+M72+M74+M76+M78+M80+M82+M84+M86+M88+M90+M92+M124+M38+M94+M96+M98+M100+M102+M104+M106+M108+M118+M120+M122+M110+M112+M114+M116) -> 0 | ... O127: =SUM(O10+O12+O14+O16+O18+O20+O22+O24+O26+O28+O30+O32+O34+O36+O40+O42+O44+O46+O48+O50+O52+O54+O56+O58+O60+O62+O64+O66+O68+O70+O72+O74+O76+O78+O80+O82+O84+O86+O88+O90+O92+O124+O38+O94+O96+O98+O100+O102+O104+O106+O108+O118+O120+O122+O110+O112+O114+O116) -> 0 | P127: =SUM(Q10+Q12+Q14+Q16+Q18+Q20+Q22+P24+P26+P28+P30+P32+P34+P36+P40+P42+P44+P46+P48+P50+P52+P54+P56+P58+P60+P62+P64+P66+P68+P70+P72+P74+P76+P78+P80+P82+P84+P86+P88+P90+P92+P124+P38+P94+P96+P98+P100+P102+P104+P106+P108+P118+P120+P122+P110+P112+P114+P116) -> 0 | Q127: =SUM(P10+P12+P14+P16+P18+P20+P22+Q24+Q26+Q28+Q30+Q32+Q34+Q36+Q40+Q42+Q44+Q46+Q48+Q50+Q52+Q54+Q56+Q58+Q60+Q62+Q64+Q66+Q68+Q70+Q72+Q74+Q76+Q78+Q80+Q82+Q84+Q86+Q88+Q90+Q92+Q124+Q38+Q94+Q96+Q98+Q100+Q102+Q104+Q106+Q108+Q118+Q120+Q122+Q110+Q112+Q114+Q116) -> 0 | R127: =SUM(S10+S12+S14+S16+S18+S20+S22+R24+R26+R28+R30+R32+R34+R36+R40+R42+R44+R46+R48+R50+R52+R54+R56+R58+R60+R62+R64+R66+R68+R70+R72+R74+R76+R78+R80+R82+R84+R86+R88+R90+R92+R124+R38+R94+R96+R98+R100+R102+R104+R106+R108+R118+R120+R122+R110+R112+R114+R116) -> 0 | S127: =SUM(R10+R12+R14+R16+R18+R20+R22+S24+S26+S28+S30+S32+S34+S36+S40+S42+S44+S46+S48+S50+S52+S54+S56+S58+S60+S62+S64+S66+S68+S70+S72+S74+S76+S78+S80+S82+S84+S86+S88+S90+S92+S124+S38+S94+S96+S98+S100+S102+S104+S106+S108+S118+S120+S122+S110+S112+S114+S116) -> 0 | T127: =SUM(T10+T12+T14+T16+T18+T20+T22+T24+T26+T28+T30+T32+T34+T36+T40+T42+T44+T46+T48+T50+T52+T54+T56+T58+T60+T62+T64+T66+T68+T70+T72+T74+T76+T78+T80+T82+T84+T86+T88+T90+T92+T124+T38+T94+T96+T98+T100+T102+T104+T106+T108+T118+T120+T122+T110+T112+T114+T116) -> 0 | U127: =SUM(Y10+Y12+Y14+Y16+Y18+Y20+Y22+U24+U26+U28+U30+U32+U34+U36+U40+U42+U44+U46+U48+U50+U52+U54+U56+U58+U60+U62+U64+U66+U68+U70+U72+U74+U76+U78+U80+U82+U84+U86+U88+U90+U92+U124+U38+U94+U96+U98+U100+U102+U104+U106+U108+U118+U120+U122+U110+U112+U114+U116) -> 0 | V127: =SUM(V10+V12+V14+V16+V18+V20+V22+V24+V26+V28+V30+V32+V34+V36+V40+V42+V44+V46+V48+V50+V52+V54+V56+V58+V60+V62+V64+V66+V68+V70+V72+V74+V76+V78+V80+V82+V84+V86+V88+V90+V92+V124+V38+V94+V96+V98+V100+V102+V104+V106+V108+V118+V120+V122+V110+V112+V114+V116) -> 0 | W127: =SUM(W10+W12+W14+W16+W18+W20+W22+W24+W26+W28+W30+W32+W34+W36+W40+W42+W44+W46+W48+W50+W52+W54+W56+W58+W60+W62+W64+W66+W68+W70+W72+W74+W76+W78+W80+W82+W84+W86+W88+W90+W92+W124+W38+W94+W96+W98+W100+W102+W104+W106+W108+W118+W120+W122+W110+W112+W114+W116) -> 0 | X127: =SUM(X10+X12+X14+X16+X18+X20+X22+X24+X26+X28+X30+X32+X34+X36+X40+X42+X44+X46+X48+X50+X52+X54+X56+X58+X60+X62+X64+X66+X68+X70+X72+X74+X76+X78+X80+X82+X84+X86+X88+X90+X92+X124+X38+X94+X96+X98+X100+X102+X104+X106+X108+X118+X120+X122+X110+X112+X114+X116) -> 0 | Y127: =SUM(U10+U12+U14+U16+U18+U20+U22+Y24+Y26+Y28+Y30+Y32+Y34+Y36+Y40+Y42+Y44+Y46+Y48+Y50+Y52+Y54+Y56+Y58+Y60+Y62+Y64+Y66+Y68+Y70+Y72+Y74+Y76+Y78+Y80+Y82+Y84+Y86+Y88+Y90+Y92+Y124+Y38+Y94+Y96+Y98+Y100+Y102+Y104+Y106+Y108+Y118+Y120+Y122+Y110+Y112+Y114+Y116) -> 0 | Z127: =SUM(Z10+Z12+Z14+Z16+Z18+Z20+Z22+Z24+Z26+Z28+Z30+Z32+Z34+Z36+Z40+Z42+Z44+Z46+Z48+Z50+Z52+Z54+Z56+Z58+Z60+Z62+Z64+Z66+Z68+Z70+Z72+Z74+Z76+Z78+Z80+Z82+Z84+Z86+Z88+Z90+Z92+Z124+Z38+Z94+Z96+Z98+Z100+Z102+Z104+Z106+Z108+Z118+Z120+Z122+Z110+Z112+Z114+Z116) -> 0 | AA127: =SUM(AA10+AA12+AA14+AA16+AA18+AA20+AA22+AA24+AA26+AA28+AA30+AA32+AA34+AA36+AA40+AA42+AA44+AA46+AA48+AA50+AA52+AA54+AA56+AA58+AA60+AA62+AA64+AA66+AA68+AA70+AA72+AA74+AA76+AA78+AA80+AA82+AA84+AA86+AA88+AA90+AA92+AA124+AA38+AA94+AA96+AA98+AA100+AA102+AA104+AA106+AA108+AA118+AA120+AA122+AA110+AA112+AA114+AA116) -> 0 | AB127: =SUM(AB10+AB12+AB14+AB16+AB18+AB20+AB22+AB24+AB26+AB28+AB30+AB32+AB34+AB36+AB40+AB42+AB44+AB46+AB48+AB50+AB52+AB54+AB56+AB58+AB60+AB62+AB64+AB66+AB68+AB70+AB72+AB74+AB76+AB78+AB80+AB82+AB84+AB86+AB88+AB90+AB92+AB124+AB38+AB94+AB96+AB98+AB100+AB102+AB104+AB106+AB108+AB118+AB120+AB122+AB110+AB112+AB114+AB116) -> 0 | AC127: =SUM(AC10+AC12+AC14+AC16+AC18+AC20+AC22+AC24+AC26+AC28+AC30+AC32+AC34+AC36+AC40+AC42+AC44+AC46+AC48+AC50+AC52+AC54+AC56+AC58+AC60+AC62+AC64+AC66+AC68+AC70+AC72+AC74+AC76+AC78+AC80+AC82+AC84+AC86+AC88+AC90+AC92+AC124+AC38+AC94+AC96+AC98+AC100+AC102+AC104+AC106+AC108+AC118+AC120+AC122+AC110+AC112+AC114+AC116) -> 0 | AD127: =SUM(AD10+AD12+AD14+AD16+AD18+AD20+AD22+AD24+AD26+AD28+AD30+AD32+AD34+AD36+AD40+AD42+AD44+AD46+AD48+AD50+AD52+AD54+AD56+AD58+AD60+AD62+AD64+AD66+AD68+AD70+AD72+AD74+AD76+AD78+AD80+AD82+AD84+AD86+AD88+AD90+AD92+AD124+AD38+AD94+AD96+AD98+AD100+AD102+AD104+AD106+AD108+AD118+AD120+AD122+AD110+AD112+AD114+AD116) -> 0
F128: =SUM(F11+F13+F15+F17+F19+F21+F23+F25+F27+F29+F31+F33+F35+F37+F41+F43+F45+F47+F49+F51+F53+F55+F57+F59+F61+F63+F65+F67+F69+F71+F73+F75+F77+F79+F81+F83+F85+F87+F89+F91+F93+F125+F39+F95+F97+F99+F101+F103+F105+F107+F109+F119+F121+F123+F111+F113+F115+F117) -> 0 | G128: =SUM(G11+G13+G15+G17+G19+G21+G23+G25+G27+G29+G31+G33+G35+G37+G41+G43+G45+G47+G49+G51+G53+G55+G57+G59+G61+G63+G65+G67+G69+G71+G73+G75+G77+G79+G81+G83+G85+G87+G89+G91+G93+G125+G39+G95+G97+G99+G101+G103+G105+G107+G109+G119+G121+G123+G111+G113+G115+G117) -> 0 | H128: =SUM(H11+H13+H15+H17+H19+H21+H23+H25+H27+H29+H31+H33+H35+H37+H41+H43+H45+H47+H49+H51+H53+H55+H57+H59+H61+H63+H65+H67+H69+H71+H73+H75+H77+H79+H81+H83+H85+H87+H89+H91+H93+H125+H39+H95+H97+H99+H101+H103+H105+H107+H109+H119+H121+H123+H111+H113+H115+H117) -> 0 | I128: =SUM(I11+I13+I15+I17+I19+I21+I23+I25+I27+I29+I31+I33+I35+I37+I41+I43+I45+I47+I49+I51+I53+I55+I57+I59+I61+I63+I65+I67+I69+I71+I73+I75+I77+I79+I81+I83+I85+I87+I89+I91+I93+I125+I39+I95+I97+I99+I101+I103+I105+I107+I109+I119+I121+I123+I111+I113+I115+I117) -> #DIV/0! | J128: =SUM(J11+J13+J15+J17+J19+J21+J23+J25+J27+J29+J31+J33+J35+J37+J41+J43+J45+J47+J49+J51+J53+J55+J57+J59+J61+J63+J65+J67+J69+J71+J73+J75+J77+J79+J81+J83+J85+J87+J89+J91+J93+J125+J39+J95+J97+J99+J101+J103+J105+J107+J109+J119+J121+J123+J111+J113+J115+J117) -> #DIV/0! | K128: =SUM(K11+K13+K15+K17+K19+K21+K23+K25+K27+K29+K31+K33+K35+K37+K41+K43+K45+K47+K49+K51+K53+K55+K57+K59+K61+K63+K65+K67+K69+K71+K73+K75+K77+K79+K81+K83+K85+K87+K89+K91+K93+K125+K39+K95+K97+K99+K101+K103+K105+K107+K109+K119+K121+K123+K111+K113+K115+K117) -> 0 | L128: =SUM(L11+L13+L15+L17+L19+L21+L23+L25+L27+L29+L31+L33+L35+L37+L41+L43+L45+L47+L49+L51+L53+L55+L57+L59+L61+L63+L65+L67+L69+L71+L73+L75+L77+L79+L81+L83+L85+L87+L89+L91+L93+L125+L39+L95+L97+L99+L101+L103+L105+L107+L109+L119+L121+L123+L111+L113+L115+L117) -> 0 | M128: =SUM(M11+M13+M15+M17+M19+M21+M23+M25+M27+M29+M31+M33+M35+M37+M41+M43+M45+M47+M49+M51+M53+M55+M57+M59+M61+M63+M65+M67+M69+M71+M73+M75+M77+M79+M81+M83+M85+M87+M89+M91+M93+M125+M39+M95+M97+M99+M101+M103+M105+M107+M109+M119+M121+M123+M111+M113+M115+M117) -> 0 | ... O128: =SUM(O11+O13+O15+O17+O19+O21+O23+O25+O27+O29+O31+O33+O35+O37+O41+O43+O45+O47+O49+O51+O53+O55+O57+O59+O61+O63+O65+O67+O69+O71+O73+O75+O77+O79+O81+O83+O85+O87+O89+O91+O93+O125+O39+O95+O97+O99+O101+O103+O105+O107+O109+O119+O121+O123+O111+O113+O115+O117) -> 0 | P128: =SUM(Q11+Q13+Q15+Q17+Q19+Q21+Q23+P25+P27+P29+P31+P33+P35+P37+P41+P43+P45+P47+P49+P51+P53+P55+P57+P59+P61+P63+P65+P67+P69+P71+P73+P75+P77+P79+P81+P83+P85+P87+P89+P91+P93+P125+P39+P95+P97+P99+P101+P103+P105+P107+P109+P119+P121+P123+P111+P113+P115+P117) -> 0 | Q128: =SUM(P11+P13+P15+P17+P19+P21+P23+Q25+Q27+Q29+Q31+Q33+Q35+Q37+Q41+Q43+Q45+Q47+Q49+Q51+Q53+Q55+Q57+Q59+Q61+Q63+Q65+Q67+Q69+Q71+Q73+Q75+Q77+Q79+Q81+Q83+Q85+Q87+Q89+Q91+Q93+Q125+Q39+Q95+Q97+Q99+Q101+Q103+Q105+Q107+Q109+Q119+Q121+Q123+Q111+Q113+Q115+Q117) -> 0 | R128: =SUM(S11+S13+S15+S17+S19+S21+S23+R25+R27+R29+R31+R33+R35+R37+R41+R43+R45+R47+R49+R51+R53+R55+R57+R59+R61+R63+R65+R67+R69+R71+R73+R75+R77+R79+R81+R83+R85+R87+R89+R91+R93+R125+R39+R95+R97+R99+R101+R103+R105+R107+R109+R119+R121+R123+R111+R113+R115+R117) -> 0 | S128: =SUM(R11+R13+R15+R17+R19+R21+R23+S25+S27+S29+S31+S33+S35+S37+S41+S43+S45+S47+S49+S51+S53+S55+S57+S59+S61+S63+S65+S67+S69+S71+S73+S75+S77+S79+S81+S83+S85+S87+S89+S91+S93+S125+S39+S95+S97+S99+S101+S103+S105+S107+S109+S119+S121+S123+S111+S113+S115+S117) -> 0 | T128: =SUM(T11+T13+T15+T17+T19+T21+T23+T25+T27+T29+T31+T33+T35+T37+T41+T43+T45+T47+T49+T51+T53+T55+T57+T59+T61+T63+T65+T67+T69+T71+T73+T75+T77+T79+T81+T83+T85+T87+T89+T91+T93+T125+T39+T95+T97+T99+T101+T103+T105+T107+T109+T119+T121+T123+T111+T113+T115+T117) -> 0 | U128: =SUM(Y11+Y13+Y15+Y17+Y19+Y21+Y23+U25+U27+U29+U31+U33+U35+U37+U41+U43+U45+U47+U49+U51+U53+U55+U57+U59+U61+U63+U65+U67+U69+U71+U73+U75+U77+U79+U81+U83+U85+U87+U89+U91+U93+U125+U39+U95+U97+U99+U101+U103+U105+U107+U109+U119+U121+U123+U111+U113+U115+U117) -> 0 | V128: =SUM(V11+V13+V15+V17+V19+V21+V23+V25+V27+V29+V31+V33+V35+V37+V41+V43+V45+V47+V49+V51+V53+V55+V57+V59+V61+V63+V65+V67+V69+V71+V73+V75+V77+V79+V81+V83+V85+V87+V89+V91+V93+V125+V39+V95+V97+V99+V101+V103+V105+V107+V109+V119+V121+V123+V111+V113+V115+V117) -> #DIV/0! | W128: =SUM(W11+W13+W15+W17+W19+W21+W23+W25+W27+W29+W31+W33+W35+W37+W41+W43+W45+W47+W49+W51+W53+W55+W57+W59+W61+W63+W65+W67+W69+W71+W73+W75+W77+W79+W81+W83+W85+W87+W89+W91+W93+W125+W39+W95+W97+W99+W101+W103+W105+W107+W109+W119+W121+W123+W111+W113+W115+W117) -> #DIV/0! | X128: =SUM(X11+X13+X15+X17+X19+X21+X23+X25+X27+X29+X31+X33+X35+X37+X41+X43+X45+X47+X49+X51+X53+X55+X57+X59+X61+X63+X65+X67+X69+X71+X73+X75+X77+X79+X81+X83+X85+X87+X89+X91+X93+X125+X39+X95+X97+X99+X101+X103+X105+X107+X109+X119+X121+X123+X111+X113+X115+X117) -> 0 | Y128: =SUM(U11+U13+U15+U17+U19+U21+U23+Y25+Y27+Y29+Y31+Y33+Y35+Y37+Y41+Y43+Y45+Y47+Y49+Y51+Y53+Y55+Y57+Y59+Y61+Y63+Y65+Y67+Y69+Y71+Y73+Y75+Y77+Y79+Y81+Y83+Y85+Y87+Y89+Y91+Y93+Y125+Y39+Y95+Y97+Y99+Y101+Y103+Y105+Y107+Y109+Y119+Y121+Y123+Y111+Y113+Y115+Y117) -> 0 | Z128: =SUM(Z11+Z13+Z15+Z17+Z19+Z21+Z23+Z25+Z27+Z29+Z31+Z33+Z35+Z37+Z41+Z43+Z45+Z47+Z49+Z51+Z53+Z55+Z57+Z59+Z61+Z63+Z65+Z67+Z69+Z71+Z73+Z75+Z77+Z79+Z81+Z83+Z85+Z87+Z89+Z91+Z93+Z125+Z39+Z95+Z97+Z99+Z101+Z103+Z105+Z107+Z109+Z119+Z121+Z123+Z111+Z113+Z115+Z117) -> #DIV/0! | AA128: =SUM(AA11+AA13+AA15+AA17+AA19+AA21+AA23+AA25+AA27+AA29+AA31+AA33+AA35+AA37+AA41+AA43+AA45+AA47+AA49+AA51+AA53+AA55+AA57+AA59+AA61+AA63+AA65+AA67+AA69+AA71+AA73+AA75+AA77+AA79+AA81+AA83+AA85+AA87+AA89+AA91+AA93+AA125+AA39+AA95+AA97+AA99+AA101+AA103+AA105+AA107+AA109+AA119+AA121+AA123+AA111+AA113+AA115+AA117) -> 0 | AB128: =SUM(AB11+AB13+AB15+AB17+AB19+AB21+AB23+AB25+AB27+AB29+AB31+AB33+AB35+AB37+AB41+AB43+AB45+AB47+AB49+AB51+AB53+AB55+AB57+AB59+AB61+AB63+AB65+AB67+AB69+AB71+AB73+AB75+AB77+AB79+AB81+AB83+AB85+AB87+AB89+AB91+AB93+AB125+AB39+AB95+AB97+AB99+AB101+AB103+AB105+AB107+AB109+AB119+AB121+AB123+AB111+AB113+AB115+AB117) -> 0 | AC128: =SUM(AC11+AC13+AC15+AC17+AC19+AC21+AC23+AC25+AC27+AC29+AC31+AC33+AC35+AC37+AC41+AC43+AC45+AC47+AC49+AC51+AC53+AC55+AC57+AC59+AC61+AC63+AC65+AC67+AC69+AC71+AC73+AC75+AC77+AC79+AC81+AC83+AC85+AC87+AC89+AC91+AC93+AC125+AC39+AC95+AC97+AC99+AC101+AC103+AC105+AC107+AC109+AC119+AC121+AC123+AC111+AC113+AC115+AC117) -> #DIV/0! | AD128: =SUM(AD11+AD13+AD15+AD17+AD19+AD21+AD23+AD25+AD27+AD29+AD31+AD33+AD35+AD37+AD41+AD43+AD45+AD47+AD49+AD51+AD53+AD55+AD57+AD59+AD61+AD63+AD65+AD67+AD69+AD71+AD73+AD75+AD77+AD79+AD81+AD83+AD85+AD87+AD89+AD91+AD93+AD125+AD39+AD95+AD97+AD99+AD101+AD103+AD105+AD107+AD109+AD119+AD121+AD123+AD111+AD113+AD115+AD117) -> 0 | AE128: =+Z128/(AD128+L127)*(AD129+2) -> #DIV/0! | AF128: =AJ128/AD128*AD129 -> #DIV/0! | AJ128: =SUM(AJ11+AJ13+AJ15+AJ17+AJ19+AJ21+AJ23+AJ25+AJ27+AJ29+AJ31+AJ33+AJ35+AJ37+AJ41+AJ43+AJ45+AJ47+AJ49+AJ51+AJ53+AJ55+AJ57+AJ59+AJ61+AJ63+AJ65+AJ67+AJ69+AJ71+AJ73+AJ75+AJ77+AJ79+AJ81+AJ83+AJ85+AJ87+AJ89+AJ91+AJ93+AJ125+AJ39+AJ95+AJ97+AJ99+AJ101+AJ103+AJ105+AJ107+AJ109+AJ119+AJ121+AJ123+AJ111+AJ113+AJ115+AJ117) -> #DIV/0!
C129: Bằng chữ: | E129: {=+_xll.VND(AC128)} -> #NAME? | AD129: =+AVERAGE(AD10:AD21) -> 0 | AE129: =+AE128/(AD129+2) -> #DIV/0! | AF129: =+AF128/AD129 -> #DIV/0!
Z130: Ngày 15 tháng 05 năm 2026
B131: Lập biểu | Z131: Phụ trách đơn vị
B135: Lê Thị Linh | Z135: Lê Văn Bắc

Sheet Phieu lương
A1: CÔNG TY TNHH 888 | L1: 26 | M1: CÔNG TY TNHH 888 | X1: 25
A2: STT : 01 | L2: Gián tiếp | M2: STT : 02
A3: PHIẾU CHI TIẾT LƯƠNG | M3: PHIẾU CHI TIẾT LƯƠNG
A4: (01) Họ Và Tên | E4: : | F4: ='[2]Bang TH nop'!B19 -> 0 | M4: (01) Họ Và Tên | Q4: : | R4: Nguyễn Văn Huy
A5: (02) Mã số cá nhân | E5: : | F5: ='[2]Bang TH nop'!C19 -> 0 | M5: (02) Mã số cá nhân | Q5: : | R5: 50018
A6: (03) Tổ / Bộ phận | E6: : | F6: =$L$2 -> Gián tiếp | M6: (03) Tổ / Bộ phận | Q6: : | R6: =$L$2 -> Gián tiếp
A7: (04) Chức danh: Công nhân vận hành máy may công nghiệp | M7: (04) Chức danh: Công nhân vận hành máy may công nghiệp
A8: (05) Lương cơ bản | E8: : | F8: 3876000 | J8: vnd | M8: (05) Lương cơ bản | Q8: : | R8: 3876000 | V8: vnd
A9: (06) Giây chế tạo | I9: ='[2]LUONG T7'!#REF! -> #REF! | M9: (06) Giây chế tạo | U9: ='[2]LUONG T7'!#REF! -> #REF!
A10: (07) Lương 1 giờ: | I10: =I11/C11/8 -> #REF! | M10: (07) Lương 1 giờ: | U10: =U11/O11/8 -> #REF!
A11: (08) Công SP | B11: : | C11: ='[2]LUONG T7'!#REF! -> #REF! | D11: ngày | E11: Lương SP | H11: : | I11: ='[2]LUONG T7'!#REF! -> #REF! | K11: vnd | L11: =F8/L1*C11 -> #REF! | M11: (08) Công SP | N11: : | O11: ='[2]LUONG T7'!#REF! -> #REF! | P11: ngày | Q11: Lương SP | T11: : | U11: ='[2]LUONG T7'!#REF! -> #REF! | W11: vnd | X11: =R8/X1*O11 -> #REF!
A12: (09) Phép | B12: : | C12: ='[2]LUONG T7'!#REF! -> #REF! | D12: ngày | E12: Lương Phép | H12: : | I12: =$F$8/$L$1*C12 -> #REF! | K12: vnd | M12: (09) Phép | N12: : | O12: ='[2]LUONG T7'!#REF! -> #REF! | P12: ngày | Q12: Lương Phép | T12: : | U12: =$F$8/$L$1*O12 -> #REF! | W12: vnd
A13: (10) Lễ, tết | B13: : | C13: ='[2]LUONG T7'!#REF! -> #REF! | D13: ngày | E13: Lương lễ tết | H13: : | I13: =$F$8/$L$1*C13 -> #REF! | K13: vnd | M13: (10) Lễ, tết | N13: : | O13: ='[2]LUONG T7'!#REF! -> #REF! | P13: ngày | Q13: Lương lễ tết | T13: : | U13: =$F$8/$L$1*O13 -> #REF! | W13: vnd
A14: (11) Học, họp | B14: : | C14: ='[2]LUONG T7'!#REF! -> #REF! | D14: ngày | E14: Lương học họp | H14: : | I14: =$F$8/$L$1*C14 -> #REF! | K14: vnd | M14: (11) Học, họp | N14: : | O14: ='[2]LUONG T7'!#REF! -> #REF! | P14: ngày | Q14: Lương học họp | T14: : | U14: =$F$8/$L$1*O14 -> #REF! | W14: vnd
A15: (12) Thêm giờ | B15: : | C15: ='[2]LUONG T7'!#REF! -> #REF! | D15: Giờ | E15: Lương thêm giờ | H15: : | I15: ='[2]LUONG T7'!#REF! -> #REF! | K15: vnd | L15: =F8*C15/L1/8*1.5 -> #REF! | M15: (12) Thêm giờ | N15: : | O15: ='[2]LUONG T7'!#REF! -> #REF! | P15: Giờ | Q15: Lương thêm giờ | T15: : | U15: ='[2]LUONG T7'!#REF! -> #REF! | W15: vnd | X15: =R8*O15/X1/8*1.5 -> #REF!
A16: (13) Thêm ngày CN | D16: ngày | E16: Lương thêm ngày | H16: : | K16: vnd | M16: (13) Thêm ngày CN | P16: ngày | Q16: Lương thêm ngày | T16: : | W16: vnd
A17: (14) Chờ Việc | B17: : | D17: ngày | E17: Lương chờ việc | H17: : | K17: vnd | M17: (14) Chờ Việc | N17: : | P17: ngày | Q17: Lương chờ việc | T17: : | W17: vnd
A18: (15) Con nhỏ, thai 7 tháng | C18: ='[2]LUONG T7'!#REF! -> #REF! | D18: Giờ | E18: Lương giờ con nhỏ | H18: : | I18: =$F$8*C18/8/$L$1 -> #REF! | K18: vnd | M18: (15) Con nhỏ, thai 7 tháng | O18: ='[2]LUONG T7'!#REF! -> #REF! | P18: Giờ | Q18: Lương giờ con nhỏ | T18: : | U18: 10000 | W18: vnd
A19: (16) Ca ba | B19: : | D19: Giờ | E19: Cơm ca | H19: : | I19: 240000 | K19: vnd | M19: (16) Ca ba | N19: : | P19: Giờ | Q19: Cơm ca | T19: : | U19: 240000 | W19: vnd
A20: (17) Nóng, độc hại | B20: : | D20: % | E20: Tiền nóng, độc hại | H20: : | K20: vnd | L20: =+IF(L11-I11<0,0,L11-I11)+IF(L15-I15<0,0,L15-I15) -> #REF! | M20: (17) Nóng, độc hại | N20: : | P20: % | Q20: Tiền nóng, độc hại | T20: : | W20: vnd | X20: =+IF(X11-U11<0,0,X11-U11)+IF(X15-U15<0,0,X15-U15) -> #REF!
A21: (18) Khuyến công | D21: ngày | E21: Tiền khuyến công | H21: : | I21: 324000 | K21: vnd | M21: (18) Khuyến công | P21: ngày | Q21: Tiền khuyến công | T21: : | U21: 324000 | W21: vnd
A22: (19) Lương khác | H22: : | I22: ='[2]LUONG T7'!#REF! -> #REF! | K22: vnd | M22: (19) Lương khác | T22: : | U22: ='[2]LUONG T7'!#REF! -> #REF! | W22: vnd
A23: (20) Bù lương | B23: : | E23: -------> | H23: : | I23: =L20 -> #REF! | K23: vnd | M23: (20) Bù lương | N23: : | Q23: -------> | T23: : | U23: =X20 -> #REF! | W23: vnd
A24: (21) Tổng cộng lương | G24: : | H24: =+I21+I11+I12+I13+I14+I15+I18+I22+I23+I19 -> #REF! | K24: vnd | M24: (21) Tổng cộng lương | S24: : | T24: =+U21+U11+U12+U13+U14+U15+U18+U22+U23+U19 -> #REF! | W24: vnd
A26: (22) Khấu trừ | M26: (22) Khấu trừ
A27: BHXH (8%) | G27: : | H27: =IF(($L$1-(C11+C12+C13+C14))>12,0,F8*8%) -> #REF! | K27: vnd | M27: BHXH (8%) | S27: : | T27: =IF(($L$1-(O11+O12+O13+O14))>12,0,R8*8%) -> #REF! | W27: vnd
A28: BHYT (1.5%) | G28: : | H28: =IF(($L$1-(C11+C12+C13+C14))>12,0,F8*1.5%) -> #REF! | K28: vnd | M28: BHYT (1.5%) | S28: : | T28: =IF(($L$1-(O11+O12+O13+O14))>12,0,R8*1.5%) -> #REF! | W28: vnd
A29: BHTN (1%) | G29: : | H29: =IF(($L$1-(C11+C12+C13+C14))>12,0,F8*1%) -> #REF! | K29: vnd | M29: BHTN (1%) | S29: : | T29: =IF(($L$1-(O11+O12+O13+O14))>12,0,R8*1%) -> #REF! | W29: vnd
A30: (23) Thuế | G30: : | H30: 0 | K30: vnd | M30: (23) Thuế | S30: : | T30: 0 | W30: vnd
A31: (24) Tổng khấu trừ | G31: : | H31: =SUM(H27:J30) -> #REF! | K31: vnd | M31: (24) Tổng khấu trừ | S31: : | T31: =SUM(T27:V30) -> #REF! | W31: vnd
A32: (25) Thực lĩnh | G32: : | H32: =ROUND(H24-H31,-2) -> #REF! | K32: vnd | M32: (25) Thực lĩnh | S32: : | T32: =ROUND(T24-T31,-2) -> #REF! | W32: vnd
I34: Phụ trách đơn vị | U34: Phụ trách đơn vị
I36: Đã duyệt | U36: Đã duyệt
A39: CÔNG TY TNHH 888 | L39: 25 | M39: CÔNG TY TNHH 888 | X39: 25
A40: STT : 03 | M40: STT : 04
A41: PHIẾU CHI TIẾT LƯƠNG | M41: PHIẾU CHI TIẾT LƯƠNG
A42: (01) Họ Và Tên | E42: : | F42: Phạm Văn Định | M42: (01) Họ Và Tên | Q42: : | R42: Đặng Văn Tá
A43: (02) Mã số cá nhân | E43: : | F43: 50038 | M43: (02) Mã số cá nhân | Q43: : | R43: 50041
A44: (03) Tổ / Bộ phận | E44: : | F44: =$L$2 -> Gián tiếp | M44: (03) Tổ / Bộ phận | Q44: : | R44: =$L$2 -> Gián tiếp
A45: (04) Chức danh: Công nhân vận hành máy may công nghiệp | M45: (04) Chức danh: Công nhân vận hành máy may công nghiệp
...
