Workbook
Name TaxTV: 10%
Name TaxXL: 5%

Sheet 00000000

Sheet 10000000

Sheet Tong hop cac ma
A1: CN CÔNG TY TNHH S&D TẠI THANH HOÁ
A2: BẢNG TỔNG HỢP GIÂY THÁNG 03/2026 - TỔ
A4: STT | B4: Họ và tên | C4: Mã số | R4: PC mã hàng | S4: Tổng giây | T4: Ký nhận
A9: 1 | D9: =xxx!D9 -> 0 | R9: {=+SUMPRODUCT(D9:Q9*$D$3:$Q$3)} -> 0 | S9: =SUM(D9:R9) -> 0
A11: 2 | D11: =xxx!D11 -> 0 | R11: {=+SUMPRODUCT(D11:Q11*$D$3:$Q$3)} -> 0 | S11: =SUM(D11:R11) -> 0
A13: 3 | D13: =xxx!D13 -> 0 | R13: {=+SUMPRODUCT(D13:Q13*$D$3:$Q$3)} -> 0 | S13: =SUM(D13:R13) -> 0
A15: 4 | D15: =xxx!D15 -> 0 | R15: {=+SUMPRODUCT(D15:Q15*$D$3:$Q$3)} -> 0 | S15: =SUM(D15:R15) -> 0
A17: 5 | D17: =xxx!D17 -> 0 | R17: {=+SUMPRODUCT(D17:Q17*$D$3:$Q$3)} -> 0 | S17: =SUM(D17:R17) -> 0
A19: 6 | D19: =xxx!D19 -> 0 | R19: {=+SUMPRODUCT(D19:Q19*$D$3:$Q$3)} -> 0 | S19: =SUM(D19:R19) -> 0
A21: 7 | D21: =xxx!D21 -> 0 | R21: {=+SUMPRODUCT(D21:Q21*$D$3:$Q$3)} -> 0 | S21: =SUM(D21:R21) -> 0
A23: 8 | D23: =xxx!D23 -> 0 | R23: {=+SUMPRODUCT(D23:Q23*$D$3:$Q$3)} -> 0 | S23: =SUM(D23:R23) -> 0
A25: 9 | D25: =xxx!D25 -> 0 | R25: {=+SUMPRODUCT(D25:Q25*$D$3:$Q$3)} -> 0 | S25: =SUM(D25:R25) -> 0
A27: 10 | D27: =xxx!D27 -> 0 | R27: {=+SUMPRODUCT(D27:Q27*$D$3:$Q$3)} -> 0 | S27: =SUM(D27:R27) -> 0
A29: 11 | D29: =xxx!D29 -> 0 | R29: {=+SUMPRODUCT(D29:Q29*$D$3:$Q$3)} -> 0 | S29: =SUM(D29:R29) -> 0
A31: 12 | D31: =xxx!D31 -> 0 | R31: {=+SUMPRODUCT(D31:Q31*$D$3:$Q$3)} -> 0 | S31: =SUM(D31:R31) -> 0
... A223: 108 | D223: =xxx!D223 -> 0 | R223: {=+SUMPRODUCT(D223:Q223*$D$3:$Q$3)} -> 0 | S223: =SUM(D223:R223) -> 0

Sheet Bang TH nop
A1: CN CÔNG TY TNHH S&D TẠI THANH HOÁ
A2: BẢNG TỔNG HỢP GIÂY THÁNG 03/2026- TỔ
K3: A | M3: B | O3: C | W3: 0
A4: TT | B4: Họ và tên | C4: Mã số | D4: Công LĐ | E4: Giây | F4: Tổ 1 | G4: Tổ 2 | H4: Tổ 3 | I4: Tổ 4 | J4: Tổ 5 | K4: Tổ 6 | L4: Tổ 7 | M4: Tổ 8 | N4: Tổ 9 | O4: Tổ 10 | P4: Tổ 11 | Q4: Tổ 12 | R4: Là TP | S4: Kiểm hoá | T4: Cơ động | U4: Cắt | V4: Hoàn thiện | W4: Tái chế | AD4: Giây PS làm thêm ngày…giờ.. | AE4: Nhóm trưởng | AF4: 20% Đ Đ | AG4: Giây phát sinh | AH4: Phân loại lđ | AI4: Giây phụ cấp ngày công 130 | AJ4: Tổng giây | AK4: ĐĐ | AL4: Tổng giây | AM4: Ký nhận | AN4: BQ giây | AO4: Ngày vào | AP4: Mức lương | AQ4: Công | AR4: Phép | AS4: Lễ tết | AT4: Học, họp | AU4: Thai 7 tháng+Con nhỏ | AV4: Thêm giờ | AW4: Tiền con nhỏ | AX4: Giờ kinh nguyệt | AY4: Giờ nghỉ ngắn | AZ4: KN+NN | BA4: Hệ số NN | BB4: Công sản phẩm | BC4: Khuyến công | BD4: Xăng xe | BE4: Vắt sữa | BF4: Chủ nhật | BG4: Trừ tiền phân loại | BH4: ATV | BI4: Khám sức khỏe | BJ4: Thâm niên
AL5: =AJ5+AJ5*AK5% -> 0 | AN5: =AL5-AJ5 -> 0
A9: 1 | B9: ='Tong hop cac ma'!B9 -> 0 | C9: ='Tong hop cac ma'!C9 -> 0 | D9: =AQ9 -> 0 | E9: =+'Tong hop cac ma'!S9 -> 0 | AF9: =IFERROR(SUM(F9:AC9)*0.2,0) -> 0 | AH9: A | AI9: =IFERROR(130*D9,0) -> 0 | AJ9: {=IFERROR(SUM(_xlfn._xlws.FILTER(E9:AI9,ISNUMBER(E9:AI9))),0)} -> 0 | AL9: =IFERROR(AJ9*(1+AK9%),0) -> 0 | AN9: =IFERROR(SUM(E9:AC9)/D9,0) -> 0 | AY9: =IFERROR((AQ9*20)/60,0) -> 0 | AZ9: =IFERROR(AX9 + AY9 + BI9,0) -> 0 | BA9: =IFERROR(AZ9/8,0) -> 0 | BB9: =IFERROR(MAX(AQ9-BA9,0),0) -> 0 | BD9: =IFERROR(10000*D9,0) -> 0 | BG9: =IFERROR(-IF(AH9=$K$3,0,IF(AH9=$M$3,15*680*D9,IF(AH9=$O$3,30*680*D9,IF(AH9=0,50*680*D9,0)))),0) -> 0
B10: ='Tong hop cac ma'!B10 -> 0 | C10: ='Tong hop cac ma'!C10 -> 0 | D10: =AQ10 -> 0
A11: 2 | B11: ='Tong hop cac ma'!B11 -> 0 | C11: ='Tong hop cac ma'!C11 -> 0 | D11: =AQ11 -> 0 | E11: =+'Tong hop cac ma'!S11 -> 0 | AF11: =IFERROR(SUM(F11:AC11)*0.2,0) -> 0 | AH11: A | AI11: =IFERROR(130*D11,0) -> 0 | AJ11: {=IFERROR(SUM(_xlfn._xlws.FILTER(E11:AI11,ISNUMBER(E11:AI11))),0)} -> 0 | AL11: =IFERROR(AJ11*(1+AK11%),0) -> 0 | AN11: =IFERROR(SUM(E11:AC11)/D11,0) -> 0 | AY11: =IFERROR((AQ11*20)/60,0) -> 0 | AZ11: =IFERROR(AX11 + AY11 + BI11,0) -> 0 | BA11: =IFERROR(AZ11/8,0) -> 0 | BB11: =IFERROR(MAX(AQ11-BA11,0),0) -> 0 | BD11: =IFERROR(10000*D11,0) -> 0 | BG11: =IFERROR(-IF(AH11=$K$3,0,IF(AH11=$M$3,15*680*D11,IF(AH11=$O$3,30*680*D11,IF(AH11=0,50*680*D11,0)))),0) -> 0
B12: ='Tong hop cac ma'!B12 -> 0 | C12: ='Tong hop cac ma'!C12 -> 0 | D12: =AQ12 -> 0
A13: 3 | B13: ='Tong hop cac ma'!B13 -> 0 | C13: ='Tong hop cac ma'!C13 -> 0 | D13: =AQ13 -> 0 | E13: =+'Tong hop cac ma'!S13 -> 0 | AF13: =IFERROR(SUM(F13:AC13)*0.2,0) -> 0 | AH13: A | AI13: =IFERROR(130*D13,0) -> 0 | AJ13: {=IFERROR(SUM(_xlfn._xlws.FILTER(E13:AI13,ISNUMBER(E13:AI13))),0)} -> 0 | AL13: =IFERROR(AJ13*(1+AK13%),0) -> 0 | AN13: =IFERROR(SUM(E13:AC13)/D13,0) -> 0 | AY13: =IFERROR((AQ13*20)/60,0) -> 0 | AZ13: =IFERROR(AX13 + AY13 + BI13,0) -> 0 | BA13: =IFERROR(AZ13/8,0) -> 0 | BB13: =IFERROR(MAX(AQ13-BA13,0),0) -> 0 | BD13: =IFERROR(10000*D13,0) -> 0 | BG13: =IFERROR(-IF(AH13=$K$3,0,IF(AH13=$M$3,15*680*D13,IF(AH13=$O$3,30*680*D13,IF(AH13=0,50*680*D13,0)))),0) -> 0
B14: ='Tong hop cac ma'!B14 -> 0 | C14: ='Tong hop cac ma'!C14 -> 0 | D14: =AQ14 -> 0
A15: 4 | B15: ='Tong hop cac ma'!B15 -> 0 | C15: ='Tong hop cac ma'!C15 -> 0 | D15: =AQ15 -> 0 | E15: =+'Tong hop cac ma'!S15 -> 0 | AF15: =IFERROR(SUM(F15:AC15)*0.2,0) -> 0 | AH15: A | AI15: =IFERROR(130*D15,0) -> 0 | AJ15: {=IFERROR(SUM(_xlfn._xlws.FILTER(E15:AI15,ISNUMBER(E15:AI15))),0)} -> 0 | AL15: =IFERROR(AJ15*(1+AK15%),0) -> 0 | AN15: =IFERROR(SUM(E15:AC15)/D15,0) -> 0 | AY15: =IFERROR((AQ15*20)/60,0) -> 0 | AZ15: =IFERROR(AX15 + AY15 + BI15,0) -> 0 | BA15: =IFERROR(AZ15/8,0) -> 0 | BB15: =IFERROR(MAX(AQ15-BA15,0),0) -> 0 | BD15: =IFERROR(10000*D15,0) -> 0 | BG15: =IFERROR(-IF(AH15=$K$3,0,IF(AH15=$M$3,15*680*D15,IF(AH15=$O$3,30*680*D15,IF(AH15=0,50*680*D15,0)))),0) -> 0
B16: ='Tong hop cac ma'!B16 -> 0 | C16: ='Tong hop cac ma'!C16 -> 0 | D16: =AQ16 -> 0
A17: 5 | B17: ='Tong hop cac ma'!B17 -> 0 | C17: ='Tong hop cac ma'!C17 -> 0 | D17: =AQ17 -> 0 | E17: =+'Tong hop cac ma'!S17 -> 0 | AF17: =IFERROR(SUM(F17:AC17)*0.2,0) -> 0 | AH17: A | AI17: =IFERROR(130*D17,0) -> 0 | AJ17: {=IFERROR(SUM(_xlfn._xlws.FILTER(E17:AI17,ISNUMBER(E17:AI17))),0)} -> 0 | AL17: =IFERROR(AJ17*(1+AK17%),0) -> 0 | AN17: =IFERROR(SUM(E17:AC17)/D17,0) -> 0 | AY17: =IFERROR((AQ17*20)/60,0) -> 0 | AZ17: =IFERROR(AX17 + AY17 + BI17,0) -> 0 | BA17: =IFERROR(AZ17/8,0) -> 0 | BB17: =IFERROR(MAX(AQ17-BA17,0),0) -> 0 | BD17: =IFERROR(10000*D17,0) -> 0 | BG17: =IFERROR(-IF(AH17=$K$3,0,IF(AH17=$M$3,15*680*D17,IF(AH17=$O$3,30*680*D17,IF(AH17=0,50*680*D17,0)))),0) -> 0
B18: ='Tong hop cac ma'!B18 -> 0 | C18: ='Tong hop cac ma'!C18 -> 0 | D18: =AQ18 -> 0
A19: 6 | B19: ='Tong hop cac ma'!B19 -> 0 | C19: ='Tong hop cac ma'!C19 -> 0 | D19: =AQ19 -> 0 | E19: =+'Tong hop cac ma'!S19 -> 0 | AF19: =IFERROR(SUM(F19:AC19)*0.2,0) -> 0 | AH19: A | AI19: =IFERROR(130*D19,0) -> 0 | AJ19: {=IFERROR(SUM(_xlfn._xlws.FILTER(E19:AI19,ISNUMBER(E19:AI19))),0)} -> 0 | AL19: =IFERROR(AJ19*(1+AK19%),0) -> 0 | AN19: =IFERROR(SUM(E19:AC19)/D19,0) -> 0 | AY19: =IFERROR((AQ19*20)/60,0) -> 0 | AZ19: =IFERROR(AX19 + AY19 + BI19,0) -> 0 | BA19: =IFERROR(AZ19/8,0) -> 0 | BB19: =IFERROR(MAX(AQ19-BA19,0),0) -> 0 | BD19: =IFERROR(10000*D19,0) -> 0 | BG19: =IFERROR(-IF(AH19=$K$3,0,IF(AH19=$M$3,15*680*D19,IF(AH19=$O$3,30*680*D19,IF(AH19=0,50*680*D19,0)))),0) -> 0
B20: ='Tong hop cac ma'!B20 -> 0 | C20: ='Tong hop cac ma'!C20 -> 0 | D20: =AQ20 -> 0
A21: 7 | B21: ='Tong hop cac ma'!B21 -> 0 | C21: ='Tong hop cac ma'!C21 -> 0 | D21: =AQ21 -> 0 | E21: =+'Tong hop cac ma'!S21 -> 0 | AF21: =IFERROR(SUM(F21:AC21)*0.2,0) -> 0 | AH21: A | AI21: =IFERROR(130*D21,0) -> 0 | AJ21: {=IFERROR(SUM(_xlfn._xlws.FILTER(E21:AI21,ISNUMBER(E21:AI21))),0)} -> 0 | AL21: =IFERROR(AJ21*(1+AK21%),0) -> 0 | AN21: =IFERROR(SUM(E21:AC21)/D21,0) -> 0 | AY21: =IFERROR((AQ21*20)/60,0) -> 0 | AZ21: =IFERROR(AX21 + AY21 + BI21,0) -> 0 | BA21: =IFERROR(AZ21/8,0) -> 0 | BB21: =IFERROR(MAX(AQ21-BA21,0),0) -> 0 | BD21: =IFERROR(10000*D21,0) -> 0 | BG21: =IFERROR(-IF(AH21=$K$3,0,IF(AH21=$M$3,15*680*D21,IF(AH21=$O$3,30*680*D21,IF(AH21=0,50*680*D21,0)))),0) -> 0
B22: ='Tong hop cac ma'!B22 -> 0 | C22: ='Tong hop cac ma'!C22 -> 0 | D22: =AQ22 -> 0
A23: 8 | B23: ='Tong hop cac ma'!B23 -> 0 | C23: ='Tong hop cac ma'!C23 -> 0 | D23: =AQ23 -> 0 | E23: =+'Tong hop cac ma'!S23 -> 0 | AF23: =IFERROR(SUM(F23:AC23)*0.2,0) -> 0 | AH23: A | AI23: =IFERROR(130*D23,0) -> 0 | AJ23: {=IFERROR(SUM(_xlfn._xlws.FILTER(E23:AI23,ISNUMBER(E23:AI23))),0)} -> 0 | AL23: =IFERROR(AJ23*(1+AK23%),0) -> 0 | AN23: =IFERROR(SUM(E23:AC23)/D23,0) -> 0 | AY23: =IFERROR((AQ23*20)/60,0) -> 0 | AZ23: =IFERROR(AX23 + AY23 + BI23,0) -> 0 | BA23: =IFERROR(AZ23/8,0) -> 0 | BB23: =IFERROR(MAX(AQ23-BA23,0),0) -> 0 | BD23: =IFERROR(10000*D23,0) -> 0 | BG23: =IFERROR(-IF(AH23=$K$3,0,IF(AH23=$M$3,15*680*D23,IF(AH23=$O$3,30*680*D23,IF(AH23=0,50*680*D23,0)))),0) -> 0
B24: ='Tong hop cac ma'!B24 -> 0 | C24: ='Tong hop cac ma'!C24 -> 0 | D24: =AQ24 -> 0
A25: 9 | B25: ='Tong hop cac ma'!B25 -> 0 | C25: ='Tong hop cac ma'!C25 -> 0 | D25: =AQ25 -> 0 | E25: =+'Tong hop cac ma'!S25 -> 0 | AF25: =IFERROR(SUM(F25:AC25)*0.2,0) -> 0 | AH25: A | AI25: =IFERROR(130*D25,0) -> 0 | AJ25: {=IFERROR(SUM(_xlfn._xlws.FILTER(E25:AI25,ISNUMBER(E25:AI25))),0)} -> 0 | AL25: =IFERROR(AJ25*(1+AK25%),0) -> 0 | AN25: =IFERROR(SUM(E25:AC25)/D25,0) -> 0 | AY25: =IFERROR((AQ25*20)/60,0) -> 0 | AZ25: =IFERROR(AX25 + AY25 + BI25,0) -> 0 | BA25: =IFERROR(AZ25/8,0) -> 0 | BB25: =IFERROR(MAX(AQ25-BA25,0),0) -> 0 | BD25: =IFERROR(10000*D25,0) -> 0 | BG25: =IFERROR(-IF(AH25=$K$3,0,IF(AH25=$M$3,15*680*D25,IF(AH25=$O$3,30*680*D25,IF(AH25=0,50*680*D25,0)))),0) -> 0
B26: ='Tong hop cac ma'!B26 -> 0 | C26: ='Tong hop cac ma'!C26 -> 0 | D26: =AQ26 -> 0
A27: 10 | B27: ='Tong hop cac ma'!B27 -> 0 | C27: ='Tong hop cac ma'!C27 -> 0 | D27: =AQ27 -> 0 | E27: =+'Tong hop cac ma'!S27 -> 0 | AF27: =IFERROR(SUM(F27:AC27)*0.2,0) -> 0 | AH27: A | AI27: =IFERROR(130*D27,0) -> 0 | AJ27: {=IFERROR(SUM(_xlfn._xlws.FILTER(E27:AI27,ISNUMBER(E27:AI27))),0)} -> 0 | AL27: =IFERROR(AJ27*(1+AK27%),0) -> 0 | AN27: =IFERROR(SUM(E27:AC27)/D27,0) -> 0 | AY27: =IFERROR((AQ27*20)/60,0) -> 0 | AZ27: =IFERROR(AX27 + AY27 + BI27,0) -> 0 | BA27: =IFERROR(AZ27/8,0) -> 0 | BB27: =IFERROR(MAX(AQ27-BA27,0),0) -> 0 | BD27: =IFERROR(10000*D27,0) -> 0 | BG27: =IFERROR(-IF(AH27=$K$3,0,IF(AH27=$M$3,15*680*D27,IF(AH27=$O$3,30*680*D27,IF(AH27=0,50*680*D27,0)))),0) -> 0
B28: ='Tong hop cac ma'!B28 -> 0 | C28: ='Tong hop cac ma'!C28 -> 0 | D28: =AQ28 -> 0
A29: 11 | B29: ='Tong hop cac ma'!B29 -> 0 | C29: ='Tong hop cac ma'!C29 -> 0 | D29: =AQ29 -> 0 | E29: =+'Tong hop cac ma'!S29 -> 0 | AF29: =IFERROR(SUM(F29:AC29)*0.2,0) -> 0 | AH29: A | AI29: =IFERROR(130*D29,0) -> 0 | AJ29: {=IFERROR(SUM(_xlfn._xlws.FILTER(E29:AI29,ISNUMBER(E29:AI29))),0)} -> 0 | AL29: =IFERROR(AJ29*(1+AK29%),0) -> 0 | AN29: =IFERROR(SUM(E29:AC29)/D29,0) -> 0 | AY29: =IFERROR((AQ29*20)/60,0) -> 0 | AZ29: =IFERROR(AX29 + AY29 + BI29,0) -> 0 | BA29: =IFERROR(AZ29/8,0) -> 0 | BB29: =IFERROR(MAX(AQ29-BA29,0),0) -> 0 | BD29: =IFERROR(10000*D29,0) -> 0 | BG29: =IFERROR(-IF(AH29=$K$3,0,IF(AH29=$M$3,15*680*D29,IF(AH29=$O$3,30*680*D29,IF(AH29=0,50*680*D29,0)))),0) -> 0
B30: ='Tong hop cac ma'!B30 -> 0 | C30: ='Tong hop cac ma'!C30 -> 0 | D30: =AQ30 -> 0
A31: 12 | B31: ='Tong hop cac ma'!B31 -> 0 | C31: ='Tong hop cac ma'!C31 -> 0 | D31: =AQ31 -> 0 | E31: =+'Tong hop cac ma'!S31 -> 0 | AF31: =IFERROR(SUM(F31:AC31)*0.2,0) -> 0 | AH31: A | AI31: =IFERROR(130*D31,0) -> 0 | AJ31: {=IFERROR(SUM(_xlfn._xlws.FILTER(E31:AI31,ISNUMBER(E31:AI31))),0)} -> 0 | AL31: =IFERROR(AJ31*(1+AK31%),0) -> 0 | AN31: =IFERROR(SUM(E31:AC31)/D31,0) -> 0 | AY31: =IFERROR((AQ31*20)/60,0) -> 0 | AZ31: =IFERROR(AX31 + AY31 + BI31,0) -> 0 | BA31: =IFERROR(AZ31/8,0) -> 0 | BB31: =IFERROR(MAX(AQ31-BA31,0),0) -> 0 | BD31: =IFERROR(10000*D31,0) -> 0 | BG31: =IFERROR(-IF(AH31=$K$3,0,IF(AH31=$M$3,15*680*D31,IF(AH31=$O$3,30*680*D31,IF(AH31=0,50*680*D31,0)))),0) -> 0
B32: ='Tong hop cac ma'!B32 -> 0 | C32: ='Tong hop cac ma'!C32 -> 0 | D32: =AQ32 -> 0
A33: 13 | B33: ='Tong hop cac ma'!B33 -> 0 | C33: ='Tong hop cac ma'!C33 -> 0 | D33: =AQ33 -> 0 | E33: =+'Tong hop cac ma'!S33 -> 0 | AF33: =IFERROR(SUM(F33:AC33)*0.2,0) -> 0 | AH33: A | AI33: =IFERROR(130*D33,0) -> 0 | AJ33: {=IFERROR(SUM(_xlfn._xlws.FILTER(E33:AI33,ISNUMBER(E33:AI33))),0)} -> 0 | AL33: =IFERROR(AJ33*(1+AK33%),0) -> 0 | AN33: =IFERROR(SUM(E33:AC33)/D33,0) -> 0 | AY33: =IFERROR((AQ33*20)/60,0) -> 0 | AZ33: =IFERROR(AX33 + AY33 + BI33,0) -> 0 | BA33: =IFERROR(AZ33/8,0) -> 0 | BB33: =IFERROR(MAX(AQ33-BA33,0),0) -> 0 | BD33: =IFERROR(10000*D33,0) -> 0 | BG33: =IFERROR(-IF(AH33=$K$3,0,IF(AH33=$M$3,15*680*D33,IF(AH33=$O$3,30*680*D33,IF(AH33=0,50*680*D33,0)))),0) -> 0
B34: ='Tong hop cac ma'!B34 -> 0 | C34: ='Tong hop cac ma'!C34 -> 0 | D34: =AQ34 -> 0
A35: 14 | B35: ='Tong hop cac ma'!B35 -> 0 | C35: ='Tong hop cac ma'!C35 -> 0 | D35: =AQ35 -> 0 | E35: =+'Tong hop cac ma'!S35 -> 0 | AF35: =IFERROR(SUM(F35:AC35)*0.2,0) -> 0 | AH35: A | AI35: =IFERROR(130*D35,0) -> 0 | AJ35: {=IFERROR(SUM(_xlfn._xlws.FILTER(E35:AI35,ISNUMBER(E35:AI35))),0)} -> 0 | AL35: =IFERROR(AJ35*(1+AK35%),0) -> 0 | AN35: =IFERROR(SUM(E35:AC35)/D35,0) -> 0 | AY35: =IFERROR((AQ35*20)/60,0) -> 0 | AZ35: =IFERROR(AX35 + AY35 + BI35,0) -> 0 | BA35: =IFERROR(AZ35/8,0) -> 0 | BB35: =IFERROR(MAX(AQ35-BA35,0),0) -> 0 | BD35: =IFERROR(10000*D35,0) -> 0 | BG35: =IFERROR(-IF(AH35=$K$3,0,IF(AH35=$M$3,15*680*D35,IF(AH35=$O$3,30*680*D35,IF(AH35=0,50*680*D35,0)))),0) -> 0
B36: ='Tong hop cac ma'!B36 -> 0 | C36: ='Tong hop cac ma'!C36 -> 0 | D36: =AQ36 -> 0
A37: 15 | B37: ='Tong hop cac ma'!B37 -> 0 | C37: ='Tong hop cac ma'!C37 -> 0 | D37: =AQ37 -> 0 | E37: =+'Tong hop cac ma'!S37 -> 0 | AF37: =IFERROR(SUM(F37:AC37)*0.2,0) -> 0 | AH37: A | AI37: =IFERROR(130*D37,0) -> 0 | AJ37: {=IFERROR(SUM(_xlfn._xlws.FILTER(E37:AI37,ISNUMBER(E37:AI37))),0)} -> 0 | AL37: =IFERROR(AJ37*(1+AK37%),0) -> 0 | AN37: =IFERROR(SUM(E37:AC37)/D37,0) -> 0 | AY37: =IFERROR((AQ37*20)/60,0) -> 0 | AZ37: =IFERROR(AX37 + AY37 + BI37,0) -> 0 | BA37: =IFERROR(AZ37/8,0) -> 0 | BB37: =IFERROR(MAX(AQ37-BA37,0),0) -> 0 | BD37: =IFERROR(10000*D37,0) -> 0 | BG37: =IFERROR(-IF(AH37=$K$3,0,IF(AH37=$M$3,15*680*D37,IF(AH37=$O$3,30*680*D37,IF(AH37=0,50*680*D37,0)))),0) -> 0
B38: ='Tong hop cac ma'!B38 -> 0 | C38: ='Tong hop cac ma'!C38 -> 0 | D38: =AQ38 -> 0
A39: 16 | B39: ='Tong hop cac ma'!B39 -> 0 | C39: ='Tong hop cac ma'!C39 -> 0 | D39: =AQ39 -> 0 | E39: =+'Tong hop cac ma'!S39 -> 0 | AF39: =IFERROR(SUM(F39:AC39)*0.2,0) -> 0 | AH39: A | AI39: =IFERROR(130*D39,0) -> 0 | AJ39: {=IFERROR(SUM(_xlfn._xlws.FILTER(E39:AI39,ISNUMBER(E39:AI39))),0)} -> 0 | AL39: =IFERROR(AJ39*(1+AK39%),0) -> 0 | AN39: =IFERROR(SUM(E39:AC39)/D39,0) -> 0 | AY39: =IFERROR((AQ39*20)/60,0) -> 0 | AZ39: =IFERROR(AX39 + AY39 + BI39,0) -> 0 | BA39: =IFERROR(AZ39/8,0) -> 0 | BB39: =IFERROR(MAX(AQ39-BA39,0),0) -> 0 | BD39: =IFERROR(10000*D39,0) -> 0 | BG39: =IFERROR(-IF(AH39=$K$3,0,IF(AH39=$M$3,15*680*D39,IF(AH39=$O$3,30*680*D39,IF(AH39=0,50*680*D39,0)))),0) -> 0
B40: ='Tong hop cac ma'!B40 -> 0 | C40: ='Tong hop cac ma'!C40 -> 0 | D40: =AQ40 -> 0
A41: 17 | B41: ='Tong hop cac ma'!B41 -> 0 | C41: ='Tong hop cac ma'!C41 -> 0 | D41: =AQ41 -> 0 | E41: =+'Tong hop cac ma'!S41 -> 0 | AF41: =IFERROR(SUM(F41:AC41)*0.2,0) -> 0 | AH41: A | AI41: =IFERROR(130*D41,0) -> 0 | AJ41: {=IFERROR(SUM(_xlfn._xlws.FILTER(E41:AI41,ISNUMBER(E41:AI41))),0)} -> 0 | AL41: =IFERROR(AJ41*(1+AK41%),0) -> 0 | AN41: =IFERROR(SUM(E41:AC41)/D41,0) -> 0 | AY41: =IFERROR((AQ41*20)/60,0) -> 0 | AZ41: =IFERROR(AX41 + AY41 + BI41,0) -> 0 | BA41: =IFERROR(AZ41/8,0) -> 0 | BB41: =IFERROR(MAX(AQ41-BA41,0),0) -> 0 | BD41: =IFERROR(10000*D41,0) -> 0 | BG41: =IFERROR(-IF(AH41=$K$3,0,IF(AH41=$M$3,15*680*D41,IF(AH41=$O$3,30*680*D41,IF(AH41=0,50*680*D41,0)))),0) -> 0
B42: ='Tong hop cac ma'!B42 -> 0 | C42: ='Tong hop cac ma'!C42 -> 0 | D42: =AQ42 -> 0
A43: 18 | B43: ='Tong hop cac ma'!B43 -> 0 | C43: ='Tong hop cac ma'!C43 -> 0 | D43: =AQ43 -> 0 | E43: =+'Tong hop cac ma'!S43 -> 0 | AF43: =IFERROR(SUM(F43:AC43)*0.2,0) -> 0 | AH43: A | AI43: =IFERROR(130*D43,0) -> 0 | AJ43: {=IFERROR(SUM(_xlfn._xlws.FILTER(E43:AI43,ISNUMBER(E43:AI43))),0)} -> 0 | AL43: =IFERROR(AJ43*(1+AK43%),0) -> 0 | AN43: =IFERROR(SUM(E43:AC43)/D43,0) -> 0 | AY43: =IFERROR((AQ43*20)/60,0) -> 0 | AZ43: =IFERROR(AX43 + AY43 + BI43,0) -> 0 | BA43: =IFERROR(AZ43/8,0) -> 0 | BB43: =IFERROR(MAX(AQ43-BA43,0),0) -> 0 | BD43: =IFERROR(10000*D43,0) -> 0 | BG43: =IFERROR(-IF(AH43=$K$3,0,IF(AH43=$M$3,15*680*D43,IF(AH43=$O$3,30*680*D43,IF(AH43=0,50*680*D43,0)))),0) -> 0
...

Sheet LƯƠNG Tx
A1: CN CÔNG TY TNHH S&D TẠI THANH HOÁ
A2: Tổ may: | O2: BẢNG CHI TIẾT THANH TOÁN LƯƠNG
O3: Tháng 03 năm 2026
F4: PC: | I4: 1
A5: Stt | B5: Họ và tên | C5: Mã Số | D5: Ngày tiếp nhận/ Mức lương CB | F5: Tổng giây | I5: Tiền lương | Q5: Các khoản hỗ trợ | Z5: Bù lương | AA5: Trừ PLLĐ | AB5: Tổng cộng | AC5: Khấu trừ | AE5: Thực lĩnh | AF5: Ký nhận | AG5: Công T02 | AH5: Lương T02 | AI5: BQT02 | AJ5: BQT03 | AK5: So sánh | AL5: Tổng lương thực tế
I6: Sản phẩm HC | J6: Thêm giờ | K6: Phép | L6: Lễ, tết | M6: Học, họp | N6: Mang thai + Con nhỏ | O6: Vắt sữa | P6: Nghỉ ngắn+Phụ nữ | Q6: Chuyên cần | R6: Xăng xe | S6: Đi lại | T6: Nuôi con nhỏ+ATV | U6: Thưởng HTCV | V6: Thưởng theo KQKD | W6: Ăn ca | X6: bï l­¬ng SP | Y6: bï l­¬ng Thªm giê | AC6: BHXH, BHYT, BHTN | AD6: CĐ
A7: 1 | B7: 2 | C7: 3 | D7: 4 | F7: 5 | I7: 6 | J7: 7 | K7: 8 | L7: 9 | M7: 10 | N7: 11 | O7: 12 | P7: 13 | Q7: 14 | R7: 15 | S7: 16 | T7: 17 | U7: 18 | V7: 19 | W7: 20 | X7: 21 | Y7: 22 | Z7: 23 | AA7: 24 | AB7: 25 | AC7: 26 | AD7: 27 | AE7: 28 | AF7: 29 | AG7: 30 | AH7: 31 | AI7: 32=31/30 | AJ7: 33=35/29 | AK7: 34=33/32 | AL7: 35=25-9
A8: 1 | B8: ='Bang TH nop'!B9 -> 0 | C8: =IFERROR(IF(LEN(TRIM(B8))>0,'Bang TH nop'!C9,""),"") -> 0 | D8: =IFERROR(IF(AND(LEN(TRIM(B8))>0,LEN(TRIM(C8))>0),'Bang TH nop'!AO9,""),"") -> 0 | I8: =IFERROR(IF(AND(LEN(TRIM(B8))>0,LEN(TRIM(C8))>0),'Bang TH nop'!BB9,0),0) -> 0 | J8: =IFERROR(IF(AND(LEN(TRIM(B8))>0,LEN(TRIM(C8))>0),'Bang TH nop'!AV9,0),0) -> 0 | K8: =IFERROR(IF(AND(LEN(TRIM(B8))>0,LEN(TRIM(C8))>0),'Bang TH nop'!AR9,0),0) -> 0 | L8: =IFERROR(IF(AND(LEN(TRIM(B8))>0,LEN(TRIM(C8))>0),'Bang TH nop'!AS9,0),0) -> 0 | M8: =IFERROR(IF(AND(LEN(TRIM(B8))>0,LEN(TRIM(C8))>0),'Bang TH nop'!AT9,0),0) -> 0 | N8: =IFERROR(IF(AND(LEN(TRIM(B8))>0,LEN(TRIM(C8))>0),'Bang TH nop'!AU9,0),0) -> 0 | O8: =IFERROR(IF(AND(LEN(TRIM(B8))>0,LEN(TRIM(C8))>0),'Bang TH nop'!BE9,0),0) -> 0 | P8: =IFERROR(IF(AND(LEN(TRIM(B8))>0,LEN(TRIM(C8))>0),'Bang TH nop'!AZ9,0),0) -> 0 | AA8: =IFERROR( IF(AND(LEN(TRIM(B8))>0,LEN(TRIM(C8))>0), 'Bang TH nop'!AH9, 0 ), 0 ) -> A
D9: =IFERROR(IF(AND(LEN(TRIM(B8))>0,LEN(TRIM(C8))>0),'Bang TH nop'!AP9,""),"") -> 0 | F9: =IFERROR(IF(AND(LEN(TRIM(B8))>0,LEN(TRIM(C8))>0),'Bang TH nop'!AL9,0),0) -> 0 | G9: =D9*I8/26 -> 0 | H9: =D9*J8*150%/(26*8) -> 0 | K9: =IFERROR( IF(AND(LEN(TRIM(B8))>0,LEN(TRIM(C8))>0), ROUND(D9/26*K8,0), 0 ), 0 ) -> 0 | L9: =IFERROR( IF(AND(LEN(TRIM(B8))>0,LEN(TRIM(C8))>0), ROUND(D9/26*L8,0), 0 ), 0 ) -> 0 | M9: =IFERROR( IF(AND(LEN(TRIM(B8))>0,LEN(TRIM(C8))>0), ROUND(D9/26*M8,0), 0 ), 0 ) -> 0 | N9: =IFERROR( IF(AND(LEN(TRIM(B8))>0,LEN(TRIM(C8))>0), D9*N8/(26*8), 0 ), 0 ) -> 0 | O9: =IFERROR( IF(AND(LEN(TRIM(B8))>0,LEN(TRIM(C8))>0), D9*O8/(26*8), 0 ), 0 ) -> 0 | P9: =IFERROR( IF(AND(LEN(TRIM(B8))>0,LEN(TRIM(C8))>0), (D9/26/8*P8), 0 ), 0 ) -> 0 | Q9: =IFERROR( IF(AND(LEN(TRIM(B8))>0,LEN(TRIM(C8))>0), 'Bang TH nop'!BC9, 0 ), 0 ) -> 0 | R9: =IFERROR( IF(AND(LEN(TRIM(B8))>0,LEN(TRIM(C8))>0), 'Bang TH nop'!BD9, 0 ), 0 ) -> 0 | S9: =IFERROR( IF(AND(LEN(TRIM(B8))>0,LEN(TRIM(C8))>0), 'Bang TH nop'!BJ9, 0 ), 0 ) -> 0 | T9: =IFERROR( IF(AND(LEN(TRIM(B8))>0,LEN(TRIM(C8))>0), IFERROR('Bang TH nop'!AW9,0)+IFERROR('Bang TH nop'!BH9,0), 0 ), 0 ) -> 0 | X9: =+IF(G9-I9<0,0,G9-I9) -> 0 | Y9: =+IF(H9-J9<0,0, H9-J9) -> 0 | Z9: =IFERROR( IF(AND(LEN(TRIM(B8))>0,LEN(TRIM(C8))>0), (X9+Y9)*25%, 0 ), 0 ) -> 0 | AA9: =IFERROR( IF(AND(LEN(TRIM(B8))>0,LEN(TRIM(C8))>0), 'Bang TH nop'!BG9, 0 ), 0 ) -> 0 | AB9: =IFERROR( IF(AND(LEN(TRIM(B8))>0,LEN(TRIM(C8))>0), SUM(I9:W9)+IFERROR(Z9,0)+IFERROR(AA9,0), 0 ), 0 ) -> 0 | AC9: =IFERROR( IF(AND(LEN(TRIM(B8))>0,LEN(TRIM(C8))>0), IF((26-(IFERROR(I8,0)+IFERROR(K8,0)+IFERROR(L8,0)+IFERROR(M8,0)))>12,0,D9*10.5%), 0 ), 0 ) -> 0 | AD9: =IFERROR( IF(AND(LEN(TRIM(B8))>0,LEN(TRIM(C8))>0), ROUND(IF(D9=4939000,D9*0.5%,0),-2), 0 ), 0 ) -> 0 | AE9: =IFERROR( IF(AND(LEN(TRIM(B8))>0,LEN(TRIM(C8))>0), ROUND(IFERROR(AB9,0)-IFERROR(AC9,0)-IFERROR(AD9,0),-2), 0 ), 0 ) -> 0 | AF9: =IFERROR( IF(AND(LEN(TRIM(B8))>0,LEN(TRIM(C8))>0), IFERROR('Bang TH nop'!AQ9,0)+IFERROR('Bang TH nop'!AT9,0)+IFERROR('Bang TH nop'!BF9,0), 0 ), 0 ) -> 0 | AI9: =IFERROR( IF(AND(LEN(TRIM(B8))>0,LEN(TRIM(C8))>0), AH9/AG9, 0 ), 0 ) -> 0 | AJ9: =IFERROR( IF(AND(LEN(TRIM(B8))>0,LEN(TRIM(C8))>0), AL9/AF9, 0 ), 0 ) -> 0 | AK9: =IFERROR( IF(AND(LEN(TRIM(B8))>0,LEN(TRIM(C8))>0), AJ9/AI9, 0 ), 0 ) -> 0 | AL9: =IFERROR( IF(AND(LEN(TRIM(B8))>0,LEN(TRIM(C8))>0), AB9/L9, 0 ), 0 ) -> 0
A10: =A8+1 -> 2 | B10: ='Bang TH nop'!B11 -> 0 | C10: =IFERROR(IF(LEN(TRIM(B10))>0,'Bang TH nop'!C11,""),"") -> 0 | D10: =IFERROR(IF(AND(LEN(TRIM(B10))>0,LEN(TRIM(C10))>0),'Bang TH nop'!AO11,""),"") -> 0 | I10: =IFERROR(IF(AND(LEN(TRIM(B10))>0,LEN(TRIM(C10))>0),'Bang TH nop'!BB11,0),0) -> 0 | J10: =IFERROR(IF(AND(LEN(TRIM(B10))>0,LEN(TRIM(C10))>0),'Bang TH nop'!AV11,0),0) -> 0 | K10: =IFERROR(IF(AND(LEN(TRIM(B10))>0,LEN(TRIM(C10))>0),'Bang TH nop'!AR11,0),0) -> 0 | L10: =IFERROR(IF(AND(LEN(TRIM(B10))>0,LEN(TRIM(C10))>0),'Bang TH nop'!AS11,0),0) -> 0 | M10: =IFERROR(IF(AND(LEN(TRIM(B10))>0,LEN(TRIM(C10))>0),'Bang TH nop'!AT11,0),0) -> 0 | N10: =IFERROR(IF(AND(LEN(TRIM(B10))>0,LEN(TRIM(C10))>0),'Bang TH nop'!AU11,0),0) -> 0 | O10: =IFERROR(IF(AND(LEN(TRIM(B10))>0,LEN(TRIM(C10))>0),'Bang TH nop'!BE11,0),0) -> 0 | P10: =IFERROR(IF(AND(LEN(TRIM(B10))>0,LEN(TRIM(C10))>0),'Bang TH nop'!AZ11,0),0) -> 0 | AA10: =IFERROR( IF(AND(LEN(TRIM(B10))>0,LEN(TRIM(C10))>0), 'Bang TH nop'!AH11, 0 ), 0 ) -> A
D11: =IFERROR(IF(AND(LEN(TRIM(B10))>0,LEN(TRIM(C10))>0),'Bang TH nop'!AP11,""),"") -> 0 | F11: =IFERROR(IF(AND(LEN(TRIM(B10))>0,LEN(TRIM(C10))>0),'Bang TH nop'!AL11,0),0) -> 0 | G11: =D11*I10/26 -> 0 | H11: =D11*J10*150%/(26*8) -> 0 | K11: =IFERROR( IF(AND(LEN(TRIM(B10))>0,LEN(TRIM(C10))>0), ROUND(D11/26*K10,0), 0 ), 0 ) -> 0 | L11: =IFERROR( IF(AND(LEN(TRIM(B10))>0,LEN(TRIM(C10))>0), ROUND(D11/26*L10,0), 0 ), 0 ) -> 0 | M11: =IFERROR( IF(AND(LEN(TRIM(B10))>0,LEN(TRIM(C10))>0), ROUND(D11/26*M10,0), 0 ), 0 ) -> 0 | N11: =IFERROR( IF(AND(LEN(TRIM(B10))>0,LEN(TRIM(C10))>0), D11*N10/(26*8), 0 ), 0 ) -> 0 | O11: =IFERROR( IF(AND(LEN(TRIM(B10))>0,LEN(TRIM(C10))>0), D11*O10/(26*8), 0 ), 0 ) -> 0 | P11: =IFERROR( IF(AND(LEN(TRIM(B10))>0,LEN(TRIM(C10))>0), (D11/26/8*P10), 0 ), 0 ) -> 0 | Q11: =IFERROR( IF(AND(LEN(TRIM(B10))>0,LEN(TRIM(C10))>0), 'Bang TH nop'!BC11, 0 ), 0 ) -> 0 | R11: =IFERROR( IF(AND(LEN(TRIM(B10))>0,LEN(TRIM(C10))>0), 'Bang TH nop'!BD11, 0 ), 0 ) -> 0 | S11: =IFERROR( IF(AND(LEN(TRIM(B10))>0,LEN(TRIM(C10))>0), 'Bang TH nop'!BJ11, 0 ), 0 ) -> 0 | T11: =IFERROR( IF(AND(LEN(TRIM(B10))>0,LEN(TRIM(C10))>0), IFERROR('Bang TH nop'!AW11,0)+IFERROR('Bang TH nop'!BH11,0), 0 ), 0 ) -> 0 | X11: =+IF(G11-I11<0,0,G11-I11) -> 0 | Y11: =+IF(H11-J11<0,0, H11-J11) -> 0 | Z11: =IFERROR( IF(AND(LEN(TRIM(B10))>0,LEN(TRIM(C10))>0), (X11+Y11)*25%, 0 ), 0 ) -> 0 | AA11: =IFERROR( IF(AND(LEN(TRIM(B10))>0,LEN(TRIM(C10))>0), 'Bang TH nop'!BG11, 0 ), 0 ) -> 0 | AB11: =IFERROR( IF(AND(LEN(TRIM(B10))>0,LEN(TRIM(C10))>0), SUM(I11:W11)+IFERROR(Z11,0)+IFERROR(AA11,0), 0 ), 0 ) -> 0 | AC11: =IFERROR( IF(AND(LEN(TRIM(B10))>0,LEN(TRIM(C10))>0), IF((26-(IFERROR(I10,0)+IFERROR(K10,0)+IFERROR(L10,0)+IFERROR(M10,0)))>12,0,D11*10.5%), 0 ), 0 ) -> 0 | AD11: =IFERROR( IF(AND(LEN(TRIM(B10))>0,LEN(TRIM(C10))>0), ROUND(IF(D11=4939000,D11*0.5%,0),-2), 0 ), 0 ) -> 0 | AE11: =IFERROR( IF(AND(LEN(TRIM(B10))>0,LEN(TRIM(C10))>0), ROUND(IFERROR(AB11,0)-IFERROR(AC11,0)-IFERROR(AD11,0),-2), 0 ), 0 ) -> 0 | AF11: =IFERROR( IF(AND(LEN(TRIM(B10))>0,LEN(TRIM(C10))>0), IFERROR('Bang TH nop'!AQ11,0)+IFERROR('Bang TH nop'!AT11,0)+IFERROR('Bang TH nop'!BF11,0), 0 ), 0 ) -> 0 | AI11: =IFERROR( IF(AND(LEN(TRIM(B10))>0,LEN(TRIM(C10))>0), AH11/AG11, 0 ), 0 ) -> 0 | AJ11: =IFERROR( IF(AND(LEN(TRIM(B10))>0,LEN(TRIM(C10))>0), AL11/AF11, 0 ), 0 ) -> 0 | AK11: =IFERROR( IF(AND(LEN(TRIM(B10))>0,LEN(TRIM(C10))>0), AJ11/AI11, 0 ), 0 ) -> 0 | AL11: =IFERROR( IF(AND(LEN(TRIM(B10))>0,LEN(TRIM(C10))>0), AB11/L11, 0 ), 0 ) -> 0
A12: =A10+1 -> 3 | B12: ='Bang TH nop'!B13 -> 0 | C12: =IFERROR(IF(LEN(TRIM(B12))>0,'Bang TH nop'!C13,""),"") -> 0 | D12: =IFERROR(IF(AND(LEN(TRIM(B12))>0,LEN(TRIM(C12))>0),'Bang TH nop'!AO13,""),"") -> 0 | I12: =IFERROR(IF(AND(LEN(TRIM(B12))>0,LEN(TRIM(C12))>0),'Bang TH nop'!BB13,0),0) -> 0 | J12: =IFERROR(IF(AND(LEN(TRIM(B12))>0,LEN(TRIM(C12))>0),'Bang TH nop'!AV13,0),0) -> 0 | K12: =IFERROR(IF(AND(LEN(TRIM(B12))>0,LEN(TRIM(C12))>0),'Bang TH nop'!AR13,0),0) -> 0 | L12: =IFERROR(IF(AND(LEN(TRIM(B12))>0,LEN(TRIM(C12))>0),'Bang TH nop'!AS13,0),0) -> 0 | M12: =IFERROR(IF(AND(LEN(TRIM(B12))>0,LEN(TRIM(C12))>0),'Bang TH nop'!AT13,0),0) -> 0 | N12: =IFERROR(IF(AND(LEN(TRIM(B12))>0,LEN(TRIM(C12))>0),'Bang TH nop'!AU13,0),0) -> 0 | O12: =IFERROR(IF(AND(LEN(TRIM(B12))>0,LEN(TRIM(C12))>0),'Bang TH nop'!BE13,0),0) -> 0 | P12: =IFERROR(IF(AND(LEN(TRIM(B12))>0,LEN(TRIM(C12))>0),'Bang TH nop'!AZ13,0),0) -> 0 | AA12: =IFERROR( IF(AND(LEN(TRIM(B12))>0,LEN(TRIM(C12))>0), 'Bang TH nop'!AH13, 0 ), 0 ) -> A
D13: =IFERROR(IF(AND(LEN(TRIM(B12))>0,LEN(TRIM(C12))>0),'Bang TH nop'!AP13,""),"") -> 0 | F13: =IFERROR(IF(AND(LEN(TRIM(B12))>0,LEN(TRIM(C12))>0),'Bang TH nop'!AL13,0),0) -> 0 | G13: =D13*I12/26 -> 0 | H13: =D13*J12*150%/(26*8) -> 0 | K13: =IFERROR( IF(AND(LEN(TRIM(B12))>0,LEN(TRIM(C12))>0), ROUND(D13/26*K12,0), 0 ), 0 ) -> 0 | L13: =IFERROR( IF(AND(LEN(TRIM(B12))>0,LEN(TRIM(C12))>0), ROUND(D13/26*L12,0), 0 ), 0 ) -> 0 | M13: =IFERROR( IF(AND(LEN(TRIM(B12))>0,LEN(TRIM(C12))>0), ROUND(D13/26*M12,0), 0 ), 0 ) -> 0 | N13: =IFERROR( IF(AND(LEN(TRIM(B12))>0,LEN(TRIM(C12))>0), D13*N12/(26*8), 0 ), 0 ) -> 0 | O13: =IFERROR( IF(AND(LEN(TRIM(B12))>0,LEN(TRIM(C12))>0), D13*O12/(26*8), 0 ), 0 ) -> 0 | P13: =IFERROR( IF(AND(LEN(TRIM(B12))>0,LEN(TRIM(C12))>0), (D13/26/8*P12), 0 ), 0 ) -> 0 | Q13: =IFERROR( IF(AND(LEN(TRIM(B12))>0,LEN(TRIM(C12))>0), 'Bang TH nop'!BC13, 0 ), 0 ) -> 0 | R13: =IFERROR( IF(AND(LEN(TRIM(B12))>0,LEN(TRIM(C12))>0), 'Bang TH nop'!BD13, 0 ), 0 ) -> 0 | S13: =IFERROR( IF(AND(LEN(TRIM(B12))>0,LEN(TRIM(C12))>0), 'Bang TH nop'!BJ13, 0 ), 0 ) -> 0 | T13: =IFERROR( IF(AND(LEN(TRIM(B12))>0,LEN(TRIM(C12))>0), IFERROR('Bang TH nop'!AW13,0)+IFERROR('Bang TH nop'!BH13,0), 0 ), 0 ) -> 0 | X13: =+IF(G13-I13<0,0,G13-I13) -> 0 | Y13: =+IF(H13-J13<0,0, H13-J13) -> 0 | Z13: =IFERROR( IF(AND(LEN(TRIM(B12))>0,LEN(TRIM(C12))>0), (X13+Y13)*25%, 0 ), 0 ) -> 0 | AA13: =IFERROR( IF(AND(LEN(TRIM(B12))>0,LEN(TRIM(C12))>0), 'Bang TH nop'!BG13, 0 ), 0 ) -> 0 | AB13: =IFERROR( IF(AND(LEN(TRIM(B12))>0,LEN(TRIM(C12))>0), SUM(I13:W13)+IFERROR(Z13,0)+IFERROR(AA13,0), 0 ), 0 ) -> 0 | AC13: =IFERROR( IF(AND(LEN(TRIM(B12))>0,LEN(TRIM(C12))>0), IF((26-(IFERROR(I12,0)+IFERROR(K12,0)+IFERROR(L12,0)+IFERROR(M12,0)))>12,0,D13*10.5%), 0 ), 0 ) -> 0 | AD13: =IFERROR( IF(AND(LEN(TRIM(B12))>0,LEN(TRIM(C12))>0), ROUND(IF(D13=4939000,D13*0.5%,0),-2), 0 ), 0 ) -> 0 | AE13: =IFERROR( IF(AND(LEN(TRIM(B12))>0,LEN(TRIM(C12))>0), ROUND(IFERROR(AB13,0)-IFERROR(AC13,0)-IFERROR(AD13,0),-2), 0 ), 0 ) -> 0 | AF13: =IFERROR( IF(AND(LEN(TRIM(B12))>0,LEN(TRIM(C12))>0), IFERROR('Bang TH nop'!AQ13,0)+IFERROR('Bang TH nop'!AT13,0)+IFERROR('Bang TH nop'!BF13,0), 0 ), 0 ) -> 0 | AI13: =IFERROR( IF(AND(LEN(TRIM(B12))>0,LEN(TRIM(C12))>0), AH13/AG13, 0 ), 0 ) -> 0 | AJ13: =IFERROR( IF(AND(LEN(TRIM(B12))>0,LEN(TRIM(C12))>0), AL13/AF13, 0 ), 0 ) -> 0 | AK13: =IFERROR( IF(AND(LEN(TRIM(B12))>0,LEN(TRIM(C12))>0), AJ13/AI13, 0 ), 0 ) -> 0 | AL13: =IFERROR( IF(AND(LEN(TRIM(B12))>0,LEN(TRIM(C12))>0), AB13/L13, 0 ), 0 ) -> 0
A14: =A12+1 -> 4 | B14: ='Bang TH nop'!B15 -> 0 | C14: =IFERROR(IF(LEN(TRIM(B14))>0,'Bang TH nop'!C15,""),"") -> 0 | D14: =IFERROR(IF(AND(LEN(TRIM(B14))>0,LEN(TRIM(C14))>0),'Bang TH nop'!AO15,""),"") -> 0 | I14: =IFERROR(IF(AND(LEN(TRIM(B14))>0,LEN(TRIM(C14))>0),'Bang TH nop'!BB15,0),0) -> 0 | J14: =IFERROR(IF(AND(LEN(TRIM(B14))>0,LEN(TRIM(C14))>0),'Bang TH nop'!AV15,0),0) -> 0 | K14: =IFERROR(IF(AND(LEN(TRIM(B14))>0,LEN(TRIM(C14))>0),'Bang TH nop'!AR15,0),0) -> 0 | L14: =IFERROR(IF(AND(LEN(TRIM(B14))>0,LEN(TRIM(C14))>0),'Bang TH nop'!AS15,0),0) -> 0 | M14: =IFERROR(IF(AND(LEN(TRIM(B14))>0,LEN(TRIM(C14))>0),'Bang TH nop'!AT15,0),0) -> 0 | N14: =IFERROR(IF(AND(LEN(TRIM(B14))>0,LEN(TRIM(C14))>0),'Bang TH nop'!AU15,0),0) -> 0 | O14: =IFERROR(IF(AND(LEN(TRIM(B14))>0,LEN(TRIM(C14))>0),'Bang TH nop'!BE15,0),0) -> 0 | P14: =IFERROR(IF(AND(LEN(TRIM(B14))>0,LEN(TRIM(C14))>0),'Bang TH nop'!AZ15,0),0) -> 0 | AA14: =IFERROR( IF(AND(LEN(TRIM(B14))>0,LEN(TRIM(C14))>0), 'Bang TH nop'!AH15, 0 ), 0 ) -> A
D15: =IFERROR(IF(AND(LEN(TRIM(B14))>0,LEN(TRIM(C14))>0),'Bang TH nop'!AP15,""),"") -> 0 | F15: =IFERROR(IF(AND(LEN(TRIM(B14))>0,LEN(TRIM(C14))>0),'Bang TH nop'!AL15,0),0) -> 0 | G15: =D15*I14/26 -> 0 | H15: =D15*J14*150%/(26*8) -> 0 | K15: =IFERROR( IF(AND(LEN(TRIM(B14))>0,LEN(TRIM(C14))>0), ROUND(D15/26*K14,0), 0 ), 0 ) -> 0 | L15: =IFERROR( IF(AND(LEN(TRIM(B14))>0,LEN(TRIM(C14))>0), ROUND(D15/26*L14,0), 0 ), 0 ) -> 0 | M15: =IFERROR( IF(AND(LEN(TRIM(B14))>0,LEN(TRIM(C14))>0), ROUND(D15/26*M14,0), 0 ), 0 ) -> 0 | N15: =IFERROR( IF(AND(LEN(TRIM(B14))>0,LEN(TRIM(C14))>0), D15*N14/(26*8), 0 ), 0 ) -> 0 | O15: =IFERROR( IF(AND(LEN(TRIM(B14))>0,LEN(TRIM(C14))>0), D15*O14/(26*8), 0 ), 0 ) -> 0 | P15: =IFERROR( IF(AND(LEN(TRIM(B14))>0,LEN(TRIM(C14))>0), (D15/26/8*P14), 0 ), 0 ) -> 0 | Q15: =IFERROR( IF(AND(LEN(TRIM(B14))>0,LEN(TRIM(C14))>0), 'Bang TH nop'!BC15, 0 ), 0 ) -> 0 | R15: =IFERROR( IF(AND(LEN(TRIM(B14))>0,LEN(TRIM(C14))>0), 'Bang TH nop'!BD15, 0 ), 0 ) -> 0 | S15: =IFERROR( IF(AND(LEN(TRIM(B14))>0,LEN(TRIM(C14))>0), 'Bang TH nop'!BJ15, 0 ), 0 ) -> 0 | T15: =IFERROR( IF(AND(LEN(TRIM(B14))>0,LEN(TRIM(C14))>0), IFERROR('Bang TH nop'!AW15,0)+IFERROR('Bang TH nop'!BH15,0), 0 ), 0 ) -> 0 | X15: =+IF(G15-I15<0,0,G15-I15) -> 0 | Y15: =+IF(H15-J15<0,0, H15-J15) -> 0 | Z15: =IFERROR( IF(AND(LEN(TRIM(B14))>0,LEN(TRIM(C14))>0), (X15+Y15)*25%, 0 ), 0 ) -> 0 | AA15: =IFERROR( IF(AND(LEN(TRIM(B14))>0,LEN(TRIM(C14))>0), 'Bang TH nop'!BG15, 0 ), 0 ) -> 0 | AB15: =IFERROR( IF(AND(LEN(TRIM(B14))>0,LEN(TRIM(C14))>0), SUM(I15:W15)+IFERROR(Z15,0)+IFERROR(AA15,0), 0 ), 0 ) -> 0 | AC15: =IFERROR( IF(AND(LEN(TRIM(B14))>0,LEN(TRIM(C14))>0), IF((26-(IFERROR(I14,0)+IFERROR(K14,0)+IFERROR(L14,0)+IFERROR(M14,0)))>12,0,D15*10.5%), 0 ), 0 ) -> 0 | AD15: =IFERROR( IF(AND(LEN(TRIM(B14))>0,LEN(TRIM(C14))>0), ROUND(IF(D15=4939000,D15*0.5%,0),-2), 0 ), 0 ) -> 0 | AE15: =IFERROR( IF(AND(LEN(TRIM(B14))>0,LEN(TRIM(C14))>0), ROUND(IFERROR(AB15,0)-IFERROR(AC15,0)-IFERROR(AD15,0),-2), 0 ), 0 ) -> 0 | AF15: =IFERROR( IF(AND(LEN(TRIM(B14))>0,LEN(TRIM(C14))>0), IFERROR('Bang TH nop'!AQ15,0)+IFERROR('Bang TH nop'!AT15,0)+IFERROR('Bang TH nop'!BF15,0), 0 ), 0 ) -> 0 | AI15: =IFERROR( IF(AND(LEN(TRIM(B14))>0,LEN(TRIM(C14))>0), AH15/AG15, 0 ), 0 ) -> 0 | AJ15: =IFERROR( IF(AND(LEN(TRIM(B14))>0,LEN(TRIM(C14))>0), AL15/AF15, 0 ), 0 ) -> 0 | AK15: =IFERROR( IF(AND(LEN(TRIM(B14))>0,LEN(TRIM(C14))>0), AJ15/AI15, 0 ), 0 ) -> 0 | AL15: =IFERROR( IF(AND(LEN(TRIM(B14))>0,LEN(TRIM(C14))>0), AB15/L15, 0 ), 0 ) -> 0
A16: =A14+1 -> 5 | B16: ='Bang TH nop'!B17 -> 0 | C16: =IFERROR(IF(LEN(TRIM(B16))>0,'Bang TH nop'!C17,""),"") -> 0 | D16: =IFERROR(IF(AND(LEN(TRIM(B16))>0,LEN(TRIM(C16))>0),'Bang TH nop'!AO17,""),"") -> 0 | I16: =IFERROR(IF(AND(LEN(TRIM(B16))>0,LEN(TRIM(C16))>0),'Bang TH nop'!BB17,0),0) -> 0 | J16: =IFERROR(IF(AND(LEN(TRIM(B16))>0,LEN(TRIM(C16))>0),'Bang TH nop'!AV17,0),0) -> 0 | K16: =IFERROR(IF(AND(LEN(TRIM(B16))>0,LEN(TRIM(C16))>0),'Bang TH nop'!AR17,0),0) -> 0 | L16: =IFERROR(IF(AND(LEN(TRIM(B16))>0,LEN(TRIM(C16))>0),'Bang TH nop'!AS17,0),0) -> 0 | M16: =IFERROR(IF(AND(LEN(TRIM(B16))>0,LEN(TRIM(C16))>0),'Bang TH nop'!AT17,0),0) -> 0 | N16: =IFERROR(IF(AND(LEN(TRIM(B16))>0,LEN(TRIM(C16))>0),'Bang TH nop'!AU17,0),0) -> 0 | O16: =IFERROR(IF(AND(LEN(TRIM(B16))>0,LEN(TRIM(C16))>0),'Bang TH nop'!BE17,0),0) -> 0 | P16: =IFERROR(IF(AND(LEN(TRIM(B16))>0,LEN(TRIM(C16))>0),'Bang TH nop'!AZ17,0),0) -> 0 | AA16: =IFERROR( IF(AND(LEN(TRIM(B16))>0,LEN(TRIM(C16))>0), 'Bang TH nop'!AH17, 0 ), 0 ) -> A
D17: =IFERROR(IF(AND(LEN(TRIM(B16))>0,LEN(TRIM(C16))>0),'Bang TH nop'!AP17,""),"") -> 0 | F17: =IFERROR(IF(AND(LEN(TRIM(B16))>0,LEN(TRIM(C16))>0),'Bang TH nop'!AL17,0),0) -> 0 | G17: =D17*I16/26 -> 0 | H17: =D17*J16*150%/(26*8) -> 0 | K17: =IFERROR( IF(AND(LEN(TRIM(B16))>0,LEN(TRIM(C16))>0), ROUND(D17/26*K16,0), 0 ), 0 ) -> 0 | L17: =IFERROR( IF(AND(LEN(TRIM(B16))>0,LEN(TRIM(C16))>0), ROUND(D17/26*L16,0), 0 ), 0 ) -> 0 | M17: =IFERROR( IF(AND(LEN(TRIM(B16))>0,LEN(TRIM(C16))>0), ROUND(D17/26*M16,0), 0 ), 0 ) -> 0 | N17: =IFERROR( IF(AND(LEN(TRIM(B16))>0,LEN(TRIM(C16))>0), D17*N16/(26*8), 0 ), 0 ) -> 0 | O17: =IFERROR( IF(AND(LEN(TRIM(B16))>0,LEN(TRIM(C16))>0), D17*O16/(26*8), 0 ), 0 ) -> 0 | P17: =IFERROR( IF(AND(LEN(TRIM(B16))>0,LEN(TRIM(C16))>0), (D17/26/8*P16), 0 ), 0 ) -> 0 | Q17: =IFERROR( IF(AND(LEN(TRIM(B16))>0,LEN(TRIM(C16))>0), 'Bang TH nop'!BC17, 0 ), 0 ) -> 0 | R17: =IFERROR( IF(AND(LEN(TRIM(B16))>0,LEN(TRIM(C16))>0), 'Bang TH nop'!BD17, 0 ), 0 ) -> 0 | S17: =IFERROR( IF(AND(LEN(TRIM(B16))>0,LEN(TRIM(C16))>0), 'Bang TH nop'!BJ17, 0 ), 0 ) -> 0 | T17: =IFERROR( IF(AND(LEN(TRIM(B16))>0,LEN(TRIM(C16))>0), IFERROR('Bang TH nop'!AW17,0)+IFERROR('Bang TH nop'!BH17,0), 0 ), 0 ) -> 0 | X17: =+IF(G17-I17<0,0,G17-I17) -> 0 | Y17: =+IF(H17-J17<0,0, H17-J17) -> 0 | Z17: =IFERROR( IF(AND(LEN(TRIM(B16))>0,LEN(TRIM(C16))>0), (X17+Y17)*25%, 0 ), 0 ) -> 0 | AA17: =IFERROR( IF(AND(LEN(TRIM(B16))>0,LEN(TRIM(C16))>0), 'Bang TH nop'!BG17, 0 ), 0 ) -> 0 | AB17: =IFERROR( IF(AND(LEN(TRIM(B16))>0,LEN(TRIM(C16))>0), SUM(I17:W17)+IFERROR(Z17,0)+IFERROR(AA17,0), 0 ), 0 ) -> 0 | AC17: =IFERROR( IF(AND(LEN(TRIM(B16))>0,LEN(TRIM(C16))>0), IF((26-(IFERROR(I16,0)+IFERROR(K16,0)+IFERROR(L16,0)+IFERROR(M16,0)))>12,0,D17*10.5%), 0 ), 0 ) -> 0 | AD17: =IFERROR( IF(AND(LEN(TRIM(B16))>0,LEN(TRIM(C16))>0), ROUND(IF(D17=4939000,D17*0.5%,0),-2), 0 ), 0 ) -> 0 | AE17: =IFERROR( IF(AND(LEN(TRIM(B16))>0,LEN(TRIM(C16))>0), ROUND(IFERROR(AB17,0)-IFERROR(AC17,0)-IFERROR(AD17,0),-2), 0 ), 0 ) -> 0 | AF17: =IFERROR( IF(AND(LEN(TRIM(B16))>0,LEN(TRIM(C16))>0), IFERROR('Bang TH nop'!AQ17,0)+IFERROR('Bang TH nop'!AT17,0)+IFERROR('Bang TH nop'!BF17,0), 0 ), 0 ) -> 0 | AI17: =IFERROR( IF(AND(LEN(TRIM(B16))>0,LEN(TRIM(C16))>0), AH17/AG17, 0 ), 0 ) -> 0 | AJ17: =IFERROR( IF(AND(LEN(TRIM(B16))>0,LEN(TRIM(C16))>0), AL17/AF17, 0 ), 0 ) -> 0 | AK17: =IFERROR( IF(AND(LEN(TRIM(B16))>0,LEN(TRIM(C16))>0), AJ17/AI17, 0 ), 0 ) -> 0 | AL17: =IFERROR( IF(AND(LEN(TRIM(B16))>0,LEN(TRIM(C16))>0), AB17/L17, 0 ), 0 ) -> 0
A18: =A16+1 -> 6 | B18: ='Bang TH nop'!B19 -> 0 | C18: =IFERROR(IF(LEN(TRIM(B18))>0,'Bang TH nop'!C19,""),"") -> 0 | D18: =IFERROR(IF(AND(LEN(TRIM(B18))>0,LEN(TRIM(C18))>0),'Bang TH nop'!AO19,""),"") -> 0 | I18: =IFERROR(IF(AND(LEN(TRIM(B18))>0,LEN(TRIM(C18))>0),'Bang TH nop'!BB19,0),0) -> 0 | J18: =IFERROR(IF(AND(LEN(TRIM(B18))>0,LEN(TRIM(C18))>0),'Bang TH nop'!AV19,0),0) -> 0 | K18: =IFERROR(IF(AND(LEN(TRIM(B18))>0,LEN(TRIM(C18))>0),'Bang TH nop'!AR19,0),0) -> 0 | L18: =IFERROR(IF(AND(LEN(TRIM(B18))>0,LEN(TRIM(C18))>0),'Bang TH nop'!AS19,0),0) -> 0 | M18: =IFERROR(IF(AND(LEN(TRIM(B18))>0,LEN(TRIM(C18))>0),'Bang TH nop'!AT19,0),0) -> 0 | N18: =IFERROR(IF(AND(LEN(TRIM(B18))>0,LEN(TRIM(C18))>0),'Bang TH nop'!AU19,0),0) -> 0 | O18: =IFERROR(IF(AND(LEN(TRIM(B18))>0,LEN(TRIM(C18))>0),'Bang TH nop'!BE19,0),0) -> 0 | P18: =IFERROR(IF(AND(LEN(TRIM(B18))>0,LEN(TRIM(C18))>0),'Bang TH nop'!AZ19,0),0) -> 0 | AA18: =IFERROR( IF(AND(LEN(TRIM(B18))>0,LEN(TRIM(C18))>0), 'Bang TH nop'!AH19, 0 ), 0 ) -> A
D19: =IFERROR(IF(AND(LEN(TRIM(B18))>0,LEN(TRIM(C18))>0),'Bang TH nop'!AP19,""),"") -> 0 | F19: =IFERROR(IF(AND(LEN(TRIM(B18))>0,LEN(TRIM(C18))>0),'Bang TH nop'!AL19,0),0) -> 0 | G19: =D19*I18/26 -> 0 | H19: =D19*J18*150%/(26*8) -> 0 | K19: =IFERROR( IF(AND(LEN(TRIM(B18))>0,LEN(TRIM(C18))>0), ROUND(D19/26*K18,0), 0 ), 0 ) -> 0 | L19: =IFERROR( IF(AND(LEN(TRIM(B18))>0,LEN(TRIM(C18))>0), ROUND(D19/26*L18,0), 0 ), 0 ) -> 0 | M19: =IFERROR( IF(AND(LEN(TRIM(B18))>0,LEN(TRIM(C18))>0), ROUND(D19/26*M18,0), 0 ), 0 ) -> 0 | N19: =IFERROR( IF(AND(LEN(TRIM(B18))>0,LEN(TRIM(C18))>0), D19*N18/(26*8), 0 ), 0 ) -> 0 | O19: =IFERROR( IF(AND(LEN(TRIM(B18))>0,LEN(TRIM(C18))>0), D19*O18/(26*8), 0 ), 0 ) -> 0 | P19: =IFERROR( IF(AND(LEN(TRIM(B18))>0,LEN(TRIM(C18))>0), (D19/26/8*P18), 0 ), 0 ) -> 0 | Q19: =IFERROR( IF(AND(LEN(TRIM(B18))>0,LEN(TRIM(C18))>0), 'Bang TH nop'!BC19, 0 ), 0 ) -> 0 | R19: =IFERROR( IF(AND(LEN(TRIM(B18))>0,LEN(TRIM(C18))>0), 'Bang TH nop'!BD19, 0 ), 0 ) -> 0 | S19: =IFERROR( IF(AND(LEN(TRIM(B18))>0,LEN(TRIM(C18))>0), 'Bang TH nop'!BJ19, 0 ), 0 ) -> 0 | T19: =IFERROR( IF(AND(LEN(TRIM(B18))>0,LEN(TRIM(C18))>0), IFERROR('Bang TH nop'!AW19,0)+IFERROR('Bang TH nop'!BH19,0), 0 ), 0 ) -> 0 | X19: =+IF(G19-I19<0,0,G19-I19) -> 0 | Y19: =+IF(H19-J19<0,0, H19-J19) -> 0 | Z19: =IFERROR( IF(AND(LEN(TRIM(B18))>0,LEN(TRIM(C18))>0), (X19+Y19)*25%, 0 ), 0 ) -> 0 | AA19: =IFERROR( IF(AND(LEN(TRIM(B18))>0,LEN(TRIM(C18))>0), 'Bang TH nop'!BG19, 0 ), 0 ) -> 0 | AB19: =IFERROR( IF(AND(LEN(TRIM(B18))>0,LEN(TRIM(C18))>0), SUM(I19:W19)+IFERROR(Z19,0)+IFERROR(AA19,0), 0 ), 0 ) -> 0 | AC19: =IFERROR( IF(AND(LEN(TRIM(B18))>0,LEN(TRIM(C18))>0), IF((26-(IFERROR(I18,0)+IFERROR(K18,0)+IFERROR(L18,0)+IFERROR(M18,0)))>12,0,D19*10.5%), 0 ), 0 ) -> 0 | AD19: =IFERROR( IF(AND(LEN(TRIM(B18))>0,LEN(TRIM(C18))>0), ROUND(IF(D19=4939000,D19*0.5%,0),-2), 0 ), 0 ) -> 0 | AE19: =IFERROR( IF(AND(LEN(TRIM(B18))>0,LEN(TRIM(C18))>0), ROUND(IFERROR(AB19,0)-IFERROR(AC19,0)-IFERROR(AD19,0),-2), 0 ), 0 ) -> 0 | AF19: =IFERROR( IF(AND(LEN(TRIM(B18))>0,LEN(TRIM(C18))>0), IFERROR('Bang TH nop'!AQ19,0)+IFERROR('Bang TH nop'!AT19,0)+IFERROR('Bang TH nop'!BF19,0), 0 ), 0 ) -> 0 | AI19: =IFERROR( IF(AND(LEN(TRIM(B18))>0,LEN(TRIM(C18))>0), AH19/AG19, 0 ), 0 ) -> 0 | AJ19: =IFERROR( IF(AND(LEN(TRIM(B18))>0,LEN(TRIM(C18))>0), AL19/AF19, 0 ), 0 ) -> 0 | AK19: =IFERROR( IF(AND(LEN(TRIM(B18))>0,LEN(TRIM(C18))>0), AJ19/AI19, 0 ), 0 ) -> 0 | AL19: =IFERROR( IF(AND(LEN(TRIM(B18))>0,LEN(TRIM(C18))>0), AB19/L19, 0 ), 0 ) -> 0
A20: =A18+1 -> 7 | B20: ='Bang TH nop'!B21 -> 0 | C20: =IFERROR(IF(LEN(TRIM(B20))>0,'Bang TH nop'!C21,""),"") -> 0 | D20: =IFERROR(IF(AND(LEN(TRIM(B20))>0,LEN(TRIM(C20))>0),'Bang TH nop'!AO21,""),"") -> 0 | I20: =IFERROR(IF(AND(LEN(TRIM(B20))>0,LEN(TRIM(C20))>0),'Bang TH nop'!BB21,0),0) -> 0 | J20: =IFERROR(IF(AND(LEN(TRIM(B20))>0,LEN(TRIM(C20))>0),'Bang TH nop'!AV21,0),0) -> 0 | K20: =IFERROR(IF(AND(LEN(TRIM(B20))>0,LEN(TRIM(C20))>0),'Bang TH nop'!AR21,0),0) -> 0 | L20: =IFERROR(IF(AND(LEN(TRIM(B20))>0,LEN(TRIM(C20))>0),'Bang TH nop'!AS21,0),0) -> 0 | M20: =IFERROR(IF(AND(LEN(TRIM(B20))>0,LEN(TRIM(C20))>0),'Bang TH nop'!AT21,0),0) -> 0 | N20: =IFERROR(IF(AND(LEN(TRIM(B20))>0,LEN(TRIM(C20))>0),'Bang TH nop'!AU21,0),0) -> 0 | O20: =IFERROR(IF(AND(LEN(TRIM(B20))>0,LEN(TRIM(C20))>0),'Bang TH nop'!BE21,0),0) -> 0 | P20: =IFERROR(IF(AND(LEN(TRIM(B20))>0,LEN(TRIM(C20))>0),'Bang TH nop'!AZ21,0),0) -> 0 | AA20: =IFERROR( IF(AND(LEN(TRIM(B20))>0,LEN(TRIM(C20))>0), 'Bang TH nop'!AH21, 0 ), 0 ) -> A
D21: =IFERROR(IF(AND(LEN(TRIM(B20))>0,LEN(TRIM(C20))>0),'Bang TH nop'!AP21,""),"") -> 0 | F21: =IFERROR(IF(AND(LEN(TRIM(B20))>0,LEN(TRIM(C20))>0),'Bang TH nop'!AL21,0),0) -> 0 | G21: =D21*I20/26 -> 0 | H21: =D21*J20*150%/(26*8) -> 0 | K21: =IFERROR( IF(AND(LEN(TRIM(B20))>0,LEN(TRIM(C20))>0), ROUND(D21/26*K20,0), 0 ), 0 ) -> 0 | L21: =IFERROR( IF(AND(LEN(TRIM(B20))>0,LEN(TRIM(C20))>0), ROUND(D21/26*L20,0), 0 ), 0 ) -> 0 | M21: =IFERROR( IF(AND(LEN(TRIM(B20))>0,LEN(TRIM(C20))>0), ROUND(D21/26*M20,0), 0 ), 0 ) -> 0 | N21: =IFERROR( IF(AND(LEN(TRIM(B20))>0,LEN(TRIM(C20))>0), D21*N20/(26*8), 0 ), 0 ) -> 0 | O21: =IFERROR( IF(AND(LEN(TRIM(B20))>0,LEN(TRIM(C20))>0), D21*O20/(26*8), 0 ), 0 ) -> 0 | P21: =IFERROR( IF(AND(LEN(TRIM(B20))>0,LEN(TRIM(C20))>0), (D21/26/8*P20), 0 ), 0 ) -> 0 | Q21: =IFERROR( IF(AND(LEN(TRIM(B20))>0,LEN(TRIM(C20))>0), 'Bang TH nop'!BC21, 0 ), 0 ) -> 0 | R21: =IFERROR( IF(AND(LEN(TRIM(B20))>0,LEN(TRIM(C20))>0), 'Bang TH nop'!BD21, 0 ), 0 ) -> 0 | S21: =IFERROR( IF(AND(LEN(TRIM(B20))>0,LEN(TRIM(C20))>0), 'Bang TH nop'!BJ21, 0 ), 0 ) -> 0 | T21: =IFERROR( IF(AND(LEN(TRIM(B20))>0,LEN(TRIM(C20))>0), IFERROR('Bang TH nop'!AW21,0)+IFERROR('Bang TH nop'!BH21,0), 0 ), 0 ) -> 0 | X21: =+IF(G21-I21<0,0,G21-I21) -> 0 | Y21: =+IF(H21-J21<0,0, H21-J21) -> 0 | Z21: =IFERROR( IF(AND(LEN(TRIM(B20))>0,LEN(TRIM(C20))>0), (X21+Y21)*25%, 0 ), 0 ) -> 0 | AA21: =IFERROR( IF(AND(LEN(TRIM(B20))>0,LEN(TRIM(C20))>0), 'Bang TH nop'!BG21, 0 ), 0 ) -> 0 | AB21: =IFERROR( IF(AND(LEN(TRIM(B20))>0,LEN(TRIM(C20))>0), SUM(I21:W21)+IFERROR(Z21,0)+IFERROR(AA21,0), 0 ), 0 ) -> 0 | AC21: =IFERROR( IF(AND(LEN(TRIM(B20))>0,LEN(TRIM(C20))>0), IF((26-(IFERROR(I20,0)+IFERROR(K20,0)+IFERROR(L20,0)+IFERROR(M20,0)))>12,0,D21*10.5%), 0 ), 0 ) -> 0 | AD21: =IFERROR( IF(AND(LEN(TRIM(B20))>0,LEN(TRIM(C20))>0), ROUND(IF(D21=4939000,D21*0.5%,0),-2), 0 ), 0 ) -> 0 | AE21: =IFERROR( IF(AND(LEN(TRIM(B20))>0,LEN(TRIM(C20))>0), ROUND(IFERROR(AB21,0)-IFERROR(AC21,0)-IFERROR(AD21,0),-2), 0 ), 0 ) -> 0 | AF21: =IFERROR( IF(AND(LEN(TRIM(B20))>0,LEN(TRIM(C20))>0), IFERROR('Bang TH nop'!AQ21,0)+IFERROR('Bang TH nop'!AT21,0)+IFERROR('Bang TH nop'!BF21,0), 0 ), 0 ) -> 0 | AI21: =IFERROR( IF(AND(LEN(TRIM(B20))>0,LEN(TRIM(C20))>0), AH21/AG21, 0 ), 0 ) -> 0 | AJ21: =IFERROR( IF(AND(LEN(TRIM(B20))>0,LEN(TRIM(C20))>0), AL21/AF21, 0 ), 0 ) -> 0 | AK21: =IFERROR( IF(AND(LEN(TRIM(B20))>0,LEN(TRIM(C20))>0), AJ21/AI21, 0 ), 0 ) -> 0 | AL21: =IFERROR( IF(AND(LEN(TRIM(B20))>0,LEN(TRIM(C20))>0), AB21/L21, 0 ), 0 ) -> 0
A22: =A20+1 -> 8 | B22: ='Bang TH nop'!B23 -> 0 | C22: =IFERROR(IF(LEN(TRIM(B22))>0,'Bang TH nop'!C23,""),"") -> 0 | D22: =IFERROR(IF(AND(LEN(TRIM(B22))>0,LEN(TRIM(C22))>0),'Bang TH nop'!AO23,""),"") -> 0 | I22: =IFERROR(IF(AND(LEN(TRIM(B22))>0,LEN(TRIM(C22))>0),'Bang TH nop'!BB23,0),0) -> 0 | J22: =IFERROR(IF(AND(LEN(TRIM(B22))>0,LEN(TRIM(C22))>0),'Bang TH nop'!AV23,0),0) -> 0 | K22: =IFERROR(IF(AND(LEN(TRIM(B22))>0,LEN(TRIM(C22))>0),'Bang TH nop'!AR23,0),0) -> 0 | L22: =IFERROR(IF(AND(LEN(TRIM(B22))>0,LEN(TRIM(C22))>0),'Bang TH nop'!AS23,0),0) -> 0 | M22: =IFERROR(IF(AND(LEN(TRIM(B22))>0,LEN(TRIM(C22))>0),'Bang TH nop'!AT23,0),0) -> 0 | N22: =IFERROR(IF(AND(LEN(TRIM(B22))>0,LEN(TRIM(C22))>0),'Bang TH nop'!AU23,0),0) -> 0 | O22: =IFERROR(IF(AND(LEN(TRIM(B22))>0,LEN(TRIM(C22))>0),'Bang TH nop'!BE23,0),0) -> 0 | P22: =IFERROR(IF(AND(LEN(TRIM(B22))>0,LEN(TRIM(C22))>0),'Bang TH nop'!AZ23,0),0) -> 0 | AA22: =IFERROR( IF(AND(LEN(TRIM(B22))>0,LEN(TRIM(C22))>0), 'Bang TH nop'!AH23, 0 ), 0 ) -> A
D23: =IFERROR(IF(AND(LEN(TRIM(B22))>0,LEN(TRIM(C22))>0),'Bang TH nop'!AP23,""),"") -> 0 | F23: =IFERROR(IF(AND(LEN(TRIM(B22))>0,LEN(TRIM(C22))>0),'Bang TH nop'!AL23,0),0) -> 0 | G23: =D23*I22/26 -> 0 | H23: =D23*J22*150%/(26*8) -> 0 | K23: =IFERROR( IF(AND(LEN(TRIM(B22))>0,LEN(TRIM(C22))>0), ROUND(D23/26*K22,0), 0 ), 0 ) -> 0 | L23: =IFERROR( IF(AND(LEN(TRIM(B22))>0,LEN(TRIM(C22))>0), ROUND(D23/26*L22,0), 0 ), 0 ) -> 0 | M23: =IFERROR( IF(AND(LEN(TRIM(B22))>0,LEN(TRIM(C22))>0), ROUND(D23/26*M22,0), 0 ), 0 ) -> 0 | N23: =IFERROR( IF(AND(LEN(TRIM(B22))>0,LEN(TRIM(C22))>0), D23*N22/(26*8), 0 ), 0 ) -> 0 | O23: =IFERROR( IF(AND(LEN(TRIM(B22))>0,LEN(TRIM(C22))>0), D23*O22/(26*8), 0 ), 0 ) -> 0 | P23: =IFERROR( IF(AND(LEN(TRIM(B22))>0,LEN(TRIM(C22))>0), (D23/26/8*P22), 0 ), 0 ) -> 0 | Q23: =IFERROR( IF(AND(LEN(TRIM(B22))>0,LEN(TRIM(C22))>0), 'Bang TH nop'!BC23, 0 ), 0 ) -> 0 | R23: =IFERROR( IF(AND(LEN(TRIM(B22))>0,LEN(TRIM(C22))>0), 'Bang TH nop'!BD23, 0 ), 0 ) -> 0 | S23: =IFERROR( IF(AND(LEN(TRIM(B22))>0,LEN(TRIM(C22))>0), 'Bang TH nop'!BJ23, 0 ), 0 ) -> 0 | T23: =IFERROR( IF(AND(LEN(TRIM(B22))>0,LEN(TRIM(C22))>0), IFERROR('Bang TH nop'!AW23,0)+IFERROR('Bang TH nop'!BH23,0), 0 ), 0 ) -> 0 | X23: =+IF(G23-I23<0,0,G23-I23) -> 0 | Y23: =+IF(H23-J23<0,0, H23-J23) -> 0 | Z23: =IFERROR( IF(AND(LEN(TRIM(B22))>0,LEN(TRIM(C22))>0), (X23+Y23)*25%, 0 ), 0 ) -> 0 | AA23: =IFERROR( IF(AND(LEN(TRIM(B22))>0,LEN(TRIM(C22))>0), 'Bang TH nop'!BG23, 0 ), 0 ) -> 0 | AB23: =IFERROR( IF(AND(LEN(TRIM(B22))>0,LEN(TRIM(C22))>0), SUM(I23:W23)+IFERROR(Z23,0)+IFERROR(AA23,0), 0 ), 0 ) -> 0 | AC23: =IFERROR( IF(AND(LEN(TRIM(B22))>0,LEN(TRIM(C22))>0), IF((26-(IFERROR(I22,0)+IFERROR(K22,0)+IFERROR(L22,0)+IFERROR(M22,0)))>12,0,D23*10.5%), 0 ), 0 ) -> 0 | AD23: =IFERROR( IF(AND(LEN(TRIM(B22))>0,LEN(TRIM(C22))>0), ROUND(IF(D23=4939000,D23*0.5%,0),-2), 0 ), 0 ) -> 0 | AE23: =IFERROR( IF(AND(LEN(TRIM(B22))>0,LEN(TRIM(C22))>0), ROUND(IFERROR(AB23,0)-IFERROR(AC23,0)-IFERROR(AD23,0),-2), 0 ), 0 ) -> 0 | AF23: =IFERROR( IF(AND(LEN(TRIM(B22))>0,LEN(TRIM(C22))>0), IFERROR('Bang TH nop'!AQ23,0)+IFERROR('Bang TH nop'!AT23,0)+IFERROR('Bang TH nop'!BF23,0), 0 ), 0 ) -> 0 | AI23: =IFERROR( IF(AND(LEN(TRIM(B22))>0,LEN(TRIM(C22))>0), AH23/AG23, 0 ), 0 ) -> 0 | AJ23: =IFERROR( IF(AND(LEN(TRIM(B22))>0,LEN(TRIM(C22))>0), AL23/AF23, 0 ), 0 ) -> 0 | AK23: =IFERROR( IF(AND(LEN(TRIM(B22))>0,LEN(TRIM(C22))>0), AJ23/AI23, 0 ), 0 ) -> 0 | AL23: =IFERROR( IF(AND(LEN(TRIM(B22))>0,LEN(TRIM(C22))>0), AB23/L23, 0 ), 0 ) -> 0
A24: =A22+1 -> 9 | B24: ='Bang TH nop'!B25 -> 0 | C24: =IFERROR(IF(LEN(TRIM(B24))>0,'Bang TH nop'!C25,""),"") -> 0 | D24: =IFERROR(IF(AND(LEN(TRIM(B24))>0,LEN(TRIM(C24))>0),'Bang TH nop'!AO25,""),"") -> 0 | I24: =IFERROR(IF(AND(LEN(TRIM(B24))>0,LEN(TRIM(C24))>0),'Bang TH nop'!BB25,0),0) -> 0 | J24: =IFERROR(IF(AND(LEN(TRIM(B24))>0,LEN(TRIM(C24))>0),'Bang TH nop'!AV25,0),0) -> 0 | K24: =IFERROR(IF(AND(LEN(TRIM(B24))>0,LEN(TRIM(C24))>0),'Bang TH nop'!AR25,0),0) -> 0 | L24: =IFERROR(IF(AND(LEN(TRIM(B24))>0,LEN(TRIM(C24))>0),'Bang TH nop'!AS25,0),0) -> 0 | M24: =IFERROR(IF(AND(LEN(TRIM(B24))>0,LEN(TRIM(C24))>0),'Bang TH nop'!AT25,0),0) -> 0 | N24: =IFERROR(IF(AND(LEN(TRIM(B24))>0,LEN(TRIM(C24))>0),'Bang TH nop'!AU25,0),0) -> 0 | O24: =IFERROR(IF(AND(LEN(TRIM(B24))>0,LEN(TRIM(C24))>0),'Bang TH nop'!BE25,0),0) -> 0 | P24: =IFERROR(IF(AND(LEN(TRIM(B24))>0,LEN(TRIM(C24))>0),'Bang TH nop'!AZ25,0),0) -> 0 | AA24: =IFERROR( IF(AND(LEN(TRIM(B24))>0,LEN(TRIM(C24))>0), 'Bang TH nop'!AH25, 0 ), 0 ) -> A
D25: =IFERROR(IF(AND(LEN(TRIM(B24))>0,LEN(TRIM(C24))>0),'Bang TH nop'!AP25,""),"") -> 0 | F25: =IFERROR(IF(AND(LEN(TRIM(B24))>0,LEN(TRIM(C24))>0),'Bang TH nop'!AL25,0),0) -> 0 | G25: =D25*I24/26 -> 0 | H25: =D25*J24*150%/(26*8) -> 0 | K25: =IFERROR( IF(AND(LEN(TRIM(B24))>0,LEN(TRIM(C24))>0), ROUND(D25/26*K24,0), 0 ), 0 ) -> 0 | L25: =IFERROR( IF(AND(LEN(TRIM(B24))>0,LEN(TRIM(C24))>0), ROUND(D25/26*L24,0), 0 ), 0 ) -> 0 | M25: =IFERROR( IF(AND(LEN(TRIM(B24))>0,LEN(TRIM(C24))>0), ROUND(D25/26*M24,0), 0 ), 0 ) -> 0 | N25: =IFERROR( IF(AND(LEN(TRIM(B24))>0,LEN(TRIM(C24))>0), D25*N24/(26*8), 0 ), 0 ) -> 0 | O25: =IFERROR( IF(AND(LEN(TRIM(B24))>0,LEN(TRIM(C24))>0), D25*O24/(26*8), 0 ), 0 ) -> 0 | P25: =IFERROR( IF(AND(LEN(TRIM(B24))>0,LEN(TRIM(C24))>0), (D25/26/8*P24), 0 ), 0 ) -> 0 | Q25: =IFERROR( IF(AND(LEN(TRIM(B24))>0,LEN(TRIM(C24))>0), 'Bang TH nop'!BC25, 0 ), 0 ) -> 0 | R25: =IFERROR( IF(AND(LEN(TRIM(B24))>0,LEN(TRIM(C24))>0), 'Bang TH nop'!BD25, 0 ), 0 ) -> 0 | S25: =IFERROR( IF(AND(LEN(TRIM(B24))>0,LEN(TRIM(C24))>0), 'Bang TH nop'!BJ25, 0 ), 0 ) -> 0 | T25: =IFERROR( IF(AND(LEN(TRIM(B24))>0,LEN(TRIM(C24))>0), IFERROR('Bang TH nop'!AW25,0)+IFERROR('Bang TH nop'!BH25,0), 0 ), 0 ) -> 0 | X25: =+IF(G25-I25<0,0,G25-I25) -> 0 | Y25: =+IF(H25-J25<0,0, H25-J25) -> 0 | Z25: =IFERROR( IF(AND(LEN(TRIM(B24))>0,LEN(TRIM(C24))>0), (X25+Y25)*25%, 0 ), 0 ) -> 0 | AA25: =IFERROR( IF(AND(LEN(TRIM(B24))>0,LEN(TRIM(C24))>0), 'Bang TH nop'!BG25, 0 ), 0 ) -> 0 | AB25: =IFERROR( IF(AND(LEN(TRIM(B24))>0,LEN(TRIM(C24))>0), SUM(I25:W25)+IFERROR(Z25,0)+IFERROR(AA25,0), 0 ), 0 ) -> 0 | AC25: =IFERROR( IF(AND(LEN(TRIM(B24))>0,LEN(TRIM(C24))>0), IF((26-(IFERROR(I24,0)+IFERROR(K24,0)+IFERROR(L24,0)+IFERROR(M24,0)))>12,0,D25*10.5%), 0 ), 0 ) -> 0 | AD25: =IFERROR( IF(AND(LEN(TRIM(B24))>0,LEN(TRIM(C24))>0), ROUND(IF(D25=4939000,D25*0.5%,0),-2), 0 ), 0 ) -> 0 | AE25: =IFERROR( IF(AND(LEN(TRIM(B24))>0,LEN(TRIM(C24))>0), ROUND(IFERROR(AB25,0)-IFERROR(AC25,0)-IFERROR(AD25,0),-2), 0 ), 0 ) -> 0 | AF25: =IFERROR( IF(AND(LEN(TRIM(B24))>0,LEN(TRIM(C24))>0), IFERROR('Bang TH nop'!AQ25,0)+IFERROR('Bang TH nop'!AT25,0)+IFERROR('Bang TH nop'!BF25,0), 0 ), 0 ) -> 0 | AI25: =IFERROR( IF(AND(LEN(TRIM(B24))>0,LEN(TRIM(C24))>0), AH25/AG25, 0 ), 0 ) -> 0 | AJ25: =IFERROR( IF(AND(LEN(TRIM(B24))>0,LEN(TRIM(C24))>0), AL25/AF25, 0 ), 0 ) -> 0 | AK25: =IFERROR( IF(AND(LEN(TRIM(B24))>0,LEN(TRIM(C24))>0), AJ25/AI25, 0 ), 0 ) -> 0 | AL25: =IFERROR( IF(AND(LEN(TRIM(B24))>0,LEN(TRIM(C24))>0), AB25/L25, 0 ), 0 ) -> 0
A26: =A24+1 -> 10 | B26: ='Bang TH nop'!B27 -> 0 | C26: =IFERROR(IF(LEN(TRIM(B26))>0,'Bang TH nop'!C27,""),"") -> 0 | D26: =IFERROR(IF(AND(LEN(TRIM(B26))>0,LEN(TRIM(C26))>0),'Bang TH nop'!AO27,""),"") -> 0 | I26: =IFERROR(IF(AND(LEN(TRIM(B26))>0,LEN(TRIM(C26))>0),'Bang TH nop'!BB27,0),0) -> 0 | J26: =IFERROR(IF(AND(LEN(TRIM(B26))>0,LEN(TRIM(C26))>0),'Bang TH nop'!AV27,0),0) -> 0 | K26: =IFERROR(IF(AND(LEN(TRIM(B26))>0,LEN(TRIM(C26))>0),'Bang TH nop'!AR27,0),0) -> 0 | L26: =IFERROR(IF(AND(LEN(TRIM(B26))>0,LEN(TRIM(C26))>0),'Bang TH nop'!AS27,0),0) -> 0 | M26: =IFERROR(IF(AND(LEN(TRIM(B26))>0,LEN(TRIM(C26))>0),'Bang TH nop'!AT27,0),0) -> 0 | N26: =IFERROR(IF(AND(LEN(TRIM(B26))>0,LEN(TRIM(C26))>0),'Bang TH nop'!AU27,0),0) -> 0 | O26: =IFERROR(IF(AND(LEN(TRIM(B26))>0,LEN(TRIM(C26))>0),'Bang TH nop'!BE27,0),0) -> 0 | P26: =IFERROR(IF(AND(LEN(TRIM(B26))>0,LEN(TRIM(C26))>0),'Bang TH nop'!AZ27,0),0) -> 0 | AA26: =IFERROR( IF(AND(LEN(TRIM(B26))>0,LEN(TRIM(C26))>0), 'Bang TH nop'!AH27, 0 ), 0 ) -> A
D27: =IFERROR(IF(AND(LEN(TRIM(B26))>0,LEN(TRIM(C26))>0),'Bang TH nop'!AP27,""),"") -> 0 | F27: =IFERROR(IF(AND(LEN(TRIM(B26))>0,LEN(TRIM(C26))>0),'Bang TH nop'!AL27,0),0) -> 0 | G27: =D27*I26/26 -> 0 | H27: =D27*J26*150%/(26*8) -> 0 | K27: =IFERROR( IF(AND(LEN(TRIM(B26))>0,LEN(TRIM(C26))>0), ROUND(D27/26*K26,0), 0 ), 0 ) -> 0 | L27: =IFERROR( IF(AND(LEN(TRIM(B26))>0,LEN(TRIM(C26))>0), ROUND(D27/26*L26,0), 0 ), 0 ) -> 0 | M27: =IFERROR( IF(AND(LEN(TRIM(B26))>0,LEN(TRIM(C26))>0), ROUND(D27/26*M26,0), 0 ), 0 ) -> 0 | N27: =IFERROR( IF(AND(LEN(TRIM(B26))>0,LEN(TRIM(C26))>0), D27*N26/(26*8), 0 ), 0 ) -> 0 | O27: =IFERROR( IF(AND(LEN(TRIM(B26))>0,LEN(TRIM(C26))>0), D27*O26/(26*8), 0 ), 0 ) -> 0 | P27: =IFERROR( IF(AND(LEN(TRIM(B26))>0,LEN(TRIM(C26))>0), (D27/26/8*P26), 0 ), 0 ) -> 0 | Q27: =IFERROR( IF(AND(LEN(TRIM(B26))>0,LEN(TRIM(C26))>0), 'Bang TH nop'!BC27, 0 ), 0 ) -> 0 | R27: =IFERROR( IF(AND(LEN(TRIM(B26))>0,LEN(TRIM(C26))>0), 'Bang TH nop'!BD27, 0 ), 0 ) -> 0 | S27: =IFERROR( IF(AND(LEN(TRIM(B26))>0,LEN(TRIM(C26))>0), 'Bang TH nop'!BJ27, 0 ), 0 ) -> 0 | T27: =IFERROR( IF(AND(LEN(TRIM(B26))>0,LEN(TRIM(C26))>0), IFERROR('Bang TH nop'!AW27,0)+IFERROR('Bang TH nop'!BH27,0), 0 ), 0 ) -> 0 | X27: =+IF(G27-I27<0,0,G27-I27) -> 0 | Y27: =+IF(H27-J27<0,0, H27-J27) -> 0 | Z27: =IFERROR( IF(AND(LEN(TRIM(B26))>0,LEN(TRIM(C26))>0), (X27+Y27)*25%, 0 ), 0 ) -> 0 | AA27: =IFERROR( IF(AND(LEN(TRIM(B26))>0,LEN(TRIM(C26))>0), 'Bang TH nop'!BG27, 0 ), 0 ) -> 0 | AB27: =IFERROR( IF(AND(LEN(TRIM(B26))>0,LEN(TRIM(C26))>0), SUM(I27:W27)+IFERROR(Z27,0)+IFERROR(AA27,0), 0 ), 0 ) -> 0 | AC27: =IFERROR( IF(AND(LEN(TRIM(B26))>0,LEN(TRIM(C26))>0), IF((26-(IFERROR(I26,0)+IFERROR(K26,0)+IFERROR(L26,0)+IFERROR(M26,0)))>12,0,D27*10.5%), 0 ), 0 ) -> 0 | AD27: =IFERROR( IF(AND(LEN(TRIM(B26))>0,LEN(TRIM(C26))>0), ROUND(IF(D27=4939000,D27*0.5%,0),-2), 0 ), 0 ) -> 0 | AE27: =IFERROR( IF(AND(LEN(TRIM(B26))>0,LEN(TRIM(C26))>0), ROUND(IFERROR(AB27,0)-IFERROR(AC27,0)-IFERROR(AD27,0),-2), 0 ), 0 ) -> 0 | AF27: =IFERROR( IF(AND(LEN(TRIM(B26))>0,LEN(TRIM(C26))>0), IFERROR('Bang TH nop'!AQ27,0)+IFERROR('Bang TH nop'!AT27,0)+IFERROR('Bang TH nop'!BF27,0), 0 ), 0 ) -> 0 | AI27: =IFERROR( IF(AND(LEN(TRIM(B26))>0,LEN(TRIM(C26))>0), AH27/AG27, 0 ), 0 ) -> 0 | AJ27: =IFERROR( IF(AND(LEN(TRIM(B26))>0,LEN(TRIM(C26))>0), AL27/AF27, 0 ), 0 ) -> 0 | AK27: =IFERROR( IF(AND(LEN(TRIM(B26))>0,LEN(TRIM(C26))>0), AJ27/AI27, 0 ), 0 ) -> 0 | AL27: =IFERROR( IF(AND(LEN(TRIM(B26))>0,LEN(TRIM(C26))>0), AB27/L27, 0 ), 0 ) -> 0
A28: =A26+1 -> 11 | B28: ='Bang TH nop'!B29 -> 0 | C28: =IFERROR(IF(LEN(TRIM(B28))>0,'Bang TH nop'!C29,""),"") -> 0 | D28: =IFERROR(IF(AND(LEN(TRIM(B28))>0,LEN(TRIM(C28))>0),'Bang TH nop'!AO29,""),"") -> 0 | I28: =IFERROR(IF(AND(LEN(TRIM(B28))>0,LEN(TRIM(C28))>0),'Bang TH nop'!BB29,0),0) -> 0 | J28: =IFERROR(IF(AND(LEN(TRIM(B28))>0,LEN(TRIM(C28))>0),'Bang TH nop'!AV29,0),0) -> 0 | K28: =IFERROR(IF(AND(LEN(TRIM(B28))>0,LEN(TRIM(C28))>0),'Bang TH nop'!AR29,0),0) -> 0 | L28: =IFERROR(IF(AND(LEN(TRIM(B28))>0,LEN(TRIM(C28))>0),'Bang TH nop'!AS29,0),0) -> 0 | M28: =IFERROR(IF(AND(LEN(TRIM(B28))>0,LEN(TRIM(C28))>0),'Bang TH nop'!AT29,0),0) -> 0 | N28: =IFERROR(IF(AND(LEN(TRIM(B28))>0,LEN(TRIM(C28))>0),'Bang TH nop'!AU29,0),0) -> 0 | O28: =IFERROR(IF(AND(LEN(TRIM(B28))>0,LEN(TRIM(C28))>0),'Bang TH nop'!BE29,0),0) -> 0 | P28: =IFERROR(IF(AND(LEN(TRIM(B28))>0,LEN(TRIM(C28))>0),'Bang TH nop'!AZ29,0),0) -> 0 | AA28: =IFERROR( IF(AND(LEN(TRIM(B28))>0,LEN(TRIM(C28))>0), 'Bang TH nop'!AH29, 0 ), 0 ) -> A
D29: =IFERROR(IF(AND(LEN(TRIM(B28))>0,LEN(TRIM(C28))>0),'Bang TH nop'!AP29,""),"") -> 0 | F29: =IFERROR(IF(AND(LEN(TRIM(B28))>0,LEN(TRIM(C28))>0),'Bang TH nop'!AL29,0),0) -> 0 | G29: =D29*I28/26 -> 0 | H29: =D29*J28*150%/(26*8) -> 0 | K29: =IFERROR( IF(AND(LEN(TRIM(B28))>0,LEN(TRIM(C28))>0), ROUND(D29/26*K28,0), 0 ), 0 ) -> 0 | L29: =IFERROR( IF(AND(LEN(TRIM(B28))>0,LEN(TRIM(C28))>0), ROUND(D29/26*L28,0), 0 ), 0 ) -> 0 | M29: =IFERROR( IF(AND(LEN(TRIM(B28))>0,LEN(TRIM(C28))>0), ROUND(D29/26*M28,0), 0 ), 0 ) -> 0 | N29: =IFERROR( IF(AND(LEN(TRIM(B28))>0,LEN(TRIM(C28))>0), D29*N28/(26*8), 0 ), 0 ) -> 0 | O29: =IFERROR( IF(AND(LEN(TRIM(B28))>0,LEN(TRIM(C28))>0), D29*O28/(26*8), 0 ), 0 ) -> 0 | P29: =IFERROR( IF(AND(LEN(TRIM(B28))>0,LEN(TRIM(C28))>0), (D29/26/8*P28), 0 ), 0 ) -> 0 | Q29: =IFERROR( IF(AND(LEN(TRIM(B28))>0,LEN(TRIM(C28))>0), 'Bang TH nop'!BC29, 0 ), 0 ) -> 0 | R29: =IFERROR( IF(AND(LEN(TRIM(B28))>0,LEN(TRIM(C28))>0), 'Bang TH nop'!BD29, 0 ), 0 ) -> 0 | S29: =IFERROR( IF(AND(LEN(TRIM(B28))>0,LEN(TRIM(C28))>0), 'Bang TH nop'!BJ29, 0 ), 0 ) -> 0 | T29: =IFERROR( IF(AND(LEN(TRIM(B28))>0,LEN(TRIM(C28))>0), IFERROR('Bang TH nop'!AW29,0)+IFERROR('Bang TH nop'!BH29,0), 0 ), 0 ) -> 0 | X29: =+IF(G29-I29<0,0,G29-I29) -> 0 | Y29: =+IF(H29-J29<0,0, H29-J29) -> 0 | Z29: =IFERROR( IF(AND(LEN(TRIM(B28))>0,LEN(TRIM(C28))>0), (X29+Y29)*25%, 0 ), 0 ) -> 0 | AA29: =IFERROR( IF(AND(LEN(TRIM(B28))>0,LEN(TRIM(C28))>0), 'Bang TH nop'!BG29, 0 ), 0 ) -> 0 | AB29: =IFERROR( IF(AND(LEN(TRIM(B28))>0,LEN(TRIM(C28))>0), SUM(I29:W29)+IFERROR(Z29,0)+IFERROR(AA29,0), 0 ), 0 ) -> 0 | AC29: =IFERROR( IF(AND(LEN(TRIM(B28))>0,LEN(TRIM(C28))>0), IF((26-(IFERROR(I28,0)+IFERROR(K28,0)+IFERROR(L28,0)+IFERROR(M28,0)))>12,0,D29*10.5%), 0 ), 0 ) -> 0 | AD29: =IFERROR( IF(AND(LEN(TRIM(B28))>0,LEN(TRIM(C28))>0), ROUND(IF(D29=4939000,D29*0.5%,0),-2), 0 ), 0 ) -> 0 | AE29: =IFERROR( IF(AND(LEN(TRIM(B28))>0,LEN(TRIM(C28))>0), ROUND(IFERROR(AB29,0)-IFERROR(AC29,0)-IFERROR(AD29,0),-2), 0 ), 0 ) -> 0 | AF29: =IFERROR( IF(AND(LEN(TRIM(B28))>0,LEN(TRIM(C28))>0), IFERROR('Bang TH nop'!AQ29,0)+IFERROR('Bang TH nop'!AT29,0)+IFERROR('Bang TH nop'!BF29,0), 0 ), 0 ) -> 0 | AI29: =IFERROR( IF(AND(LEN(TRIM(B28))>0,LEN(TRIM(C28))>0), AH29/AG29, 0 ), 0 ) -> 0 | AJ29: =IFERROR( IF(AND(LEN(TRIM(B28))>0,LEN(TRIM(C28))>0), AL29/AF29, 0 ), 0 ) -> 0 | AK29: =IFERROR( IF(AND(LEN(TRIM(B28))>0,LEN(TRIM(C28))>0), AJ29/AI29, 0 ), 0 ) -> 0 | AL29: =IFERROR( IF(AND(LEN(TRIM(B28))>0,LEN(TRIM(C28))>0), AB29/L29, 0 ), 0 ) -> 0
A30: =A28+1 -> 12 | B30: ='Bang TH nop'!B31 -> 0 | C30: =IFERROR(IF(LEN(TRIM(B30))>0,'Bang TH nop'!C31,""),"") -> 0 | D30: =IFERROR(IF(AND(LEN(TRIM(B30))>0,LEN(TRIM(C30))>0),'Bang TH nop'!AO31,""),"") -> 0 | I30: =IFERROR(IF(AND(LEN(TRIM(B30))>0,LEN(TRIM(C30))>0),'Bang TH nop'!BB31,0),0) -> 0 | J30: =IFERROR(IF(AND(LEN(TRIM(B30))>0,LEN(TRIM(C30))>0),'Bang TH nop'!AV31,0),0) -> 0 | K30: =IFERROR(IF(AND(LEN(TRIM(B30))>0,LEN(TRIM(C30))>0),'Bang TH nop'!AR31,0),0) -> 0 | L30: =IFERROR(IF(AND(LEN(TRIM(B30))>0,LEN(TRIM(C30))>0),'Bang TH nop'!AS31,0),0) -> 0 | M30: =IFERROR(IF(AND(LEN(TRIM(B30))>0,LEN(TRIM(C30))>0),'Bang TH nop'!AT31,0),0) -> 0 | N30: =IFERROR(IF(AND(LEN(TRIM(B30))>0,LEN(TRIM(C30))>0),'Bang TH nop'!AU31,0),0) -> 0 | O30: =IFERROR(IF(AND(LEN(TRIM(B30))>0,LEN(TRIM(C30))>0),'Bang TH nop'!BE31,0),0) -> 0 | P30: =IFERROR(IF(AND(LEN(TRIM(B30))>0,LEN(TRIM(C30))>0),'Bang TH nop'!AZ31,0),0) -> 0 | AA30: =IFERROR( IF(AND(LEN(TRIM(B30))>0,LEN(TRIM(C30))>0), 'Bang TH nop'!AH31, 0 ), 0 ) -> A
D31: =IFERROR(IF(AND(LEN(TRIM(B30))>0,LEN(TRIM(C30))>0),'Bang TH nop'!AP31,""),"") -> 0 | F31: =IFERROR(IF(AND(LEN(TRIM(B30))>0,LEN(TRIM(C30))>0),'Bang TH nop'!AL31,0),0) -> 0 | G31: =D31*I30/26 -> 0 | H31: =D31*J30*150%/(26*8) -> 0 | K31: =IFERROR( IF(AND(LEN(TRIM(B30))>0,LEN(TRIM(C30))>0), ROUND(D31/26*K30,0), 0 ), 0 ) -> 0 | L31: =IFERROR( IF(AND(LEN(TRIM(B30))>0,LEN(TRIM(C30))>0), ROUND(D31/26*L30,0), 0 ), 0 ) -> 0 | M31: =IFERROR( IF(AND(LEN(TRIM(B30))>0,LEN(TRIM(C30))>0), ROUND(D31/26*M30,0), 0 ), 0 ) -> 0 | N31: =IFERROR( IF(AND(LEN(TRIM(B30))>0,LEN(TRIM(C30))>0), D31*N30/(26*8), 0 ), 0 ) -> 0 | O31: =IFERROR( IF(AND(LEN(TRIM(B30))>0,LEN(TRIM(C30))>0), D31*O30/(26*8), 0 ), 0 ) -> 0 | P31: =IFERROR( IF(AND(LEN(TRIM(B30))>0,LEN(TRIM(C30))>0), (D31/26/8*P30), 0 ), 0 ) -> 0 | Q31: =IFERROR( IF(AND(LEN(TRIM(B30))>0,LEN(TRIM(C30))>0), 'Bang TH nop'!BC31, 0 ), 0 ) -> 0 | R31: =IFERROR( IF(AND(LEN(TRIM(B30))>0,LEN(TRIM(C30))>0), 'Bang TH nop'!BD31, 0 ), 0 ) -> 0 | S31: =IFERROR( IF(AND(LEN(TRIM(B30))>0,LEN(TRIM(C30))>0), 'Bang TH nop'!BJ31, 0 ), 0 ) -> 0 | T31: =IFERROR( IF(AND(LEN(TRIM(B30))>0,LEN(TRIM(C30))>0), IFERROR('Bang TH nop'!AW31,0)+IFERROR('Bang TH nop'!BH31,0), 0 ), 0 ) -> 0 | X31: =+IF(G31-I31<0,0,G31-I31) -> 0 | Y31: =+IF(H31-J31<0,0, H31-J31) -> 0 | Z31: =IFERROR( IF(AND(LEN(TRIM(B30))>0,LEN(TRIM(C30))>0), (X31+Y31)*25%, 0 ), 0 ) -> 0 | AA31: =IFERROR( IF(AND(LEN(TRIM(B30))>0,LEN(TRIM(C30))>0), 'Bang TH nop'!BG31, 0 ), 0 ) -> 0 | AB31: =IFERROR( IF(AND(LEN(TRIM(B30))>0,LEN(TRIM(C30))>0), SUM(I31:W31)+IFERROR(Z31,0)+IFERROR(AA31,0), 0 ), 0 ) -> 0 | AC31: =IFERROR( IF(AND(LEN(TRIM(B30))>0,LEN(TRIM(C30))>0), IF((26-(IFERROR(I30,0)+IFERROR(K30,0)+IFERROR(L30,0)+IFERROR(M30,0)))>12,0,D31*10.5%), 0 ), 0 ) -> 0 | AD31: =IFERROR( IF(AND(LEN(TRIM(B30))>0,LEN(TRIM(C30))>0), ROUND(IF(D31=4939000,D31*0.5%,0),-2), 0 ), 0 ) -> 0 | AE31: =IFERROR( IF(AND(LEN(TRIM(B30))>0,LEN(TRIM(C30))>0), ROUND(IFERROR(AB31,0)-IFERROR(AC31,0)-IFERROR(AD31,0),-2), 0 ), 0 ) -> 0 | AF31: =IFERROR( IF(AND(LEN(TRIM(B30))>0,LEN(TRIM(C30))>0), IFERROR('Bang TH nop'!AQ31,0)+IFERROR('Bang TH nop'!AT31,0)+IFERROR('Bang TH nop'!BF31,0), 0 ), 0 ) -> 0 | AI31: =IFERROR( IF(AND(LEN(TRIM(B30))>0,LEN(TRIM(C30))>0), AH31/AG31, 0 ), 0 ) -> 0 | AJ31: =IFERROR( IF(AND(LEN(TRIM(B30))>0,LEN(TRIM(C30))>0), AL31/AF31, 0 ), 0 ) -> 0 | AK31: =IFERROR( IF(AND(LEN(TRIM(B30))>0,LEN(TRIM(C30))>0), AJ31/AI31, 0 ), 0 ) -> 0 | AL31: =IFERROR( IF(AND(LEN(TRIM(B30))>0,LEN(TRIM(C30))>0), AB31/L31, 0 ), 0 ) -> 0
